Templates,label
"File <*>/fully_connected_feed.py, line 27, in [FUNC] [CODE][SEP]File <*>/input_data.py, line 29, in [FUNC] [CODE][SEP]ImportError: No module named contrib.learn.python.learn.datasets.mnist",1
"File <stdin>, line 1, in <module> [CODE][SEP]File <*>python2.7/site-packages/tflearn/__init__.py, line 22, in <module> from . import activations[SEP]File <*>python2.7/site-packages/tflearn/activations.py, line 7, in <module> from . import initializations[SEP]File <*>python2.7/site-packages/tflearn/initializations.py, line 5, in <module> from tensorflow.contrib.layers.python.layers.initializers import \[SEP]ImportError: cannot import name variance_scaling_initializer",1
"File <*>/worker.py, line 98, in main command = pickleSer._read_with_length(infile)[SEP]File <*>/serializers.py, line 164, in _read_with_length return self.loads(obj)[SEP]File <*>/serializers.py, line 422, in loads return pickle.loads(obj)[SEP]File <*>python2.7/site-packages/six.py, line 118, in __getattr__ _module = self._resolve()[SEP]File <*>python2.7/site-packages/six.py, line 115, in _resolve return _import_module(self.mod)[SEP]RuntimeError: maximum recursion depth exceeded",1
"File mnist_softmax.py, line 78, in <module> tf.app.run(main=main, argv=[sys.argv[0]] + unparsed)[SEP]TypeError: run() got an unexpected keyword argument 'argv'",1
"File <*>python3.5/site-packages/keras/backend/tensorflow_backend.py, line 5, in <module>() from tensorflow.python.ops import ctc_ops as ctc[SEP]ImportError: cannot import name 'ctc_ops'",1
"File <*>python2.7/dist-packages/pip/basecommand.py, line 122, in main status = self.run(options, args)[SEP]File <*>python2.7/dist-packages/pip/commands/install.py, line 278, in run requirement_set.prepare_files(finder, force_root_egg_info=self.bundle, bundle=self.bundle)[SEP]File /usr/lib/python2.7/dist-packages/pip/req.py, line 1178, in prepare_files url = finder.find_requirement(req_to_install, upgrade=self.upgrade)",1
"File <*>python2.7/site-packages/tensorflow/python/__init__.py, line 61, in <module> from tensorflow.python import pywrap_tensorflow[SEP]File <*>python2.7/site-packages/tensorflow/python/pywrap_tensorflow.py, line 28, in <module> _pywrap_tensorflow = swig_import_helper()[SEP]File <*>python2.7/site-packages/tensorflow/python/pywrap_tensorflow.py, line 24, in swig_import_helper _mod = imp.load_module('_pywrap_tensorflow', fp, pathname, description)[SEP]ImportError: dlopen(/Users/smahesh/src/tensorflow/lib/python2.7/site-packages/tensorflow/python/_pywrap_tensorflow.so, 10): Library not loaded: @rpath/libcudart.8.0.dylib",1
"File cnn.py, line 258, in <module> models = run_cross_validation_create_models(num_folds)[SEP]File cnn.py, line 205, in run_cross_validation_create_models validation_data=(X_valid, Y_valid))[SEP]TypeError: fit_generator() takes at least 4 arguments (5 given)",1
"File <*>/test_model.py, line 2, in <module> from models import NN_with_EntityEmbedding[SEP]File <*>/models.py, line 8, in <module> from keras.layers.core import Dense, Dropout, Activation, Merge, Reshape[SEP]ImportError: cannot import name Merge",1
"File [FILE], line 44, in <module>() num_sampled, vocabulary_size))[SEP]File <*>python3.5/site-packages/tensorflow/python/ops/nn_impl.py, line 1166, in nce_loss(weights, biases, labels, inputs, num_sampled, num_classes, num_true, sampled_values, remove_accidental_hits, partition_strategy, name) name=name)[SEP]File <*>python3.5/site-packages/tensorflow/python/ops/nn_impl.py, line 1001, in _compute_sampled_logits(weights, biases, labels, inputs, num_sampled, num_classes, num_true, sampled_values, subtract_log_q, remove_accidental_hits, partition_strategy, name) array_ops.reshape(true_w, new_true_w_shape))[SEP]File <*>python3.5/site-packages/tensorflow/python/ops/math_ops.py, line 278, in multiply(x, y, name) return gen_math_ops._mul(x, y, name)[SEP]File <*>python3.5/site-packages/tensorflow/python/ops/gen_math_ops.py, line 1434, in _mul(x, y, name) result = _op_def_lib.apply_op(""Mul"", x=x, y=y, name=name)[SEP]File <*>python3.5/site-packages/tensorflow/python/framework/op_def_library.py, line 527, in apply_op(self, op_type_name, name, **keywords) inferred_from[input_arg.type_attr]))[SEP]TypeError: Input 'y' of 'Mul' Op has type float32 that does not match type int32 of argument 'x'.",1
"File <*>/site-packages/tensorflow/python/pywrap_tensorflow_internal.py, line 18, in swig_import_helper return importlib.import_module(mname)[SEP]File <*>/__init__.py, line 126, in import_module return _bootstrap._gcd_import(name[level:], package, level)[SEP]File <frozen importlib._bootstrap>, line 986, in _gcd_import [CODE][SEP]File <frozen importlib._bootstrap>, line 969, in _find_and_load [CODE][SEP]File <frozen importlib._bootstrap>, line 958, in _find_and_load_unlocked [CODE][SEP]File <frozen importlib._bootstrap>, line 666, in _load_unlocked [CODE][SEP]File <frozen importlib._bootstrap>, line 577, in module_from_spec [CODE][SEP]File <frozen importlib._bootstrap_external>, line 906, in create_module [CODE][SEP]File <frozen importlib._bootstrap>, line 222, in _call_with_frames_removed [CODE][SEP]ImportError: DLL load failed: The specified module could not be found.",1
"File <*>/tensorboard, line 7, in <module> from tensorflow.tensorboard.tensorboard import main[SEP]ModuleNotFoundError: No module named 'tensorflow.tensorboard.tensorboard'",1
"File <*>python2.7/site-packages/tensorflow/python/pywrap_tensorflow.py, line 41, in <module> from tensorflow.python.pywrap_tensorflow_internal import *[SEP]File <*>python2.7/site-packages/tensorflow/python/pywrap_tensorflow_internal.py, line 28, in <module> _pywrap_tensorflow_internal = swig_import_helper()[SEP]File <*>python2.7/site-packages/tensorflow/python/pywrap_tensorflow_internal.py, line 24, in swig_import_helper _mod = imp.load_module('_pywrap_tensorflow_internal', fp, pathname, description)[SEP]ImportError: libcusolver.so.8.0: cannot open shared object file: No such file or directory Failed to load the native TensorFlow runtime.",1
"File <pyshell#6>, line 1, in <module> import tensorflow as tf[SEP]File <*>/site-packages/tensorflow/__init__.py, line 24, in <module> from tensorflow.python import *[SEP]File <*>/site-packages/tensorflow/python/__init__.py, line 49, in <module> from tensorflow.python import pywrap_tensorflow[SEP]File <*>/site-packages/tensorflow/python/pywrap_tensorflow.py, line 30, in <module> self_check.preload_check()[SEP]File <*>/site-packages/tensorflow/python/platform/self_check.py, line 82, in preload_check % (build_info.cudart_dll_name, build_info.cuda_version_number))[SEP]ImportError: Could not find 'cudart64_90.dll'. TensorFlow requires that this DLL be installed in a directory that is named in your %PATH% environment variable. Download and install CUDA 9.0 from this URL: https://developer.nvidia.com/cuda-toolkit",1
"File <*>/site-packages/tensorflow/python/pywrap_tensorflow_internal.py, line 18, in swig_import_helper return importlib.import_module(mname)[SEP]File <*>/__init__.py, line 126, in import_module return _bootstrap._gcd_import(name[level:], package, level)[SEP]File <frozen importlib._bootstrap>, line 994, in _gcd_import [CODE][SEP]File <frozen importlib._bootstrap>, line 971, in _find_and_load [CODE][SEP]File <frozen importlib._bootstrap>, line 955, in _find_and_load_unlocked [CODE][SEP]File <frozen importlib._bootstrap>, line 658, in _load_unlocked [CODE][SEP]File <frozen importlib._bootstrap>, line 571, in module_from_spec [CODE][SEP]File <frozen importlib._bootstrap_external>, line 922, in create_module [CODE][SEP]File <frozen importlib._bootstrap>, line 219, in _call_with_frames_removed [CODE][SEP]ImportError: DLL load failed with error code -1073741795",1
"File <stdin>, line 1, in <module> [CODE][SEP]AttributeError: module 'tensorflow.python.keras.datasets.fashion_mnist' has no attribute 'load_data'",1
"File <*>python3.6/site-packages/tensorflow/python/framework/tensor_util.py, line 527, in make_tensor_proto str_values = [compat.as_bytes(x) for x in proto_values][SEP]File <*>python3.6/site-packages/tensorflow/python/framework/tensor_util.py, line 527, in <listcomp> str_values = [compat.as_bytes(x) for x in proto_values][SEP]File <*>python3.6/site-packages/tensorflow/python/util/compat.py, line 61, in as_bytes (bytes_or_text,))[SEP]TypeError: Expected binary or unicode string, got {'DispositionSoldAmount': <tf.Tensor 'random_shuffle_queue_DequeueMany:4' shape=(128,) dtype=float64>}",1
"File [FILE], line 2, in () model = InceptionV3(include_top=True,weights='imagenet')[SEP]File <*>python3.6/site-packages/keras/applications/__init__.py, line 28, in wrapper(*args, **kwargs) return base_fun(*args, **kwargs)[SEP]File <*>python3.6/site-packages/keras/applications/inception_v3.py, line 11, in InceptionV3(*args, **kwargs) return inception_v3.InceptionV3(*args, **kwargs)[SEP]File <*>python3.6/site-packages/keras_applications/inception_v3.py, line 157, in InceptionV3(include_top, weights, input_tensor, input_shape, pooling, classes, **kwargs) img_input = layers.Input(shape=input_shape)[SEP]File <*>python3.6/site-packages/keras/engine/input_layer.py, line 178, in Input(shape, batch_shape, name, dtype, sparse, tensor) input_tensor=tensor)[SEP]File <*>python3.6/site-packages/keras/legacy/interfaces.py, line 91, in wrapper(*args, **kwargs) return func(*args, **kwargs)[SEP]File <*>python3.6/site-packages/keras/engine/input_layer.py, line 39, in __init__(self, input_shape, batch_size, batch_input_shape, dtype, input_tensor, sparse, name) name = prefix + '_' + str(K.get_uid(prefix))[SEP]File <*>python3.6/site-packages/keras/backend/tensorflow_backend.py, line 74, in get_uid(prefix) graph = tf.get_default_graph()[SEP]AttributeError: module 'tensorflow' has no attribute 'get_default_graph'",1
"File [FILE], line 28, in () callbacks=callbacks_list[SEP]File <*>python3.6/dist-packages/tensorflow/python/keras/callbacks.py, line 247, in _call_batch_hook(self, mode, hook, batch, logs) batch_hook = getattr(callback, hook_name)[SEP]AttributeError: 'ModelCheckpoint' object has no attribute 'on_train_batch_begin'",1
"File [FILE], line 3, in <module> model.add(Embedding(vocabulary_size, embedding_size, input_length=MAXLEN))[SEP]File <*>/site-packages/keras/legacy/interfaces.py, line 91, in wrapper(*args, **kwargs) return func(*args, **kwargs)[SEP]File <*>/site-packages/keras/layers/embeddings.py, line 90, in __init__(self, input_dim, output_dim, embeddings_initializer, embeddings_regularizer, activity_regularizer, embeddings_constraint, mask_zero, input_length, **kwargs) super(Embedding, self).__init__(**kwargs)[SEP]File <*>/site-packages/keras/engine/base_layer.py, line 132, in __init__(self, **kwargs) name = _to_snake_case(prefix) + '_' + str(K.get_uid(prefix))[SEP]File <*>/site-packages/keras/backend/tensorflow_backend.py, line 74, in get_uid(prefix) graph = tf.get_default_graph()[SEP]AttributeError: module 'tensorflow' has no attribute 'get_default_graph'",1
"File [FILE], line 1, in <module>() plot_model(model, to_file='model_plot.png', show_shapes=True, show_layer_names=True)[SEP]File <*>python3.6/dist-packages/keras/utils/vis_utils.py, line 132, in plot_model(model, to_file, show_shapes, show_layer_names, rankdir) dot = model_to_dot(model, show_shapes, show_layer_names, rankdir)[SEP]File <*>python3.6/dist-packages/keras/utils/vis_utils.py, line 109, in model_to_dot(model, show_shapes, show_layer_names, rankdir) for inbound_layer in node.inbound_layers:[SEP]TypeError: 'InputLayer' object is not iterable",1
"File <*>/Testing.py, line 82, in <module> model.fit(x_train, y_train, batch_size=50, epochs = 3, callbacks= [tensorboard])[SEP]File <*>/site-packages/keras/engine/training.py, line 1178, in fit validation_freq=validation_freq)[SEP]File <*>/site-packages/keras/engine/training_arrays.py, line 125, in fit_loop callbacks.set_model(callback_model)[SEP]File <*>/site-packages/keras/callbacks.py, line 68, in set_model callback.set_model(model)[SEP]File <*>/site-packages/tensorflow/python/keras/callbacks.py, line 1509, in set_model if not model.run_eagerly:[SEP]AttributeError: 'Sequential' object has no attribute 'run_eagerly'",1
"File <stdin>, line 1, in <module> [CODE][SEP]File <*>python3.6/dist-packages/torch/cuda/__init__.py, line 386, in current_device _lazy_init()[SEP]File <*>python3.6/dist-packages/torch/cuda/__init__.py, line 192, in _lazy_init _check_driver()[SEP]File <*>python3.6/dist-packages/torch/cuda/__init__.py, line 111, in _check_driver of the CUDA driver."""""".format(str(torch._C._cuda_getDriverVersion())))[SEP]AssertionError: The NVIDIA driver on your system is too old (found version 10000). Please update your GPU driver by downloading and installing a new version from the URL: http://www.nvidia.com/Download/index.aspx Alternatively, go to: https://pytorch.org to install a PyTorch version that has been compiled with your version of the CUDA driver.",1
"File [FILE], line 1, in <module> last_hidden_state.shape[SEP]AttributeError: 'str' object has no attribute 'shape'",1
"File [FILE], line 9, in <module>() from keras.preprocessing import image[SEP]File <*>python3.7/dist-packages/keras/backend.py, line 37, in <module>() from tensorflow.python.eager.context import get_config[SEP]ImportError: cannot import name 'get_config' from 'tensorflow.python.eager.context' (/usr/local/lib/python3.7/dist-packages/tensorflow_core/python/eager/context.py)",1
"File <*>/main_dist_maml_l2l.py, line 1423, in <module> main()[SEP]File <*>/main_dist_maml_l2l.py, line 1365, in main train(args=args)[SEP]File <*>/main_dist_maml_l2l.py, line 1385, in train args.opt = move_opt_to_cherry_opt_and_sync_params(args) if is_running_parallel(args.rank) else args.opt[SEP]File <*>/distributed.py, line 456, in move_opt_to_cherry_opt_and_sync_params args.opt = cherry.optim.Distributed(args.model.parameters(), opt=args.opt, sync=syn)[SEP]File <*>python3.9/site-packages/cherry/optim.py, line 62, in __init__ self.sync_parameters()[SEP]File <*>python3.9/site-packages/cherry/optim.py, line 78, in sync_parameters dist.broadcast(p.data, src=root)[SEP]File <*>python3.9/site-packages/torch/distributed/distributed_c10d.py, line 1090, in broadcast work = default_pg.broadcast([tensor], opts)[SEP]RuntimeError: NCCL error in: ../torch/lib/c10d/ProcessGroupNCCL.cpp:911, unhandled system error, NCCL version 2.7.8",1
"File train.py, line 28, in <module> tf.keras.mixed_precision.set_global_policy('mixed_float16')[SEP]AttributeError: module 'tensorflow.keras.mixed_precision' has no attribute 'set_global_policy'",1
"File <*>/model_main_tf2.py, line 32, in <module> from object_detection import model_lib_v2[SEP]File <*>python3.7/dist-packages/object_detection/model_lib_v2.py, line 29, in <module> from object_detection import eval_util[SEP]File <*>python3.7/dist-packages/object_detection/eval_util.py, line 36, in <module> from object_detection.metrics import lvis_evaluation[SEP]File <*>python3.7/dist-packages/object_detection/metrics/lvis_evaluation.py, line 23, in <module> from lvis import results as lvis_results[SEP]File <*>python3.7/dist-packages/lvis/__init__.py, line 5, in <module> from lvis.vis import LVISVis[SEP]File <*>python3.7/dist-packages/lvis/vis.py, line 1, in <module> import cv2[SEP]File <*>python3.7/dist-packages/cv2/__init__.py, line 9, in <module> from .cv2 import _registerMatType[SEP]ImportError: cannot import name '_registerMatType' from 'cv2.cv2' (/usr/local/lib/python3.7/dist-packages/cv2/cv2.cpython-37m-x86_64-linux-gnu.so)",1
"File <*>/test.py, line 156, in <module> import network3[SEP]File <*>/network3.py, line 37, in <module> import theano[SEP]File <*>/site-packages/theano/__init__.py, line 124, in <module> from theano.scan_module import (scan, map, reduce, foldl, foldr, clone,[SEP]File <*>/site-packages/theano/scan_module/__init__.py, line 41, in <module> from theano.scan_module import scan_opt[SEP]File <*>/site-packages/theano/scan_module/scan_opt.py, line 60, in <module> from theano import tensor, scalar[SEP]File <*>/site-packages/theano/tensor/__init__.py, line 17, in <module> from theano.tensor import blas[SEP]File <*>/site-packages/theano/tensor/blas.py, line 155, in <module> from theano.tensor.blas_headers import blas_header_text[SEP]File <*>/site-packages/theano/tensor/blas_headers.py, line 987, in <module> if not config.blas.ldflags:[SEP]File <*>/site-packages/theano/configparser.py, line 332, in __get__ val_str = self.default()[SEP]File <*>/site-packages/theano/configdefaults.py, line 1284, in default_blas_ldflags blas_info = np.distutils.__config__.blas_opt_info[SEP]AttributeError: module 'numpy.distutils.__config__' has no attribute 'blas_opt_info'",1
"File <stdin>, line 1, in <module> [CODE][SEP]File <*>/site-packages/spyderlib/widgets/externalshell/sitecustomize.py, line 540, in runfile execfile(filename, namespace)[SEP]File <*>/untitled4.py, line 603, in <module> params = test_mlp()[SEP]File <*>/untitled4.py, line 553, in test_mlp minibatch_avg_cost = train_model(minibatch_index)[SEP]File <*>/site-packages/theano-0.6.0-py2.7.egg/theano/compile/function_module.py, line 588, in __call__ self.fn.thunks[self.fn.position_of_error])[SEP]File <*>/site-packages/theano-0.6.0-py2.7.egg/theano/compile/function_module.py, line 579, in __call__ outputs = self.fn()[SEP]ValueError: y_i value out of bounds Apply node that caused the error: CrossentropySoftmaxArgmax1HotWithBias(Dot22.0, b, Elemwise{Cast{int32}}.0) Inputs shapes: [(10L, 1L), (1L,), (10L,)] Inputs strides: [(8L, 8L), (8L,), (4L,)] Inputs types: [TensorType(float64, matrix), TensorType(float64, vector), TensorType(int32, vector)] Use the Theano flag 'exception_verbosity=high' for a debugprint of this apply node.",0
"File <string>, line 1, in <module> [CODE][SEP]ImportError: No module named caffe",0
"File test_theano.py, line 9, in <module> for iter in range(n_iters):[SEP]TypeError: range() integer end argument expected, got TensorVariable.",0
"File <stdin>, line 1, in <module> [CODE][SEP]File <*>python2.7/site-packages/tensorflow/__init__.py, line 8, in <module> from tensorflow.python import *[SEP]File <*>python2.7/site-packages/tensorflow/python/__init__.py, line 34, in <module> from tensorflow.python.client.client_lib import *[SEP]File <*>python2.7/site-packages/tensorflow/python/client/client_lib.py, line 39, in <module> from tensorflow.python.client.session import InteractiveSession[SEP]File <*>python2.7/site-packages/tensorflow/python/client/session.py, line 16, in <module> from tensorflow.python import pywrap_tensorflow as tf_session[SEP]File <*>python2.7/site-packages/tensorflow/python/pywrap_tensorflow.py, line 26, in <module> _pywrap_tensorflow = swig_import_helper()[SEP]File <*>python2.7/site-packages/tensorflow/python/pywrap_tensorflow.py, line 22, in swig_import_helper _mod = imp.load_module('_pywrap_tensorflow', fp, pathname, description)[SEP]ImportError: /home/zjuese/anaconda2/lib/python2.7/site-packages/tensorflow/python/_pywrap_tensorflow.so: undefined symbol: clock_gettime",0
"File <string>, line 1, in <module> [CODE][SEP]AttributeError: 'module' object has no attribute 'getsitepackages'",0
"File [FILE], line <*>, in [FUNC] [CODE][SEP]File <*>/site-packages/nolearn/lasagne/base.py, line 457, in fit self.initialize()[SEP]File <*>/site-packages/nolearn/lasagne/base.py, line 303, in initialize self.y_tensor_type,[SEP]File <*>/site-packages/nolearn/lasagne/base.py, line 435, in _create_iter_funcs allow_input_downcast=True,[SEP]File <*>/site-packages/theano/compile/function.py, line 317, in function output_keys=output_keys)[SEP]File <*>/site-packages/theano/compile/pfunc.py, line 526, in pfunc output_keys=output_keys)[SEP]File <*>/site-packages/theano/compile/function_module.py, line 1778, in orig_function defaults)[SEP]File <*>/site-packages/theano/compile/function_module.py, line 1642, in create input_storage=input_storage_lists, storage_map=storage_map)[SEP]File <*>/site-packages/theano/gof/link.py, line 690, in make_thunk storage_map=storage_map)[:3][SEP]File <*>/site-packages/theano/gof/vm.py, line 1037, in make_all no_recycling))[SEP]File <*>/site-packages/theano/gof/op.py, line 932, in make_thunk no_recycling)[SEP]File <*>/site-packages/theano/gof/op.py, line 850, in make_c_thunk output_storage=node_output_storage)[SEP]File <*>/site-packages/theano/gof/cc.py, line 1207, in make_thunk keep_lock=keep_lock)[SEP]File <*>/site-packages/theano/gof/cc.py, line 1152, in __compile__ keep_lock=keep_lock)[SEP]File <*>/site-packages/theano/gof/cc.py, line 1602, in cthunk_factory key=key, lnk=self, keep_lock=keep_lock)[SEP]File <*>/site-packages/theano/gof/cmodule.py, line 1174, in module_from_key module = lnk.compile_cmodule(location)[SEP]File <*>/site-packages/theano/gof/cc.py, line 1513, in compile_cmodule preargs=preargs)[SEP]File <*>/site-packages/theano/gof/cmodule.py, line 2187, in compile_str (status, compile_stderr.replace('\n', '. ')))[SEP]Exception: ('The following error happened while compiling the node', CorrMM{valid, (1, 1)}(input.input, Subtensor{::, ::, ::int64, ::int64}.0), '\n', ""Compilation failed (return status=1): C:\\Users\\Michal\\AppData\\Local\\Theano\\compiledir_Windows-8-6.2.9200-Intel64_Family_6_Model_60_Stepping_3_GenuineIntel-3.4.3-64\\tmpgdh7ov2i\\mod.cpp: In member function 'int {anonymous}::__struct_compiled_op_mf217e5b3a6b61b4ef70844368439f6cb::run()':\r. C:\\Users\\Michal\\AppData\\Local\\Theano\\compiledir_Windows-8-6.2.9200-Intel64_Family_6_Model_60_Stepping_3_GenuineIntel-3.4.3-64\\tmpgdh7ov2i\\mod.cpp:947:16: warning: converting to non-pointer type 'int' from NULL [-Wconversion-null]\r. kH = NULL;\r. ^\r. C:\\Users\\Michal\\AppData\\Local\\Theano\\compiledir_Windows-8-6.2.9200-Intel64_Family_6_Model_60_Stepping_3_GenuineIntel-3.4.3-64\\tmpgdh7ov2i\\mod.cpp:958:16: warning: converting to non-pointer type 'int' from NULL [-Wconversion-null]\r. kW = NULL;\r. ^\r. C:\\Users\\Michal\\AppData\\Local\\Temp\\cc67su6o.o: In function `corrMM(tagPyArrayObject*, tagPyArrayObject*, tagPyArrayObject*, int, int, int, int, int)':\r. C:/Users/Michal/AppData/Local/Theano/compiledir_Windows-8-6.2.9200-Intel64_Family_6_Model_60_Stepping_3_GenuineIntel-3.4.3-64/tmpgdh7ov2i/mod.cpp:431: undefined reference to `dgemm_'\r. C:/Users/Michal/AppData/Local/Theano/compiledir_Windows-8-6.2.9200-Intel64_Family_6_Model_60_Stepping_3_GenuineIntel-3.4.3-64/tmpgdh7ov2i/mod.cpp:528: undefined reference to `dgemm_'\r. C:/Users/Michal/AppData/Local/Theano/compiledir_Windows-8-6.2.9200-Intel64_Family_6_Model_60_Stepping_3_GenuineIntel-3.4.3-64/tmpgdh7ov2i/mod.cpp:483: undefined reference to `dgemm_'\r. collect2.exe: error: ld returned 1 exit status\r. "", '[CorrMM{valid, (1, 1)}(input.input, )]')",0
"File mnist_mlp.py, line 13, in <module> from keras.models import Sequential[SEP]File <*>python3.5/site-packages/Keras-0.3.1-py3.5.egg/keras/models.py, line 15, in <module> [CODE][SEP]File <*>python3.5/site-packages/Keras-0.3.1-py3.5.egg/keras/backend/__init__.py, line 46, in <module> [CODE][SEP]File <*>python3.5/site-packages/Keras-0.3.1-py3.5.egg/keras/backend/theano_backend.py, line 4, in <module> [CODE][SEP]File <*>python3.5/site-packages/Theano-0.8.0.dev0-py3.5.egg/theano/tensor/signal/downsample.py, line 2, in <module> import pool[SEP]ImportError: No module named 'pool'",0
"File <*>/lstmNetwork.py, line 54, in <module> model.fit(X_train, Y_train, batch_size=batch_size, nb_epoch=3, validation_data=(X_test, Y_test), show_accuracy=True)[SEP]File <*>python2.7/dist-packages/keras/models.py, line 581, in fit shuffle=shuffle, metrics=metrics)[SEP]File <*>python2.7/dist-packages/keras/models.py, line 239, in _fit outs = f(ins_batch)[SEP]File <*>python2.7/dist-packages/keras/backend/theano_backend.py, line 365, in __call__ return self.function(*inputs)[SEP]File <*>/function_module.py, line 786, in __call__ allow_downcast=s.allow_downcast)[SEP]File <*>/type.py, line 177, in filter data.shape))[SEP]TypeError: ('Bad input argument to theano function with name ""/usr/local/lib/python2.7/dist-packages/keras/backend/theano_backend.py:362"" at index 1(0-based)', 'Wrong number of dimensions: expected 3, got 2 with shape (5, 10).')",0
"File <*>/pool.py, line 119, in worker result = (True, func(*args, **kwds))[SEP]TypeError: func1() got multiple values for argument 'func'",0
"File <stdin>, line 1, in <module> [CODE][SEP]File <*>python3.4/site-packages/tensorflow/__init__.py, line 23, in <module> from tensorflow.python import *[SEP]File <*>python3.4/site-packages/tensorflow/python/__init__.py, line 48, in <module> from tensorflow.python import pywrap_tensorflow[SEP]File <*>python3.4/site-packages/tensorflow/python/pywrap_tensorflow.py, line 28, in <module> _pywrap_tensorflow = swig_import_helper()[SEP]File <*>python3.4/site-packages/tensorflow/python/pywrap_tensorflow.py, line 24, in swig_import_helper _mod = imp.load_module('_pywrap_tensorflow', fp, pathname, description)[SEP]File <*>python3.4/imp.py, line 243, in load_module return load_dynamic(name, filename, file)[SEP]ImportError: dlopen(/Library/Frameworks/Python.framework/Versions/3.4/lib/python3.4/site-packages/tensorflow/python/_pywrap_tensorflow.so, 10): Library not loaded: @rpath/libcudart.7.5.dylib",0
"File <*>python2.7/site-packages/theano/sandbox/gpuarray/__init__.py, line 20, in <module> import pygpu[SEP]File <*>/__init__.py, line 7, in <module> from . import gpuarray, elemwise, reduction[SEP]File <*>/elemwise.py, line 3, in <module> from .dtypes import dtype_to_ctype, get_common_dtype[SEP]File <*>/dtypes.py, line 6, in <module> from . import gpuarray[SEP]ImportError: cannot import name gpuarray",0
"File <*>/main, line 132, in <module> apply_weights_OP = tf.matmul(activation_OP, Weights, name=""apply_weights"")[SEP]File <*>python3.5/dist-packages/tensorflow/python/ops/math_ops.py, line 1346, in matmul name=name)[SEP]File <*>python3.5/dist-packages/tensorflow/python/ops/gen_math_ops.py, line 1271, in _mat_mul transpose_b=transpose_b, name=name)[SEP]File <*>python3.5/dist-packages/tensorflow/python/framework/op_def_library.py, line 703, in apply_op op_def=op_def)[SEP]File <*>python3.5/dist-packages/tensorflow/python/framework/ops.py, line 2312, in create_op set_shapes_for_outputs(ret)[SEP]File <*>python3.5/dist-packages/tensorflow/python/framework/ops.py, line 1704, in set_shapes_for_outputs shapes = shape_func(op)[SEP]File <*>python3.5/dist-packages/tensorflow/python/framework/common_shapes.py, line 94, in matmul_shape inner_a.assert_is_compatible_with(inner_b)[SEP]File <*>python3.5/dist-packages/tensorflow/python/framework/tensor_shape.py, line 108, in assert_is_compatible_with % (self, other))[SEP]ValueError: Dimensions 3 and 4 are not compatible",0
"File <*>/mlp_.py, line 152, in <module> train_auc = sess.run(auc, feed_dict={X: batch_xs, y: batch_ys, dropout_keep_prob:1.})[SEP]File <*>python3.5/dist-packages/tensorflow/python/client/session.py, line 372, in run run_metadata_ptr)[SEP]File <*>python3.5/dist-packages/tensorflow/python/client/session.py, line 636, in _run feed_dict_string, options, run_metadata)[SEP]File <*>python3.5/dist-packages/tensorflow/python/client/session.py, line 708, in _do_run target_list, options, run_metadata)[SEP]File <*>python3.5/dist-packages/tensorflow/python/client/session.py, line 728, in _do_call raise type(e)(node_def, op, message)[SEP]tensorflow.python.framework.errors.FailedPreconditionError: Attempting to use uninitialized value auc/false_positives [[Node: auc/false_positives/read = Identity[T=DT_FLOAT, _class=[""loc:@auc/false_positives""], _device=""/job:localhost/replica:0/task:0/cpu:0""](auc/false_positives)]]",0
"File <string>, line 1, in <module> [CODE][SEP]File <*>/setup.py, line 339, in <module> cmdclass=cmdclass,[SEP]File <*>python3.5/core.py, line 148, in setup dist.run_commands()[SEP]File <*>python3.5/dist.py, line 955, in run_commands self.run_command(cmd)[SEP]File <*>python3.5/dist.py, line 974, in run_command cmd_obj.run()[SEP]File <*>python3.5/site-packages/setuptools-28.7.1-py3.5.egg/setuptools/command/egg_info.py, line 279, in run [CODE][SEP]File <*>python3.5/site-packages/setuptools-28.7.1-py3.5.egg/setuptools/command/egg_info.py, line 306, in find_sources [CODE][SEP]File <*>python3.5/site-packages/setuptools-28.7.1-py3.5.egg/setuptools/command/egg_info.py, line 533, in run [CODE][SEP]File <*>python3.5/site-packages/setuptools-28.7.1-py3.5.egg/setuptools/command/egg_info.py, line 562, in add_defaults [CODE][SEP]File <*>python3.5/site-packages/setuptools-28.7.1-py3.5.egg/setuptools/command/py36compat.py, line 36, in add_defaults [CODE][SEP]File <*>python3.5/site-packages/setuptools-28.7.1-py3.5.egg/setuptools/command/py36compat.py, line 119, in _add_defaults_ext [CODE][SEP]File <*>python3.5/cmd.py, line 299, in get_finalized_command cmd_obj.ensure_finalized()[SEP]File <*>python3.5/cmd.py, line 107, in ensure_finalized self.finalize_options()[SEP]File <*>python3.5/site-packages/Cython/Distutils/build_ext.py, line 19, in finalize_options self.distribution.ext_modules)[SEP]File <*>python3.5/site-packages/Cython/Build/Dependencies.py, line 809, in cythonize aliases=aliases)[SEP]File <*>python3.5/site-packages/Cython/Build/Dependencies.py, line 752, in create_extension_list **kwds))[SEP]TypeError: __init__() missing 3 required positional arguments: 'feature_name', 'feature_description', and 'feature_check'",0
"File test.py, line 45, in <module> (x_train, _), (x_test, _) = data[SEP]ValueError: too many values to unpack (expected 2)",0
"File <*>python3.5/site-packages/tensorflow/python/client/session.py, line 972, in _do_call return fn(*args)[SEP]File <*>python3.5/site-packages/tensorflow/python/client/session.py, line 954, in _run_fn status, run_metadata)[SEP]File <*>python3/contextlib.py, line 66, in __exit__ next(self.gen)[SEP]File <*>python3.5/site-packages/tensorflow/python/framework/errors.py, line 463, in raise_exception_on_not_ok_status pywrap_tensorflow.TF_GetCode(status))[SEP]tensorflow.python.framework.errors.InvalidArgumentError: Input to reshape is a tensor with 313600 values, but the requested shape requires a multiple of 4608 [[Node: Reshape_1 = Reshape[T=DT_FLOAT, Tshape=DT_INT32, _device=""/job:localhost/replica:0/task:0/cpu:0""](dropout/mul, Reshape_1/shape)]]",0
"File neural_network.py, line 48, in <module> print(sess.run(loss), feed_dict={xs:x_data, ys:y_data})[SEP]File <*>python35/site-packages/tensorflow/python/client/session.py, line 717, in run run_metadata_ptr)[SEP]File <*>python35/site-packages/tensorflow/python/client/session.py, line 915, in _run feed_dict_string, options, run_metadata)[SEP]File <*>python35/site-packages/tensorflow/python/client/session.py, line 965, in _do_run target_list, options, run_metadata)[SEP]File <*>python35/site-packages/tensorflow/python/client/session.py, line 985, in _do_call raise type(e)(node_def, op, message)[SEP]tensorflow.python.framework.errors.InvalidArgumentError: You must feed a value for placeholder tensor 'Placeholder' with dtype float [[Node: Placeholder = Placeholder[dtype=DT_FLOAT, shape=[], _device=""/job:localhost/replica:0/task:0/cpu:0""]()]]",0
"File <*>/site-packages/tensorflow/python/framework/tensor_shape.py, line 451, in __init__ dims_iter = iter(dims)[SEP]File <*>/site-packages/tensorflow/python/framework/ops.py, line 510, in __iter__ raise TypeError(""'Tensor' object is not iterable."")[SEP]TypeError: 'Tensor' object is not iterable.",0
"File <*>/test_placeholder.py, line 5, in <module> input = tf.placeholder(tf.int32, [batchSize, 5])[SEP]File <*>/site-packages/tensorflow/python/ops/array_ops.py, line 1579, in placeholder shape = tensor_shape.as_shape(shape)[SEP]File <*>/site-packages/tensorflow/python/framework/tensor_shape.py, line 821, in as_shape return TensorShape(shape)[SEP]File <*>/site-packages/tensorflow/python/framework/tensor_shape.py, line 457, in __init__ self._dims = [as_dimension(d) for d in dims_iter][SEP]File <*>/site-packages/tensorflow/python/framework/tensor_shape.py, line 457, in <listcomp> self._dims = [as_dimension(d) for d in dims_iter][SEP]File <*>/site-packages/tensorflow/python/framework/tensor_shape.py, line 378, in as_dimension return Dimension(value)[SEP]File <*>/site-packages/tensorflow/python/framework/tensor_shape.py, line 33, in __init__ self._value = int(value)[SEP]TypeError: int() argument must be a string, a bytes-like object or a number, not 'Tensor'",0
"File test_keras.py, line 52, in <module> model.fit(x_train, y_train, validation_data=(x_test, y_test), nb_epoch=epochs, batch_size=32)[SEP]File <*>python2.7/dist-packages/keras/models.py, line 664, in fit sample_weight=sample_weight)[SEP]File <*>python2.7/dist-packages/keras/engine/training.py, line 1068, in fit batch_size=batch_size)[SEP]File <*>python2.7/dist-packages/keras/engine/training.py, line 981, in _standardize_user_data exception_prefix='model input')[SEP]File <*>python2.7/dist-packages/keras/engine/training.py, line 113, in standardize_input_data str(array.shape))[SEP]ValueError: Error when checking model input: expected convolution2d_input_1 to have shape (None, 3, 32, 32) but got array with shape (50000, 32, 32, 3)",0
"File <string>, line 1, in <module> [CODE][SEP]IOError: [Errno 2] No such file or directory: '/private/var/folders/1p/7km73m0s2cvdfb1js3ct8_mh0000gn/T/pip-JMMIRP-build/setup.py'",0
"File <*>/site-packages/tensorflow/python/client/session.py, line 10, in [FUNC] [CODE][SEP]File <*>/contextlib.py, line 66, in __exit__ next(self.gen)[SEP]File <*>/contextlib.py, line 66, in [FUNC] [CODE][SEP]n_on_not_ok_status pywrap_tensorflow.TF_GetCode(status)) tensorflow.python.framework.errors_impl.InvalidArgumentError: Incompatible shapes: [10000,10] vs. [10000] [[Node: sub = Sub[T=DT_FLOAT, _device=""/job:localhost/replica:0/task:0/gpu:0""](Add, _recv_Placeholder_1_0/_7)]]",0
"File <*>python2.7/dist-packages/tensorflow/python/__init__.py, line 61, in <module> from tensorflow.python import pywrap_tensorflow[SEP]File <*>python2.7/dist-packages/tensorflow/python/pywrap_tensorflow.py, line 28, in <module> _pywrap_tensorflow = swig_import_helper()[SEP]File <*>python2.7/dist-packages/tensorflow/python/pywrap_tensorflow.py, line 24, in swig_import_helper _mod = imp.load_module('_pywrap_tensorflow', fp, pathname, description)[SEP]ImportError: libcudart.so.8.0: cannot open shared object file: No such file or directory Failed to load the native TensorFlow runtime.",0
"File pymask.py, line 303, in <module> main(sys.argv)[SEP]File pymask.py, line 285, in main keras.callbacks.ProgbarLogger()[SEP]File <*>python3.6/site-packages/keras/engine/training.py, line 1557, in fit_generator class_weight=class_weight)[SEP]File <*>python3.6/site-packages/keras/engine/training.py, line 1314, in train_on_batch check_batch_axis=True)[SEP]File <*>python3.6/site-packages/keras/engine/training.py, line 1029, in _standardize_user_data exception_prefix='model input')[SEP]File <*>python3.6/site-packages/keras/engine/training.py, line 52, in standardize_input_data str(names))[SEP]ValueError: No data provided for ""input_1"". Need data for each key in: ['input_1']",0
"File <*>/tfclass.py, line 36, in <module> summary_writer = tf.summary.FileWriter('/home/sergo/work/logs',graph_def = sess.graph_def)[SEP]File <*>python3.6/site-packages/tensorflow/python/summary/writer/writer.py, line 308, in __init__ event_writer = EventFileWriter(logdir, max_queue, flush_secs)[SEP]File <*>python3.6/site-packages/tensorflow/python/summary/writer/event_file_writer.py, line 69, in __init__ gfile.MakeDirs(self._logdir)[SEP]File <*>python3.6/site-packages/tensorflow/python/lib/io/file_io.py, line 301, in recursive_create_dir pywrap_tensorflow.RecursivelyCreateDir(compat.as_bytes(dirname), status)[SEP]File <*>python3.6/contextlib.py, line 89, in __exit__ next(self.gen)[SEP]File <*>python3.6/site-packages/tensorflow/python/framework/errors_impl.py, line 469, in raise_exception_on_not_ok_status pywrap_tensorflow.TF_GetCode(status))[SEP]tensorflow.python.framework.errors_impl.UnimplementedError: /home/sergo",0
"File <*>python3.5/site-packages/tensorflow/python/client/session.py, line 1022, in _do_call return fn(*args)[SEP]File <*>python3.5/site-packages/tensorflow/python/client/session.py, line 1004, in _run_fn status, run_metadata)[SEP]File <*>python3.5/contextlib.py, line 66, in __exit__ next(self.gen)[SEP]File <*>python3.5/site-packages/tensorflow/python/framework/errors_impl.py, line 469, in raise_exception_on_not_ok_status pywrap_tensorflow.TF_GetCode(status))[SEP]tensorflow.python.framework.errors_impl.ResourceExhaustedError: OOM when allocating tensor with shape[14525,14000] [[Node: rnn/basic_lstm_cell/weights/Initializer/random_uniform = Add[T=DT_FLOAT, _class=[""loc:@rnn/basic_lstm_cell/weights""], _device=""/job:localhost/replica:0/task:0/gpu:0""](rnn/basic_lstm_cell/weights/Initializer/random_uniform/mul, rnn/basic_lstm_cell/weights/Initializer/random_uniform/min)]]",0
"File <*>/pydevd.py, line 1599, in <module> globals = debugger.run(setup['file'], None, None, is_module)[SEP]File <*>/pydevd.py, line 1026, in run pydev_imports.execfile(file, globals, locals) # execute the script[SEP]File <*>/_pydev_execfile.py, line 18, in execfile exec(compile(contents+""\n"", file, 'exec'), glob, loc)[SEP]File worker.py, line 426, in <module> main()[SEP]File worker.py, line 418, in main run(args, server)[SEP]File worker.py, line 174, in run sess.run(trainer.sync)[SEP]File <*>python3.6/site-packages/tensorflow/python/client/session.py, line 889, in run run_metadata_ptr)[SEP]File <*>python3.6/site-packages/tensorflow/python/client/session.py, line 1120, in _run feed_dict_tensor, options, run_metadata)[SEP]File <*>python3.6/site-packages/tensorflow/python/client/session.py, line 1317, in _do_run options, run_metadata)[SEP]File <*>python3.6/site-packages/tensorflow/python/client/session.py, line 1336, in _do_call raise type(e)(node_def, op, message)[SEP]tensorflow.python.framework.errors_impl.UnavailableError: Trying to connect an http1.x server",0
"File <*>python3.5/dist-packages/Theano-1.0.0rc1-py3.5.egg/theano/gpuarray/__init__.py, line 220, in <module> use(config.device)[SEP]File <*>python3.5/dist-packages/Theano-1.0.0rc1-py3.5.egg/theano/gpuarray/__init__.py, line 207, in use init_dev(device, preallocate=preallocate)[SEP]File <*>python3.5/dist-packages/Theano-1.0.0rc1-py3.5.egg/theano/gpuarray/__init__.py, line 152, in init_dev pygpu.blas.gemm(0, tmp, tmp, 0, tmp, overwrite_c=True)[SEP]File <*>/blas.pyx, line 149, in pygpu.blas.gemm [CODE][SEP]File <*>/blas.pyx, line 47, in pygpu.blas.pygpu_blas_rgemm [CODE][SEP]pygpu.gpuarray.GpuArrayException: (b'cuLinkCreate: CUDA_ERROR_JIT_COMPILER_NOT_FOUND: PTX JIT compiler library not found', 3)",0
"File <stdin>, line 1, in <module> [CODE][SEP]RuntimeError: matrices expected, got 1D, 2D tensors at /Users/soumith/code/builder/wheel/pytorch-src/torch/lib/TH/generic/THTensorMath.c:1288",0
"File <*>/site-packages/tensorflow/python/platform/self_check.py, line 75, in preload_check ctypes.WinDLL(build_info.cudart_dll_name)[SEP]File <*>/__init__.py, line 351, in __init__ self._handle = _dlopen(self._name, mode)[SEP]OSError: [WinError 126] This specified module could not be found",0
"File <*>/neuralnetworktest.py, line 45, in <module> train(x)[SEP]File <*>/neuralnetworktest.py, line 29, in train prediction = neuralNetwork(inputdata)[SEP]File <*>/neuralnetworktest.py, line 22, in neuralNetwork FinalH2 = tf.add(tf.matmul(H1, H2[""weights""]), H2[""biases""])[SEP]File <*>/site-packages/tensorflow/python/ops/math_ops.py, line 1844, in matmul a = ops.convert_to_tensor(a, name=""a"")[SEP]File <*>/site-packages/tensorflow/python/framework/ops.py, line 836, in convert_to_tensor as_ref=False)[SEP]File <*>/site-packages/tensorflow/python/framework/ops.py, line 926, in internal_convert_to_tensor ret = conversion_func(value, dtype=dtype, name=name, as_ref=as_ref)[SEP]File <*>/site-packages/tensorflow/python/framework/constant_op.py, line 229, in _constant_tensor_conversion_function return constant(v, dtype=dtype, name=name)[SEP]File <*>/site-packages/tensorflow/python/framework/constant_op.py, line 208, in constant value, dtype=dtype, shape=shape, verify_shape=verify_shape))[SEP]File <*>/site-packages/tensorflow/python/framework/tensor_util.py, line 472, in make_tensor_proto ""supported type."" % (type(values), values))[SEP]TypeError: Failed to convert object of type <class 'dict'> to Tensor.",0
"File RF_2.py, line 312, in <module> main()[SEP]File RF_2.py, line 298, in main train_eval(x_train, y_train, x_validation, y_validation, x_test, y_test, num_tree)[SEP]File RF_2.py, line 221, in train_eval prob0 = results[0][eval_metrics.INFERENCE_PROB_NAME][SEP]KeyError: 'probabilities'",0
"File <*>python3.4/site-packages/tensorflow/python/client/session.py, line 1323, in _do_call return fn(*args)[SEP]File <*>python3.4/site-packages/tensorflow/python/client/session.py, line 1302, in _run_fn status, run_metadata)[SEP]File <*>python3.4/site-packages/tensorflow/python/framework/errors_impl.py, line 473, in __exit__ c_api.TF_GetCode(self.status.status))[SEP]tensorflow.python.framework.errors_impl.InvalidArgumentError: NaN: average_gradients(expanded_g) : Tensor had Inf and NaN values [[Node: CheckNumerics_30 = CheckNumerics[T=DT_FLOAT, message=""NaN: average_gradients(expanded_g)"", _device=""/job:localhost/replica:0/task:0/device:CPU:0""](ExpandDims_30)]] [[Node: tower_6/total_loss/_2216 = _Send[T=DT_FLOAT, client_terminated=false, recv_device=""/job:localhost/replica:0/task:0/device:CPU:0"", send_device=""/job:localhost/replica:0/task:0/device:GPU:6"", send_device_incarnation=1, tensor_name=""edge_4923_tower_6/total_loss"", _device=""/job:localhost/replica:0/task:0/device:GPU:6""](tower_6/total_loss)]]",0
"File cnn_base.py, line 1704, in <module> training()[SEP]File cnn_base.py, line 1312, in training nan_debug, _, loss_value = sess.run([check_op, train_op, loss])[SEP]File <*>python3.4/site-packages/tensorflow/python/client/session.py, line 889, in run run_metadata_ptr)[SEP]File <*>python3.4/site-packages/tensorflow/python/client/session.py, line 1120, in _run feed_dict_tensor, options, run_metadata)[SEP]File <*>python3.4/site-packages/tensorflow/python/client/session.py, line 1317, in _do_run options, run_metadata)[SEP]File <*>python3.4/site-packages/tensorflow/python/client/session.py, line 1336, in _do_call raise type(e)(node_def, op, message)[SEP]tensorflow.python.framework.errors_impl.InvalidArgumentError: NaN: average_gradients(expanded_g) : Tensor had Inf and NaN values [[Node: CheckNumerics_30 = CheckNumerics[T=DT_FLOAT, message=""NaN: average_gradients(expanded_g)"", _device=""/job:localhost/replica:0/task:0/device:CPU:0""](ExpandDims_30)]] [[Node: tower_6/total_loss/_2216 = _Send[T=DT_FLOAT, client_terminated=false, recv_device=""/job:localhost/replica:0/task:0/device:CPU:0"", send_device=""/job:localhost/replica:0/task:0/device:GPU:6"", send_device_incarnation=1, tensor_name=""edge_4923_tower_6/total_loss"", _device=""/job:localhost/replica:0/task:0/device:GPU:6""](tower_6/total_loss)]]",0
"File <*>python3.5/dist-packages/tensorflow/python/pywrap_tensorflow.py, line 58, in <module> from tensorflow.python.pywrap_tensorflow_internal import *[SEP]File <*>python3.5/dist-packages/tensorflow/python/pywrap_tensorflow_internal.py, line 28, in <module> _pywrap_tensorflow_internal = swig_import_helper()[SEP]File <*>python3.5/dist-packages/tensorflow/python/pywrap_tensorflow_internal.py, line 24, in swig_import_helper _mod = imp.load_module('_pywrap_tensorflow_internal', fp, pathname, description)[SEP]File <*>python3.5/imp.py, line 242, in load_module return load_dynamic(name, filename, file)[SEP]File <*>python3.5/imp.py, line 342, in load_dynamic return _load(spec)[SEP]ImportError: libcublas.so.9.0: cannot open shared object file: No such file or directory",0
"File <*>/hackerearth_project.py, line 90, in <module> model(X_train, X_test, Y_train, Y_test)[SEP]File <*>/hackerearth_project.py, line 71, in model optimizer = tf.train.AdamOptimizer(learning_rate=learning_rate, beta1=beta1, beta2=beta2).minimize(cost)[SEP]File <*>/site-packages/tensorflow/python/training/optimizer.py, line 343, in minimize grad_loss=grad_loss)[SEP]File <*>/site-packages/tensorflow/python/training/optimizer.py, line 394, in compute_gradients self._assert_valid_dtypes([loss])[SEP]File <*>/site-packages/tensorflow/python/training/optimizer.py, line 543, in _assert_valid_dtypes dtype = t.dtype.base_dtype[SEP]AttributeError: 'NoneType' object has no attribute 'dtype'",0
"File <*>python3.6/configparser.py, line 1138, in _unify_values sectiondict = self._sections[section][SEP]KeyError: 'blas'",0
"File <*>/site-packages/tensorflow/python/framework/common_shapes.py, line 686, in _call_cpp_shape_fn_impl input_tensors_as_shapes, status)[SEP]File <*>/site-packages/tensorflow/python/framework/errors_impl.py, line 473, in __exit__ c_api.TF_GetCode(self.status.status))[SEP]tensorflow.python.framework.errors_impl.InvalidArgumentError: Can not squeeze dim[1], expected a dimension of 1, got 3 for 'sparse_softmax_cross_entropy_loss/remove_squeezable_dimensions/Squeeze' (op: 'Squeeze') with input shapes: [100,3].",0
"File <*>/cnn_mnist.py, line 214, in <module> tf.app.run()[SEP]File <*>/site-packages/tensorflow/python/platform/app.py, line 124, in run _sys.exit(main(argv))[SEP]File <*>/cnn_mnist.py, line 203, in main hooks=[logging_hook])[SEP]File <*>/site-packages/tensorflow/python/estimator/estimator.py, line 314, in train loss = self._train_model(input_fn, hooks, saving_listeners)[SEP]File <*>/site-packages/tensorflow/python/estimator/estimator.py, line 743, in _train_model features, labels, model_fn_lib.ModeKeys.TRAIN, self.config)[SEP]File <*>/site-packages/tensorflow/python/estimator/estimator.py, line 725, in _call_model_fn model_fn_results = self._model_fn(features=features, **kwargs)[SEP]File <*>/cnn_mnist.py, line 67, in cnn_model_fn loss = tf.losses.sparse_softmax_cross_entropy(labels=labels, logits=logits)[SEP]File <*>/site-packages/tensorflow/python/ops/losses/losses_impl.py, line 790, in sparse_softmax_cross_entropy labels, logits, weights, expected_rank_diff=1)[SEP]File <*>/site-packages/tensorflow/python/ops/losses/losses_impl.py, line 720, in _remove_squeezable_dimensions labels, predictions, expected_rank_diff=expected_rank_diff)[SEP]File <*>/site-packages/tensorflow/python/ops/confusion_matrix.py, line 76, in remove_squeezable_dimensions labels = array_ops.squeeze(labels, [-1])[SEP]File <*>/site-packages/tensorflow/python/ops/array_ops.py, line 2490, in squeeze return gen_array_ops._squeeze(input, axis, name)[SEP]File <*>/site-packages/tensorflow/python/ops/gen_array_ops.py, line 7049, in _squeeze ""Squeeze"", input=input, squeeze_dims=axis, name=name)[SEP]File <*>/site-packages/tensorflow/python/framework/op_def_library.py, line 787, in _apply_op_helper op_def=op_def)[SEP]File <*>/site-packages/tensorflow/python/framework/ops.py, line 3162, in create_op compute_device=compute_device)[SEP]File <*>/site-packages/tensorflow/python/framework/ops.py, line 3208, in _create_op_helper set_shapes_for_outputs(op)[SEP]File <*>/site-packages/tensorflow/python/framework/ops.py, line 2427, in set_shapes_for_outputs return _set_shapes_for_outputs(op)[SEP]File <*>/site-packages/tensorflow/python/framework/ops.py, line 2400, in _set_shapes_for_outputs shapes = shape_func(op)[SEP]File <*>/site-packages/tensorflow/python/framework/ops.py, line 2330, in call_with_requiring return call_cpp_shape_fn(op, require_shape_fn=True)[SEP]File <*>/site-packages/tensorflow/python/framework/common_shapes.py, line 627, in call_cpp_shape_fn require_shape_fn)[SEP]File <*>/site-packages/tensorflow/python/framework/common_shapes.py, line 691, in _call_cpp_shape_fn_impl raise ValueError(err.message)[SEP]ValueError: Can not squeeze dim[1], expected a dimension of 1, got 3 for 'sparse_softmax_cross_entropy_loss/remove_squeezable_dimensions/Squeeze' (op: 'Squeeze') with input shapes: [100,3].",0
"File <*>/lstm.py, line 131, in <module> main()[SEP]File <*>/lstm.py, line 111, in main model.fit_generator(generator=training_sequence)[SEP]File <*>/site-packages/keras/legacy/interfaces.py, line 91, in wrapper return func(*args, **kwargs)[SEP]File <*>/site-packages/keras/models.py, line 1253, in fit_generator initial_epoch=initial_epoch)[SEP]File <*>/site-packages/keras/engine/training.py, line 2244, in fit_generator class_weight=class_weight)[SEP]File <*>/site-packages/keras/engine/training.py, line 1884, in train_on_batch class_weight=class_weight)[SEP]File <*>/site-packages/keras/engine/training.py, line 1487, in _standardize_user_data exception_prefix='target')[SEP]File <*>/site-packages/keras/engine/training.py, line 113, in _standardize_input_data 'with shape ' + str(data_shape))[SEP]ValueError: Error when checking target: expected dense_1 to have 2 dimensions, but got array with shape (1, 1034, 9)",0
"File experiment.py, line 65, in <module> batches_per_lot=batches_per_lot, sigma=dp_sigma, dp=dp)[SEP]File <*>/model.py, line 247, in GAN_solvers G_solver = tf.train.AdamOptimizer().minimize(G_loss_mean_over_batch, var_list=generator_vars)[SEP]File <*>python3.5/dist-packages/tensorflow/python/training/optimizer.py, line 343, in minimize grad_loss=grad_loss)[SEP]File <*>python3.5/dist-packages/tensorflow/python/training/optimizer.py, line 414, in compute_gradients colocate_gradients_with_ops=colocate_gradients_with_ops)[SEP]File <*>python3.5/dist-packages/tensorflow/python/ops/gradients_impl.py, line 609, in gradients % (op.name, i, t_in.shape, in_grad.shape))[SEP]ValueError: Incompatible shapes between op input and calculated input gradient. Forward operation: generator/conv2d_transpose_1. Input index: 2. Original input shape: (?, 4, 15, 1). Calculated input gradient shape: (?, 5, 15, 1)",0
"File processing_2a_1.py, line 125, in <module> history=model.fit(X_train, Y_train, batch_size=batch_size, validation_data=(X_val,Y_val), epochs=nr_of_epochs,verbose=2)[SEP]File <*>/models.py, line 871, in fit [CODE][SEP]File <*>/training.py, line 1524, in fit [CODE][SEP]File <*>/training.py, line 1382, in _standardize_user_data [CODE][SEP]File <*>/training.py, line 132, in _standardize_input_data [CODE][SEP]ValueError: Error when checking target: expected dense_2 to have 3 dimensions, but got array with shape (1496000, 1)",0
"File <*>/site-packages/theano/gof/lazylinker_c.py, line 81, in <module> actual_version, force_compile, _need_reload))[SEP]ImportError: Version check of the existing lazylinker compiled file. Looking for version 0.211, but found None. Extra debug information: force_compile=False, _need_reload=True",0
"File test.py, line 13, in <module> layers.Dense(64, activation='sigmoid')[SEP]NameError: name 'layers' is not defined",0
"File <stdin>, line 1, in <module> [CODE][SEP]File <*>python3.5/site-packages/tensorflow/__init__.py, line 22, in <module> from tensorflow.python import pywrap_tensorflow # pylint: disable=unused-import[SEP]File <*>python3.5/site-packages/tensorflow/python/__init__.py, line 52, in <module> from tensorflow.core.framework.graph_pb2 import *[SEP]ImportError: No module named 'tensorflow.core'",0
"File main.py, line 109, in <module> train(loader_train, model, criterion, optimizer)[SEP]File main.py, line 54, in train optimizer.step()[SEP]File <*>python3.6/site-packages/torch/optim/sgd.py, line 93, in step d_p.add_(weight_decay, p.data)[SEP]RuntimeError: cuda runtime error (59) : device-side assert triggered at /opt/conda/conda-bld/pytorch_1524584710464/work/aten/src/THC/generated/../generic/THCTensorMathPointwise.cu:265",0
"File deparser.py, line 402, in <module> d.train()[SEP]File deparser.py, line 331, in train total, correct, avgloss = self.train_util()[SEP]File deparser.py, line 362, in train_util loss = self.step(X_train, Y_train, correct, total)[SEP]File deparser.py, line 214, in step loss = nn.CrossEntropyLoss()(out.long(), y)[SEP]File <*>python3.5/site-packages/torch/nn/modules/module.py, line 477, in __call__ result = self.forward(*input, **kwargs)[SEP]File <*>python3.5/site-packages/torch/nn/modules/loss.py, line 862, in forward ignore_index=self.ignore_index, reduction=self.reduction)[SEP]File <*>python3.5/site-packages/torch/nn/functional.py, line 1550, in cross_entropy return nll_loss(log_softmax(input, 1), target, weight, None, ignore_index, None, reduction)[SEP]File <*>python3.5/site-packages/torch/nn/functional.py, line 975, in log_softmax return input.log_softmax(dim)[SEP]RuntimeError: ""host_softmax"" not implemented for 'torch.cuda.LongTensor'",0
"File pytorch.py, line 14, in <module> test_tensor = torch.tensor(test)[SEP]ValueError: could not determine the shape of object type 'DataFrame'",0
"File <*>/testing.py, line 10, in <module> model = Model(inputs=model_in, outputs=output)[SEP]File <*>/site-packages/keras/legacy/interfaces.py, line 91, in wrapper return func(*args, **kwargs)[SEP]File <*>/site-packages/keras/engine/network.py, line 93, in __init__ self._init_graph_network(*args, **kwargs)[SEP]File <*>/site-packages/keras/engine/network.py, line 237, in _init_graph_network self.inputs, self.outputs)[SEP]File <*>/site-packages/keras/engine/network.py, line 1353, in _map_graph_network tensor_index=tensor_index)[SEP]File <*>/site-packages/keras/engine/network.py, line 1340, in build_map node_index, tensor_index)[SEP]File <*>/site-packages/keras/engine/network.py, line 1312, in build_map node = layer._inbound_nodes[node_index][SEP]AttributeError: 'NoneType' object has no attribute '_inbound_nodes'",0
"File lstm_test.py, line 152, in <module> model.fit(samples_train, labels_train, epochs=1, batch_size=1)[SEP]File <*>/site-packages/keras/models.py, line 1002, in fit validation_steps=validation_steps)[SEP]File <*>/site-packages/keras/engine/training.py, line 1630, in fit batch_size=batch_size)[SEP]File <*>/site-packages/keras/engine/training.py, line 1476, in _standardize_user_data exception_prefix='input')[SEP]File <*>/site-packages/keras/engine/training.py, line 113, in _standardize_input_data 'with shape ' + str(data_shape))[SEP]ValueError: Error when checking input: expected lstm_1_input to have 3 dimensions, but got array with shape (134, 1)",0
"File run.py, line 64, in <module> model.fit(images, labels, epochs=1, steps_per_epoch=2)[SEP]File <*>python2.7/site-packages/tensorflow/python/keras/engine/training.py, line 1363, in fit validation_steps=validation_steps)[SEP]File <*>python2.7/site-packages/tensorflow/python/keras/engine/training_arrays.py, line 205, in fit_loop outs = f(ins)[SEP]File <*>python2.7/site-packages/tensorflow/python/keras/backend.py, line 2914, in __call__ fetched = self._callable_fn(*array_vals)[SEP]File <*>python2.7/site-packages/tensorflow/python/client/session.py, line 1382, in __call__ run_metadata_ptr)[SEP]File <*>python2.7/site-packages/tensorflow/python/framework/errors_impl.py, line 519, in __exit__ c_api.TF_GetCode(self.status.status))[SEP]tensorflow.python.framework.errors_impl.InvalidArgumentError: Matrix size-incompatible: In[0]: [10000,1], In[1]: [3,1] [[Node: rgb_to_grayscale/Tensordot/MatMul = MatMul[T=DT_FLOAT, transpose_a=false, transpose_b=false](rgb_to_grayscale/Tensordot/Reshape, rgb_to_grayscale/Tensordot/Reshape_1)]] [[Node: IteratorGetNext = IteratorGetNext[output_shapes=[[?,100,100,1], [?,1]], output_types=[DT_FLOAT, DT_FLOAT], _device=""/job:localhost/replica:0/task:0/device:CPU:0""](OneShotIterator)]]",0
"File <*>python3.6/site-packages/pip/_vendor/pkg_resources/__init__.py, line 2869, in _dep_map return self.__dep_map[SEP]File <*>python3.6/site-packages/pip/_vendor/pkg_resources/__init__.py, line 2663, in __getattr__ raise AttributeError(attr)[SEP]AttributeError: _DistInfoDistribution__dep_map",0
"File noveou_train_netvlad.py, line 226, in <module> minu = keras.layers.Maximum()( [ minu, K.zeros(nN, nP) ] )[SEP]File <*>python2.7/dist-packages/keras/engine/base_layer.py, line 457, in __call__ output = self.call(inputs, **kwargs)[SEP]File <*>python2.7/dist-packages/keras/layers/merge.py, line 115, in call return self._merge_function(reshaped_inputs)[SEP]File <*>python2.7/dist-packages/keras/layers/merge.py, line 301, in _merge_function output = K.maximum(output, inputs[i])[SEP]File <*>python2.7/dist-packages/keras/backend/tensorflow_backend.py, line 1672, in maximum return tf.maximum(x, y)[SEP]File <*>python2.7/dist-packages/tensorflow/python/ops/gen_math_ops.py, line 4707, in maximum ""Maximum"", x=x, y=y, name=name)[SEP]File <*>python2.7/dist-packages/tensorflow/python/framework/op_def_library.py, line 546, in _apply_op_helper inferred_from[input_arg.type_attr]))[SEP]TypeError: Input 'y' of 'Maximum' Op has type string that does not match type float32 of argument 'x'.",0
"File <string>, line 1, in <module> [CODE][SEP]File <*>/setup.py, line 25, in <module> cythonize(ext_modules)[SEP]File <*>/site-packages/Cython/Build/Dependencies.py, line 956, in cythonize aliases=aliases)[SEP]File <*>/site-packages/Cython/Build/Dependencies.py, line 801, in create_extension_list for file in nonempty(sorted(extended_iglob(filepattern)), ""'%s' doesn't match any files"" % filepattern):[SEP]File <*>/site-packages/Cython/Build/Dependencies.py, line 111, in nonempty raise ValueError(error_msg)[SEP]ValueError: 'pycocotools/_mask.pyx' doesn't match any files",0
"File <*>/QuestionStackoverflow.py, line 26, in <module> q_vals_v = net(state_v.view(1, state_v.shape[0], state_v.shape[1]))[SEP]File <*>python3.5/site-packages/torch/nn/modules/module.py, line 477, in __call__ result = self.forward(*input, **kwargs)[SEP]File <*>/QuestionStackoverflow.py, line 15, in forward out = self.hidden2tag(out)[SEP]File <*>python3.5/site-packages/torch/nn/modules/, line 55, in forward return F.linear(input, self.weight, self.bias)[SEP]File <*>python3.5/site-packages/torch/nn/functional.py, line 1022, in linear if input.dim() == 2 and bias is not None:[SEP]AttributeError: 'tuple' object has no attribute 'dim'",0
"File <*>/site-packages/keras/engine/topology.py, line 442, in assert_input_compatibility K.is_keras_tensor(x)[SEP]File <*>/site-packages/keras/backend/tensorflow_backend.py, line 468, in is_keras_tensor raise ValueError('Unexpectedly found an instance of type `' + str(type(x)) + '`. '[SEP]ValueError: Unexpectedly found an instance of type `<class 'keras.layers.core.Masking'>`. Expected a symbolic tensor instance.",0
"File <ipython-input-286-e49b6fac918b>, line 1, in <module> output=model(input_)[SEP]File <*>/site-packages/torch/nn/modules/module.py, line 489, in __call__ result = self.forward(*input, **kwargs)[SEP]TypeError: forward() missing 1 required positional argument: 'p'",0
"File <*>python3.6/site-packages/torch/utils/data/dataloader.py, line 138, in _worker_loop samples = collate_fn([dataset[i] for i in batch_indices])[SEP]File <*>python3.6/site-packages/torch/utils/data/dataloader.py, line 138, in <listcomp> samples = collate_fn([dataset[i] for i in batch_indices])[SEP]File <*>python3.6/site-packages/torch/utils/data/dataset.py, line 103, in __getitem__ return self.dataset[self.indices[idx]][SEP]File <ipython-input-27-107e03bc3c6a>, line 12, in __getitem__ x = torch.tensor(self.x_data.iloc[index].values, dtype=torch.float)[SEP]File <*>python3.6/site-packages/pandas/core/indexing.py, line 1478, in __getitem__ return self._getitem_axis(maybe_callable, axis=axis)[SEP]File <*>python3.6/site-packages/pandas/core/indexing.py, line 2091, in _getitem_axis return self._get_list_axis(key, axis=axis)[SEP]File <*>python3.6/site-packages/pandas/core/indexing.py, line 2070, in _get_list_axis return self.obj._take(key, axis=axis)[SEP]File <*>python3.6/site-packages/pandas/core/generic.py, line 2789, in _take verify=True)[SEP]File <*>python3.6/site-packages/pandas/core/internals.py, line 4537, in take new_labels = self.axes[axis].take(indexer)[SEP]File <*>python3.6/site-packages/pandas/core/indexes/base.py, line 2195, in take return self._shallow_copy(taken)[SEP]File <*>python3.6/site-packages/pandas/core/indexes/range.py, line 267, in _shallow_copy return self._int64index._shallow_copy(values, **kwargs)[SEP]File <*>python3.6/site-packages/pandas/core/indexes/numeric.py, line 68, in _shallow_copy return self._shallow_copy_with_infer(values=values, **kwargs)[SEP]File <*>python3.6/site-packages/pandas/core/indexes/base.py, line 538, in _shallow_copy_with_infer if not len(values) and 'dtype' not in kwargs:[SEP]TypeError: object of type 'numpy.int64' has no len()",0
"File <*>/tensorboard-script.py, line 6, in <module> from tensorboard.main import run_main[SEP]File <*>/site-packages/tensorboard/main.py, line 40, in <module> from tensorboard import default[SEP]File <*>/site-packages/tensorboard/default.py, line 38, in <module> from tensorboard.plugins.beholder import beholder_plugin[SEP]File <*>/site-packages/tensorboard/plugins/beholder/__init__.py, line 15, in <module> from tensorboard.plugins.beholder.beholder import Beholder[SEP]File <*>/site-packages/tensorboard/plugins/beholder/beholder.py, line 25, in <module> from tensorboard.plugins.beholder import im_util[SEP]File <*>/site-packages/tensorboard/plugins/beholder/im_util.py, line 89, in <module> class PNGDecoder(util.PersistentOpEvaluator):[SEP]AttributeError: module 'tensorboard.util' has no attribute 'PersistentOpEvaluator'",0
"File <*>python3.6/site-packages/theano/compile/function_module.py, line 884, in __call__ self.fn() if output_subset is None else\[SEP]ValueError: Input dimension mis-match. (input[0].shape[1] = 50, input[1].shape[1] = 100)",0
"File <stdin>, line 1, in <module> [CODE][SEP]RuntimeError: Could not infer dtype of generator",0
"File <*>/min_working_example.py, line 37, in <module> model.fit(data_generator)[SEP]File <*>python3.7/site-packages/tensorflow/python/keras/engine/training.py, line 873, in fit steps_name='steps_per_epoch')[SEP]File <*>python3.7/site-packages/tensorflow/python/keras/engine/training_arrays.py, line 352, in model_iteration batch_outs = f(ins_batch)[SEP]File <*>python3.7/site-packages/tensorflow/python/keras/backend.py, line 3217, in __call__ outputs = self._graph_fn(*converted_inputs)[SEP]File <*>python3.7/site-packages/tensorflow/python/eager/function.py, line 558, in __call__ return self._call_flat(args)[SEP]File <*>python3.7/site-packages/tensorflow/python/eager/function.py, line 627, in _call_flat outputs = self._inference_function.call(ctx, args)[SEP]File <*>python3.7/site-packages/tensorflow/python/eager/function.py, line 397, in call (len(args), len(list(self.signature.input_arg))))[SEP]ValueError: Arguments and signature arguments do not match: 21 23",0
"File <*>/train.py, line 184, in <module> tf.app.run()[SEP]File <*>python3.6/site-packages/tensorflow/python/platform/app.py, line 125, in run _sys.exit(main(argv))[SEP]File <*>python3.6/site-packages/tensorflow/python/util/deprecation.py, line 324, in new_func return func(*args, **kwargs)[SEP]File <*>/train.py, line 180, in main graph_hook_fn=graph_rewriter_fn)[SEP]File <*>/trainer.py, line 416, in train saver=saver)[SEP]File <*>python3.6/site-packages/tensorflow/contrib/slim/python/slim/learning.py, line 785, in train ignore_live_threads=ignore_live_threads)[SEP]File <*>python3.6/site-packages/tensorflow/python/training/supervisor.py, line 832, in stop ignore_live_threads=ignore_live_threads)[SEP]File <*>python3.6/site-packages/tensorflow/python/training/coordinator.py, line 389, in join six.reraise(*self._exc_info_to_raise)[SEP]File <*>python3.6/site-packages/six.py, line 693, in reraise raise value[SEP]File <*>python3.6/site-packages/tensorflow/python/training/queue_runner_impl.py, line 257, in _run enqueue_callable()[SEP]File <*>python3.6/site-packages/tensorflow/python/client/session.py, line 1257, in _single_operation_run self._call_tf_sessionrun(None, {}, [], target_list, None)[SEP]File <*>python3.6/site-packages/tensorflow/python/client/session.py, line 1407, in _call_tf_sessionrun run_metadata)[SEP]tensorflow.python.framework.errors_impl.ResourceExhaustedError: OOM when allocating tensor with shape[15,1,1755,2777,3] and type float on /job:localhost/replica:0/task:0/device:CPU:0 by allocator cpu [[{{node batch}}]]",0
"File <stdin>, line 1, in <module> [CODE][SEP]ImportError: cannot import name 'estimator' from 'tensorflow' (/home/cjs/.conda/envs/my-env/lib/python3.7/site-packages/tensorflow/__init__.py)",0
"File <*>python3.5/dist-packages/tensorflow/python/pywrap_tensorflow.py, line 58, in <module> from tensorflow.python.pywrap_tensorflow_internal import *[SEP]File <*>python3.5/dist-packages/tensorflow/python/pywrap_tensorflow_internal.py, line 28, in <module> _pywrap_tensorflow_internal = swig_import_helper()[SEP]File <*>python3.5/dist-packages/tensorflow/python/pywrap_tensorflow_internal.py, line 24, in swig_import_helper _mod = imp.load_module('_pywrap_tensorflow_internal', fp, pathname, description)[SEP]File <*>python3.5/imp.py, line 242, in load_module return load_dynamic(name, filename, file)[SEP]File <*>python3.5/imp.py, line 342, in load_dynamic return _load(spec)[SEP]ImportError: /usr/lib/aarch64-linux-gnu/libstdc++.so.6: version `GLIBCXX_3.4.22' not found (required by /usr/local/lib/python3.5/dist-packages/tensorflow/python/_pywrap_tensorflow_internal.so)",0
"File <*>/mnist.py, line 69, in <module> train(epoch)[SEP]File <*>/mnist.py, line 60, in train loss = criterion(out, target)[SEP]File <*>python3.6/site-packages/torch/nn/modules/module.py, line 493, in __call__ result = self.forward(*input, **kwargs)[SEP]File <*>python3.6/site-packages/torch/nn/modules/loss.py, line 942, in forward ignore_index=self.ignore_index, reduction=self.reduction)[SEP]File <*>python3.6/site-packages/torch/nn/functional.py, line 2056, in cross_entropy return nll_loss(log_softmax(input, 1), target, weight, None, ignore_index, None, reduction)[SEP]File <*>python3.6/site-packages/torch/nn/functional.py, line 1869, in nll_loss .format(input.size(0), target.size(0)))[SEP]ValueError: Expected input batch_size (12) to match target batch_size (64).",0
"File <*>/train_fit.py, line 286, in <module> validation_steps=None) #devset_steps_per_epoch)[SEP]File <*>/site-packages/tensorflow/python/keras/engine/training.py, line 780, in fit steps_name='steps_per_epoch')[SEP]File <*>/site-packages/tensorflow/python/keras/engine/training_arrays.py, line 374, in model_iteration callbacks._call_batch_hook(mode, 'end', batch_index, batch_logs)[SEP]File <*>/site-packages/tensorflow/python/keras/callbacks.py, line 248, in _call_batch_hook batch_hook(batch, logs)[SEP]File <*>/site-packages/tensorflow/python/keras/callbacks.py, line 531, in on_train_batch_end self.on_batch_end(batch, logs=logs)[SEP]File <*>/site-packages/tensorflow/python/keras/callbacks_v1.py, line 362, in on_batch_end profiler.save(self.log_dir, profiler.stop())[SEP]File <*>/site-packages/tensorflow/python/eager/profiler.py, line 144, in save gfile.MakeDirs(plugin_dir)[SEP]File <*>/site-packages/tensorflow/python/lib/io/file_io.py, line 438, in recursive_create_dir recursive_create_dir_v2(dirname)[SEP]File <*>/site-packages/tensorflow/python/lib/io/file_io.py, line 453, in recursive_create_dir_v2 pywrap_tensorflow.RecursivelyCreateDir(compat.as_bytes(path))[SEP]tensorflow.python.framework.errors_impl.NotFoundError: Failed to create a directory: ./logs\plugins\profile\2019-07-02_13-04-26; No such file or directory",0
"File <*>python3.6/site-packages/tensorflow/python/framework/importer.py, line 427, in import_graph_def graph._c_graph, serialized, options) # pylint: disable=protected-access[SEP]tensorflow.python.framework.errors_impl.InvalidArgumentError: Input 1 of node StatefulPartitionedCall was passed float from conv2d/kernel:0 incompatible with expected resource.",0
"File <*>/tensorrt.py, line 23, in <module> converter.save(saved_model_dir_trt)[SEP]File <*>python3.6/site-packages/tensorflow/python/compiler/tensorrt/trt_convert.py, line 822, in save super(TrtGraphConverter, self).save(output_saved_model_dir)[SEP]File <*>python3.6/site-packages/tensorflow/python/compiler/tensorrt/trt_convert.py, line 432, in save importer.import_graph_def(self._converted_graph_def, name="""")[SEP]File <*>python3.6/site-packages/tensorflow/python/util/deprecation.py, line 507, in new_func return func(*args, **kwargs)[SEP]File <*>python3.6/site-packages/tensorflow/python/framework/importer.py, line 431, in import_graph_def raise ValueError(str(e))[SEP]ValueError: Input 1 of node StatefulPartitionedCall was passed float from conv2d/kernel:0 incompatible with expected resource.",0
"File <*>python3.6/managers.py, line 228, in serve_client request = recv()[SEP]File <*>python3.6/connection.py, line 251, in recv return _ForkingPickler.loads(buf.getbuffer())[SEP]File <*>python3.6/site-packages/torch/multiprocessing/reductions.py, line 276, in rebuild_storage_fd fd = df.detach()[SEP]File <*>python3.6/resource_sharer.py, line 58, in detach return reduction.recv_handle(conn)[SEP]File <*>python3.6/reduction.py, line 182, in recv_handle return recvfds(s, 1)[0][SEP]File <*>python3.6/reduction.py, line 161, in recvfds len(ancdata))[SEP]RuntimeError: received 0 items of ancdata",0
"File <string>, line 1, in <module> [CODE][SEP]File <*>python3.6/site-packages/torch/cuda/__init__.py, line 163, in _lazy_init torch._C._cuda_init()[SEP]RuntimeError: cuda runtime error (38) : no CUDA-capable device is detected at /opt/conda/conda-bld/pytorch_1556653099582/work/aten/src/THC/THCGeneral.cpp:51",0
"File <ipython-input-12-f8636d3ba083>, line 26, in <module> predict(model, ""/home/x/閺傚洦銆?Deep_Learning/pytorch/MNIST/test/2/QQ閹搭亜娴?0191022093955.png"")[SEP]File <ipython-input-12-f8636d3ba083>, line 9, in predict test_image_tensor = transform(test_image)[SEP]File <*>python3.6/site-packages/torchvision/transforms/transforms.py, line 61, in __call__ img = t(img)[SEP]File <*>python3.6/site-packages/torchvision/transforms/transforms.py, line 166, in __call__ return F.normalize(tensor, self.mean, self.std, self.inplace)[SEP]File <*>python3.6/site-packages/torchvision/transforms/functional.py, line 217, in normalize tensor.sub_(mean[:, None, None]).div_(std[:, None, None])[SEP]RuntimeError: The size of tensor a (4) must match the size of tensor b (3) at non-singleton dimension 0",0
"File <input>, line 1, in <module> [CODE][SEP]AttributeError: module 'keras.applications' has no attribute 'resnet_v2'",0
"File <*>/train_model.py, line 110, in <module> model.fit(train_dataset, epochs=5)[SEP]File <*>/site-packages/tensorflow_core/python/keras/engine/training.py, line 728, in fit 1/Unknown - 0s 13ms/step 1/Unknown - 0s 13ms/step use_multiprocessing=use_multiprocessing)[SEP]File <*>/site-packages/tensorflow_core/python/keras/engine/training_v2.py, line 324, in fit total_epochs=epochs)[SEP]File <*>/site-packages/tensorflow_core/python/keras/engine/training_v2.py, line 123, in run_one_epoch batch_outs = execution_function(iterator)[SEP]File <*>/site-packages/tensorflow_core/python/keras/engine/training_v2_utils.py, line 86, in execution_function distributed_function(input_fn))[SEP]File <*>/site-packages/tensorflow_core/python/eager/def_function.py, line 457, in __call__ result = self._call(*args, **kwds)[SEP]File <*>/site-packages/tensorflow_core/python/eager/def_function.py, line 503, in _call self._initialize(args, kwds, add_initializers_to=initializer_map)[SEP]File <*>/site-packages/tensorflow_core/python/eager/def_function.py, line 408, in _initialize *args, **kwds))[SEP]File <*>/site-packages/tensorflow_core/python/eager/function.py, line 1848, in _get_concrete_function_internal_garbage_collected graph_function, _, _ = self._maybe_define_function(args, kwargs)[SEP]File <*>/site-packages/tensorflow_core/python/eager/function.py, line 2150, in _maybe_define_function graph_function = self._create_graph_function(args, kwargs)[SEP]File <*>/site-packages/tensorflow_core/python/eager/function.py, line 2041, in _create_graph_function capture_by_value=self._capture_by_value),[SEP]File <*>/site-packages/tensorflow_core/python/framework/func_graph.py, line 915, in func_graph_from_py_func func_outputs = python_func(*func_args, **func_kwargs)[SEP]File <*>/site-packages/tensorflow_core/python/eager/def_function.py, line 358, in wrapped_fn return weak_wrapped_fn().__wrapped__(*args, **kwds)[SEP]File <*>/site-packages/tensorflow_core/python/keras/engine/training_v2_utils.py, line 66, in distributed_function model, input_iterator, mode)[SEP]File <*>/site-packages/tensorflow_core/python/keras/engine/training_v2_utils.py, line 112, in _prepare_feed_values inputs, targets, sample_weights = _get_input_from_iterator(inputs)[SEP]File <*>/site-packages/tensorflow_core/python/keras/engine/training_v2_utils.py, line 149, in _get_input_from_iterator distribution_strategy_context.get_strategy(), x, y, sample_weights)[SEP]File <*>/site-packages/tensorflow_core/python/keras/distribute/distributed_training_utils.py, line 308, in validate_distributed_dataset_inputs x_values_list = validate_per_replica_inputs(distribution_strategy, x)[SEP]File <*>/site-packages/tensorflow_core/python/keras/distribute/distributed_training_utils.py, line 356, in validate_per_replica_inputs validate_all_tensor_shapes(x, x_values)[SEP]File <*>/site-packages/tensorflow_core/python/keras/distribute/distributed_training_utils.py, line 373, in validate_all_tensor_shapes x_shape = x_values[0].shape.as_list()[SEP]File <*>/site-packages/tensorflow_core/python/framework/tensor_shape.py, line 1171, in as_list raise ValueError(""as_list() is not defined on an unknown TensorShape."")[SEP]ValueError: as_list() is not defined on an unknown TensorShape.",0
"File <*>python3.6/dist-packages/torch/utils/data/_utils/worker.py, line 178, in _worker_loop data = fetcher.fetch(index)[SEP]File <*>python3.6/dist-packages/torch/utils/data/_utils/fetch.py, line 44, in fetch data = [self.dataset[idx] for idx in possibly_batched_index][SEP]File <*>python3.6/dist-packages/torch/utils/data/_utils/fetch.py, line 44, in <listcomp> data = [self.dataset[idx] for idx in possibly_batched_index][SEP]File <ipython-input-180-0b00b175e18c>, line 72, in __getitem__ image = self.transform(image)[SEP]File <*>python3.6/dist-packages/torchvision/transforms/transforms.py, line 70, in __call__ img = t(img)[SEP]File <*>python3.6/dist-packages/torchvision/transforms/transforms.py, line 175, in __call__ return F.normalize(tensor, self.mean, self.std, self.inplace)[SEP]File <*>python3.6/dist-packages/torchvision/transforms/functional.py, line 217, in normalize tensor.sub_(mean[:, None, None]).div_(std[:, None, None])[SEP]RuntimeError: output with shape [1, 224, 224] doesn't match the broadcast shape [3, 224, 224]",0
"File <*>python3.7/site-packages/tensorflow_core/python/eager/execute.py, line 61, in quick_execute num_outputs)[SEP]TypeError: An op outside of the function building code is being passed",0
"File <*>/Wrong.py, line 33, in <module> net.forward(dataset[0])[SEP]File <*>/Wrong.py, line 23, in forward x = F.relu(self.layer(x))[SEP]File <*>/site-packages/torch/nn/modules/module.py, line 532, in __call__ result = self.forward(*input, **kwargs)[SEP]File <*>/site-packages/torch/nn/modules/, line 87, in forward return F.linear(input, self.weight, self.bias)[SEP]File <*>/site-packages/torch/nn/functional.py, line 1372, in linear output = input.matmul(weight.t())[SEP]RuntimeError: Expected object of scalar type Double but got scalar type Float for argument #2 'mat2' in call to _th_mm",0
"File <*>/mmconvert, line 8, in <module> sys.exit(_main())[SEP]File <*>python3.5/dist-packages/mmdnn/conversion/_script/convert.py, line 102, in _main ret = convertToIR._convert(ir_args)[SEP]File <*>python3.5/dist-packages/mmdnn/conversion/_script/convertToIR.py, line 62, in _convert from mmdnn.conversion.tensorflow.tensorflow_parser import TensorflowParser[SEP]File <*>python3.5/dist-packages/mmdnn/conversion/tensorflow/tensorflow_parser.py, line 15, in <module> from tensorflow.tools.graph_transforms import TransformGraph[SEP]ImportError: No module named 'tensorflow.tools.graph_transforms'",0
"File pytorch_test.py, line 21, in <module> a_copy.resize_(1, 1)[SEP]RuntimeError: cannot resize variables that require grad",0
"File trial_mult-ips.py, line 240, in <module> predops=p.map(prediction,new_all_t)[SEP]File <*>python2.7/pool.py, line 253, in map return self.map_async(func, iterable, chunksize).get()[SEP]File <*>python2.7/pool.py, line 572, in get raise self._value[SEP]NotImplementedError: numpy() is only available when eager execution is enabled.",0
"File main.py, line 95, in <module> model.load_weights(checkpoint_dir)[SEP]File <*>python3.7/site-packages/tensorflow/python/keras/engine/training.py, line 162, in load_weights return super(Model, self).load_weights(filepath, by_name)[SEP]File <*>python3.7/site-packages/tensorflow/python/keras/engine/network.py, line 1398, in load_weights status.assert_nontrivial_match()[SEP]File <*>python3.7/site-packages/tensorflow/python/training/tracking/util.py, line 917, in assert_nontrivial_match return self.assert_consumed()[SEP]File <*>python3.7/site-packages/tensorflow/python/training/tracking/util.py, line 894, in assert_consumed (unused_attributes,))[SEP]AssertionError: Some objects had attributes which were not restored: {<tf.Variable 'embedding_1/embeddings:0' shape=(65, 256) dtype=float32, numpy= array([[-0.00044268, -0.02351714, -0.01139065, ..., -0.00327835, 0.00074228, -0.00383734], [-0.02313181, 0.04697707, -0.02350216, ..., 0.040385 , 0.03087702, 0.02765551], [ 0.0410727 , 0.00130001, 0.0051438 , ..., 0.02899202, 0.04258115, -0.03773504], ..., [-0.03134514, 0.01370119, 0.00993627, ..., -0.02257681, 0.02617678, 0.03761976], [-0.02954974, 0.02407967, 0.02768463, ..., -0.0056519 , -0.01507735, 0.04617763], [-0.04113789, -0.03544737, 0.01056757, ..., 0.01236727, -0.01791535, -0.01635399]], dtype=float32)>: ['embedding_1/embeddings'], <tf.Variable 'dense_1/kernel:0' shape=(1024, 65) dtype=float32, numpy= array([[-6.7811467e-02, -2.5536597e-02, 5.1763237e-02, ..., -6.9665730e-02, 3.9457709e-02, -5.3290475e-02], [ 1.5835620e-02, -3.0763537e-02, -7.4058644e-02, ..., 3.8087368e-05, -9.1508478e-03, 5.5485427e-02], [ 3.8143486e-02, 8.8131428e-04, -2.3478847e-02, ..., -1.5135627e-02, -5.2146181e-02, 7.1185097e-02], ..., [-6.6591002e-02, 4.7627889e-02, 5.7474524e-02, ..., 4.1528463e-02, 4.6467118e-02, -3.0670539e-02], [-5.0804108e-02, 5.4505378e-02, -1.5776977e-03, ..., 2.1875933e-02, -2.9637258e-02, 2.0201296e-02], [-4.7325939e-02, -8.0013275e-03, -3.6348965e-02, ..., -7.0560835e-02, -4.9752403e-02, 1.0509960e-02]], dtype=float32)>: ['dense_1/kernel'], <tf.Variable 'dense_1/bias:0' shape=(65,) dtype=float32, numpy= array([0., 0., 0., 0., 0., 0., 0., 0., 0., 0., 0., 0., 0., 0., 0., 0., 0., 0., 0., 0., 0., 0., 0., 0., 0., 0., 0., 0., 0., 0., 0., 0., 0., 0., 0., 0., 0., 0., 0., 0., 0., 0., 0., 0., 0., 0., 0., 0., 0., 0., 0., 0., 0., 0., 0., 0., 0., 0., 0., 0., 0., 0., 0., 0., 0.], dtype=float32)>: ['dense_1/bias'], <tf.Variable 'gru_1/kernel:0' shape=(256, 3072) dtype=float32, numpy= array([[ 0.00432818, 0.03131782, 0.00038544, ..., -0.00559966, 0.03458985, -0.03219106], [-0.00865119, 0.01648769, -0.00768028, ..., 0.01366192, -0.03043955, -0.01382086], [-0.01379537, 0.00547716, -0.00385967, ..., -0.00027269, -0.01285852, 0.0377048 ], ..., [-0.01940641, 0.01454895, 0.03349226, ..., -0.04234404, -0.02699661, 0.0376601 ], [ 0.00186675, -0.00547577, -0.02205843, ..., -0.01287581, -0.02314153, 0.04158166], [ 0.00954719, -0.02883693, -0.03259185, ..., -0.02587803, 0.02906795, -0.00559821]], dtype=float32)>: ['gru_1/kernel'], <tf.Variable 'gru_1/recurrent_kernel:0' shape=(1024, 3072) dtype=float32, numpy= array([[ 9.11542401e-03, 1.50135346e-02, 2.96630897e-02, ..., 2.25223936e-02, 2.31253020e-02, -2.96920985e-02], [-2.21075956e-02, -8.46013427e-06, -2.16848943e-02, ..., -1.26914177e-02, -3.49153839e-02, -3.01396102e-02], [-3.59148793e-02, 9.98445973e-03, 2.60963626e-02, ..., 3.15430500e-02, 1.28889643e-02, 3.37569825e-02], ..., [ 3.39106433e-02, 6.54980540e-03, -1.27352085e-02, ..., -4.14674729e-03, 3.53236459e-02, -1.36333425e-02], [-3.50691415e-02, -1.76392253e-02, 1.67468414e-02, ..., -2.06982102e-02, -1.06042419e-02, 2.26641595e-02], [-1.14825107e-02, -3.46554294e-02, -1.83847174e-03, ..., 2.25809850e-02, 2.45791934e-02, -2.70933360e-02]], dtype=float32)>: ['gru_1/recurrent_kernel'], <tf.Variable 'gru_1/bias:0' shape=(2, 3072) dtype=float32, numpy= array([[0., 0., 0., ..., 0., 0., 0.], [0., 0., 0., ..., 0., 0., 0.]], dtype=float32)>: ['gru_1/bias']}",0
"File <*>python3.6/dist-packages/optkeras/optkeras.py, line 230, in synch_with_optuna self.best_trial = self.study.best_trial[SEP]File <*>python3.6/dist-packages/optuna/study.py, line 97, in best_trial return copy.deepcopy(self._storage.get_best_trial(self._study_id))[SEP]File <*>python3.6/dist-packages/optuna/storages/in_memory.py, line 293, in get_best_trial raise ValueError(""No trials are completed yet."")[SEP]ValueError: No trials are completed yet.",0
"File <*>python3.6/pool.py, line 119, in worker result = (True, func(*args, **kwds))[SEP]File <*>python3.6/pool.py, line 44, in mapstar return list(map(*args))[SEP]File <ipython-input-35-6529ab6dac60>, line 11, in X_power_func X_power = X**j[SEP]RuntimeError: CUDA error: initialization error",0
"File [FILE], line <*>, in [FUNC] [CODE][SEP]File <*>python3.7/site-packages/tensorflow_estimator/python/estimator/estimator.py, line 349, in train loss = self._train_model(input_fn, hooks, saving_listeners)[SEP]File <*>python3.7/site-packages/tensorflow_estimator/python/estimator/estimator.py, line 1182, in _train_model return self._train_model_default(input_fn, hooks, saving_listeners)[SEP]File <*>python3.7/site-packages/tensorflow_estimator/python/estimator/estimator.py, line 1208, in _train_model_default self._get_features_and_labels_from_input_fn(input_fn, ModeKeys.TRAIN))[SEP]File <*>python3.7/site-packages/tensorflow_estimator/python/estimator/estimator.py, line 1044, in _get_features_and_labels_from_input_fn self._call_input_fn(input_fn, mode))[SEP]File <*>python3.7/site-packages/tensorflow_estimator/python/estimator/estimator.py, line 1137, in _call_input_fn return input_fn(**kwargs)[SEP]File [FILE], line 1137, in [FUNC] [CODE][SEP]File <*>python3.7/site-packages/tensorflow/python/data/ops/dataset_ops.py, line 406, in __iter__ raise RuntimeError(""__iter__() is only supported inside of tf.function ""[SEP]RuntimeError: __iter__() is only supported inside of tf.function or when eager execution is enabled.",0
"File foo_test.py, line 21, in test3 self.assertEqual(3,4)[SEP]AssertionError: 3 != 4",0
"File <*>python3.4/site-packages/theano/gof/op.py, line 517, in __call__(self, *inputs, **kwargs) storage_map[ins] = [self._get_test_value(ins)][SEP]File <*>python3.4/site-packages/theano/gof/op.py, line 479, in _get_test_value(cls, v) raise AttributeError('%s has no test value' % v)[SEP]AttributeError: x has no test value",0
"File [FILE], line 16, in <module>() caffe.Net(net_param, caffe.TEST)[SEP]ArgumentError: Python argument types in Net.__init__(Net, NetParameter, int) did not match C++ signature: __init__(boost::python::api::object, std::string, std::string, int) __init__(boost::python::api::object, std::string, int)",0
"File [FILE], line 9, in <module>() example, label = sess.run([features, col1])[SEP]File <*>python2.7/site-packages/tensorflow/python/client/session.pyc, line 345, in run(self, fetches, feed_dict) results = self._do_run(target_list, unique_fetch_targets, feed_dict_string)[SEP]File <*>python2.7/site-packages/tensorflow/python/client/session.pyc, line 419, in _do_run(self, target_list, fetch_list, feed_dict) e.code)[SEP]InvalidArgumentError: Field 1 in record 0 is not a valid int32: 0.766126609",0
"File [FILE], line 1, in <module>() saver.restore(sess, ""params.ckpt"")[SEP]File <*>python3.5/site-packages/tensorflow/python/training/saver.py, line 891, in restore(self, sess, save_path) sess.run([self._restore_op_name], {self._filename_tensor_name: save_path})[SEP]File <*>python3.5/site-packages/tensorflow/python/client/session.py, line 368, in run(self, fetches, feed_dict) results = self._do_run(target_list, unique_fetch_targets, feed_dict_string)[SEP]File <*>python3.5/site-packages/tensorflow/python/client/session.py, line 428, in _do_run(self, target_list, fetch_list, feed_dict) target_list)[SEP]SystemError: <built-in function delete_Status> returned a result with an error set",0
"File [FILE], line 3, in <module>() batch_size=16)[SEP]File <*>python2.7/site-packages/keras/models.pyc, line 402, in fit(self, x, y, batch_size, nb_epoch, verbose, callbacks, validation_split, validation_data, shuffle, class_weight, sample_weight, **kwargs) sample_weight=sample_weight)[SEP]File <*>python2.7/site-packages/keras/engine/training.pyc, line 971, in fit(self, x, y, batch_size, nb_epoch, verbose, callbacks, validation_split, validation_data, shuffle, class_weight, sample_weight) batch_size=batch_size)[SEP]File <*>python2.7/site-packages/keras/engine/training.pyc, line 911, in _standardize_user_data(self, x, y, sample_weight, class_weight, check_batch_dim, batch_size) check_loss_and_target_compatibility(y, self.loss_functions, self.internal_output_shapes)[SEP]File <*>python2.7/site-packages/keras/engine/training.pyc, line 184, in check_loss_and_target_compatibility(targets, losses, output_shapes) ' while using as loss `categorical_crossentropy`. '[SEP]Exception: You are passing a target array of shape (10105, 1) while using as loss `categorical_crossentropy`. `categorical_crossentropy` expects targets to be binary matrices (1s and 0s) of shape (samples, classes). If your targets are integer classes, you can convert them to the expected format via: ``` from keras.utils.np_utils import to_categorical y_binary = to_categorical(y_int) ``` Alternatively, you can use the loss function `sparse_categorical_crossentropy` instead, which does expect integer targets.",0
"File [FILE], line 30, in <module>() sess.run(optimizer, feed_dict={X: x, y: y})[SEP]File <*>python2.7/site-packages/tensorflow/python/client/session.pyc, line 340, in run(self, fetches, feed_dict, options, run_metadata) run_metadata_ptr)[SEP]File <*>python2.7/site-packages/tensorflow/python/client/session.pyc, line 542, in _run(self, handle, fetches, feed_dict, options, run_metadata) + e.args[0])[SEP]TypeError: Cannot interpret feed_dict key as Tensor: Can not convert a float64 into a Tensor.",0
"File [FILE], line 13, in <module>() m.fit(input_fn=train_input_fn, steps=200)[SEP]File <*>python2.7/site-packages/tensorflow/contrib/learn/python/learn/estimators/estimator.pyc, line 240, in fit(self, x, y, input_fn, steps, batch_size, monitors, max_steps) max_steps=max_steps)[SEP]File <*>python2.7/site-packages/tensorflow/contrib/learn/python/learn/estimators/estimator.pyc, line 550, in _train_model(self, input_fn, steps, feed_fn, init_op, init_feed_fn, init_fn, device_fn, monitors, log_every_steps, fail_on_nan_loss, max_steps) train_op, loss_op = self._get_train_ops(features, targets)[SEP]File <*>python2.7/site-packages/tensorflow/contrib/learn/python/learn/estimators/linear.pyc, line 336, in _get_train_ops(self, features, targets) return super(LinearRegressor, self)._get_train_ops(features, targets)[SEP]File <*>python2.7/site-packages/tensorflow/contrib/learn/python/learn/estimators/dnn_linear_combined.pyc, line 182, in _get_train_ops(self, features, targets) logits = self._logits(features, is_training=True)[SEP]File <*>python2.7/site-packages/tensorflow/contrib/learn/python/learn/estimators/dnn_linear_combined.pyc, line 271, in _logits(self, features, is_training) logits = self._linear_logits(features, is_training)[SEP]File <*>python2.7/site-packages/tensorflow/contrib/learn/python/learn/estimators/dnn_linear_combined.pyc, line 233, in _linear_logits(self, features, is_training) features, self._linear_feature_columns, is_training)[SEP]File <*>python2.7/site-packages/tensorflow/contrib/learn/python/learn/estimators/composable_model.pyc, line 177, in build_model(self, features, feature_columns, is_training) scope=scope)[SEP]File <*>python2.7/site-packages/tensorflow/contrib/layers/python/layers/feature_column_ops.pyc, line 178, in weighted_sum_from_feature_columns(columns_to_tensors, feature_columns, num_outputs, weight_collections, trainable, scope) transformed_tensor = transformer.transform(column)[SEP]File <*>python2.7/site-packages/tensorflow/contrib/layers/python/layers/feature_column_ops.pyc, line 384, in transform(self, feature_column) feature_column.insert_transformed_feature(self._columns_to_tensors)[SEP]File <*>python2.7/site-packages/tensorflow/contrib/layers/python/layers/feature_column.pyc, line 364, in insert_transformed_feature(self, columns_to_tensors) name=self.name + ""_lookup"")[SEP]File <*>python2.7/site-packages/tensorflow/python/ops/gen_string_ops.pyc, line 185, in string_to_hash_bucket_fast(input, num_buckets, name) num_buckets=num_buckets, name=name)[SEP]File <*>python2.7/site-packages/tensorflow/python/framework/op_def_library.pyc, line 463, in apply_op(self, op_type_name, name, **keywords) (prefix, dtypes.as_dtype(input_arg.type).name))[SEP]TypeError: Input 'input' of 'StringToHashBucketFast' Op has type int64 that does not match expected type of string.",0
"File [FILE], line 1, in <module>() from imagenet_utils import preprocess_input, decode_predictions[SEP]ImportError: No module named 'imagenet_utils'",0
"File [FILE], line 2, in <module>() loaded_model = load_model('my_model_vgg16.h5')[SEP]File <*>/site-packages/keras/models.py, line 246, in load_model(filepath, custom_objects, compile) topology.load_weights_from_hdf5_group(f['model_weights'], model.layers)[SEP]File <*>/site-packages/keras/engine/topology.py, line 3166, in load_weights_from_hdf5_group(f, layers) K.batch_set_value(weight_value_tuples)[SEP]File <*>/site-packages/keras/backend/tensorflow_backend.py, line 2365, in batch_set_value(tuples) assign_op = x.assign(assign_placeholder)[SEP]File <*>/site-packages/tensorflow/python/ops/variables.py, line 573, in assign(self, value, use_locking) return state_ops.assign(self._variable, value, use_locking=use_locking)[SEP]File <*>/site-packages/tensorflow/python/ops/state_ops.py, line 276, in assign(ref, value, validate_shape, use_locking, name) validate_shape=validate_shape)[SEP]File <*>/site-packages/tensorflow/python/ops/gen_state_ops.py, line 56, in assign(ref, value, validate_shape, use_locking, name) use_locking=use_locking, name=name)[SEP]File <*>/site-packages/tensorflow/python/framework/op_def_library.py, line 787, in _apply_op_helper(self, op_type_name, name, **keywords) op_def=op_def)[SEP]File <*>/site-packages/tensorflow/python/framework/ops.py, line 2958, in create_op(self, op_type, inputs, dtypes, input_types, name, attrs, op_def, compute_shapes, compute_device) set_shapes_for_outputs(ret)[SEP]File <*>/site-packages/tensorflow/python/framework/ops.py, line 2209, in set_shapes_for_outputs(op) shapes = shape_func(op)[SEP]File <*>/site-packages/tensorflow/python/framework/ops.py, line 2159, in call_with_requiring(op) return call_cpp_shape_fn(op, require_shape_fn=True)[SEP]File <*>/site-packages/tensorflow/python/framework/common_shapes.py, line 627, in call_cpp_shape_fn(op, require_shape_fn) require_shape_fn)[SEP]File <*>/site-packages/tensorflow/python/framework/common_shapes.py, line 691, in _call_cpp_shape_fn_impl(op, input_tensors_needed, input_tensors_as_shapes_needed, require_shape_fn) raise ValueError(err.message)[SEP]ValueError: Dimension 0 in both shapes must be equal, but are 4096 and 1000 for 'Assign_30' (op: 'Assign') with input shapes: [4096,3], [1000,3].",0
"File [FILE], line 1, in <module>() import tensorflow as tf[SEP]ModuleNotFoundError: No module named 'tensorflow'",0
"File <*>/train.py, line 167, in <module>() tf.app.run()[SEP]File <*>python3.6/dist-packages/tensorflow/python/platform/app.py, line 126, in run(main, argv) _sys.exit(main(argv))[SEP]File <*>/train.py, line 107, in main(_) overwrite=True)[SEP]File <*>python3.6/dist-packages/tensorflow/python/lib/io/file_io.py, line 392, in copy(oldpath, newpath, overwrite) compat.as_bytes(oldpath), compat.as_bytes(newpath), overwrite, status)[SEP]File <*>python3.6/dist-packages/tensorflow/python/framework/errors_impl.py, line 516, in __exit__(self, type_arg, value_arg, traceback_arg) c_api.TF_GetCode(self.status.status))[SEP]NotFoundError: ; No such file or directory",0
"File <*>/model_finegrained.py, line 1, in <module>() tf.Variable(2, name='a:b')[SEP]File <*>python3.6/site-packages/tensorflow/python/ops/variables.py, line 213, in __init__(self, initial_value, trainable, collections, validate_shape, caching_device, name, variable_def, dtype, expected_shape, import_scope, constraint) constraint=constraint)[SEP]File <*>python3.6/site-packages/tensorflow/python/ops/variables.py, line 289, in _init_from_args(self, initial_value, trainable, collections, validate_shape, caching_device, name, dtype, expected_shape, constraint) [initial_value]) as name:[SEP]File <*>python3.6/site-packages/tensorflow/python/framework/ops.py, line 4932, in __enter__(self) return self._name_scope.__enter__()[SEP]File <*>python3.6/contextlib.py, line 81, in __enter__(self) return next(self.gen)[SEP]File <*>python3.6/site-packages/tensorflow/python/framework/ops.py, line 3514, in name_scope(self, name) raise ValueError(""'%s' is not a valid scope name"" % name)[SEP]ValueError: 'a:b' is not a valid scope name",0
"File [FILE], line 3, in <module>() plt.imshow(grid)[SEP]File <*>python3.6/site-packages/matplotlib/pyplot.py, line 3205, in imshow(X, cmap, norm, aspect, interpolation, alpha, vmin, vmax, origin, extent, shape, filternorm, filterrad, imlim, resample, url, hold, data, **kwargs) **kwargs)[SEP]File <*>python3.6/site-packages/matplotlib/__init__.py, line 1855, in inner(ax, *args, **kwargs) return func(ax, *args, **kwargs)[SEP]File <*>python3.6/site-packages/matplotlib/axes/_axes.py, line 5487, in imshow(self, X, cmap, norm, aspect, interpolation, alpha, vmin, vmax, origin, extent, shape, filternorm, filterrad, imlim, resample, url, **kwargs) im.set_data(X)[SEP]File <*>python3.6/site-packages/matplotlib/image.py, line 653, in set_data(self, A) raise TypeError(""Invalid dimensions for image data"")[SEP]TypeError: Invalid dimensions for image data",0
"File [FILE], line 5, in <module> hessian = tf.hessians(f, xy)[SEP]File <*>python3.7/site-packages/tensorflow/python/ops/gradients_impl.py, line 1407, in hessians(ys, xs, name, colocate_gradients_with_ops, gate_gradients, aggregation_method) gradient = array_ops.reshape(gradient, [-1])[SEP]File <*>python3.7/site-packages/tensorflow/python/ops/gen_array_ops.py, line 7180, in reshape(tensor, shape, name) ""Reshape"", tensor=tensor, shape=shape, name=name)[SEP]File <*>python3.7/site-packages/tensorflow/python/framework/op_def_library.py, line 529, in _apply_op_helper(self, op_type_name, name, **keywords) (input_name, err))[SEP]ValueError: Tried to convert 'tensor' to a tensor and failed. Error: None values not supported.",0
"File [FILE], line 1, in <module>() tf.enable_eager_execution()[SEP]AttributeError: module 'tensorflow' has no attribute 'enable_eager_execution'",0
"File [FILE], line 1, in <module>() create_record()[SEP]File [FILE], line 17, in create_record() ""mfcc"":tf.train.Feature(float_list=tf.train.FloatList(value=mfcc.tolist()))[SEP]TypeError: [-389.381029172618, -393.08814551655723, -404.7248725876356, -407.1006984237564, -409.22695909850626 has type list, but expected one of: int, long, float",0
"File [FILE], line 51, in <module> model.fit([x_img_train, x_transform_train], y_train, batch_size=8)[SEP]File <*>python3.6/site-packages/keras/engine/training.py, line 1039, in fit(self, x, y, batch_size, epochs, verbose, callbacks, validation_split, validation_data, shuffle, class_weight, sample_weight, initial_epoch, steps_per_epoch, validation_steps, **kwargs) validation_steps=validation_steps)[SEP]File <*>python3.6/site-packages/keras/engine/training_arrays.py, line 199, in fit_loop(model, f, ins, out_labels, batch_size, epochs, verbose, callbacks, val_f, val_ins, shuffle, callback_metrics, initial_epoch, steps_per_epoch, validation_steps) outs = f(ins_batch)[SEP]File <*>python3.6/site-packages/keras/backend/tensorflow_backend.py, line 2715, in __call__(self, inputs) return self._call(inputs)[SEP]File <*>python3.6/site-packages/keras/backend/tensorflow_backend.py, line 2675, in _call(self, inputs) fetched = self._callable_fn(*array_vals)[SEP]File <*>python3.6/site-packages/tensorflow/python/client/session.py, line 1439, in __call__(self, *args, **kwargs) run_metadata_ptr)[SEP]File <*>python3.6/site-packages/tensorflow/python/framework/errors_impl.py, line 528, in __exit__(self, type_arg, value_arg, traceback_arg) c_api.TF_GetCode(self.status.status))[SEP]InvalidArgumentError: Incompatible shapes: [8,28,28,32] vs. [8,32] [[{{node training_5/Adam/gradients/affine_transform_18/mul_grad/BroadcastGradientArgs}} = BroadcastGradientArgs[T=DT_INT32, _class=[""loc:@training_5/Adam/gradients/batch_normalization_22/cond/Merge_grad/cond_grad""], _device=""/job:localhost/replica:0/task:0/device:CPU:0""](training_5/Adam/gradients/affine_transform_18/mul_grad/Shape, training_5/Adam/gradients/affine_transform_18/mul_grad/Shape_1)]]",0
"File [FILE], line 72, in <module>() validate=True, resume=False, flow=True, use_cuda=cuda)[SEP]File <*>/train_helper.py, line 109, in train(model, num_epochs, train_set, dev_set, lr, batch_size, start_epoch, log, checkpoint_path, validate, resume, flow, use_cuda) loss = criterion(outputs, labels)[SEP]File <*>python3.6/dist-packages/torch/nn/modules/module.py, line 489, in __call__(self, *input, **kwargs) result = self.forward(*input, **kwargs)[SEP]File <*>python3.6/dist-packages/torch/nn/modules/loss.py, line 904, in forward(self, input, target) ignore_index=self.ignore_index, reduction=self.reduction)[SEP]File <*>python3.6/dist-packages/torch/nn/functional.py, line 1970, in cross_entropy(input, target, weight, size_average, ignore_index, reduce, reduction) return nll_loss(log_softmax(input, 1), target, weight, None, ignore_index, None, reduction)[SEP]File <*>python3.6/dist-packages/torch/nn/functional.py, line 1790, in nll_loss(input, target, weight, size_average, ignore_index, reduce, reduction) ret = torch._C._nn.nll_loss(input, target, weight, _Reduction.get_enum(reduction), ignore_index)[SEP]RuntimeError: Expected object of scalar type Long but got scalar type Byte for argument #2 'target'",0
"File [FILE], line 17, in <module>() d1, d2 = sess.run((d_fx1, d_fx2))[SEP]File <*>/site-packages/tensorflow/python/client/session.py, line 929, in run(self, fetches, feed_dict, options, run_metadata) run_metadata_ptr)[SEP]File <*>/site-packages/tensorflow/python/client/session.py, line 1137, in _run(self, handle, fetches, feed_dict, options, run_metadata) self._graph, fetches, feed_dict_tensor, feed_handles=feed_handles)[SEP]File <*>/site-packages/tensorflow/python/client/session.py, line 471, in __init__(self, graph, fetches, feeds, feed_handles) self._fetch_mapper = _FetchMapper.for_fetch(fetches)[SEP]File <*>/site-packages/tensorflow/python/client/session.py, line 261, in for_fetch(fetch) return _ListFetchMapper(fetch)[SEP]File <*>/site-packages/tensorflow/python/client/session.py, line 370, in __init__(self, fetches) self._mappers = [_FetchMapper.for_fetch(fetch) for fetch in fetches][SEP]File <*>/site-packages/tensorflow/python/client/session.py, line 370, in <listcomp>(.0) self._mappers = [_FetchMapper.for_fetch(fetch) for fetch in fetches][SEP]File <*>/site-packages/tensorflow/python/client/session.py, line 258, in for_fetch(fetch) type(fetch)))[SEP]TypeError: Fetch argument None has invalid type <class 'NoneType'>",0
"File [FILE], line 4, in <module> steps=20)[SEP]File <*>python3.7/site-packages/tensorflow/python/framework/ops.py, line 1185, in internal_convert_to_tensor(value, dtype, name, as_ref, preferred_dtype, ctx, accept_symbolic_tensors, accept_composite_tensors) raise RuntimeError(""Attempting to capture an EagerTensor without ""[SEP]RuntimeError: Attempting to capture an EagerTensor without building a function.",0
"File [FILE], line 3, in <module> train(n_epochs,net,loaders,optimizer,criterion,'saved_model/dog_model.pt')[SEP]File [FILE], line 24, in train(n_epochs, model, loader, optimizer, criterion, save_path) loss = criterion(outputs,target)[SEP]RuntimeError: The size of tensor a (133) must match the size of tensor b (10) at non-singleton dimension 1.",0
"File [FILE], line 35, in <module>() output = model(data)[SEP]File <*>python3.6/dist-packages/torch/nn/modules/conv.py, line 338, in forward(self, input) self.padding, self.dilation, self.groups)[SEP]RuntimeError: Expected 4-dimensional input for 4-dimensional weight 32 3 3, but got 3-dimensional input of size [3, 224, 224] instead",0
"File <*>python3.7/site-packages/tensorflow/python/client/session.py, line 1356, in _do_call(self, fn, *args) return fn(*args)[SEP]File <*>python3.7/site-packages/tensorflow/python/client/session.py, line 1339, in _run_fn(feed_dict, fetch_list, target_list, options, run_metadata) self._extend_graph()[SEP]File <*>python3.7/site-packages/tensorflow/python/client/session.py, line 1374, in _extend_graph(self) tf_session.ExtendSession(self._session)[SEP]InvalidArgumentError: Cannot assign a device for operation MatMul: {{node MatMul}}was explicitly assigned to /device:GPU:0 but available devices are [ /job:localhost/replica:0/task:0/device:CPU:0, /job:localhost/replica:0/task:0/device:XLA_CPU:0, /job:localhost/replica:0/task:0/device:XLA_GPU:0 ]. Make sure the device specification refers to a valid device.",0
"File [FILE], line 11, in <module>() print(x[0])[SEP]KeyError: 0",0
"File [FILE], line 6, in <module> from tensorflow.keras.models import Sequential[SEP]File <*>/site-packages/tensorflow/keras/__init__.py, line 14, in <module> from . import activations[SEP]File <*>/site-packages/tensorflow/keras/activations/__init__.py, line 23, in <module> from tensorflow.python.keras.activations import swish[SEP]ImportError: cannot import name 'swish' from 'tensorflow.python.keras.activations' (C:\Users\FlamePrinz\Anaconda3\lib\site-packages\tensorflow\python\keras\activations.py)",0
"File [FILE], line 14, in <module> Y = torch.masked_select(X, (mask == 1))[SEP]RuntimeError: The size of tensor a (2) must match the size of tensor b (3) at non-singleton dimension 2",0
"File [FILE], line 4, in <module> history = comp_lstm.fit(train,[SEP]File <*>python3.8/site-packages/tensorflow/python/keras/engine/training.py, line 66, in _method_wrapper(self, *args, **kwargs) return method(self, *args, **kwargs)[SEP]File <*>python3.8/site-packages/tensorflow/python/keras/engine/training.py, line 848, in fit(self, x, y, batch_size, epochs, verbose, callbacks, validation_split, validation_data, shuffle, class_weight, sample_weight, initial_epoch, steps_per_epoch, validation_steps, validation_batch_size, validation_freq, max_queue_size, workers, use_multiprocessing) tmp_logs = train_function(iterator)[SEP]File <*>python3.8/site-packages/tensorflow/python/eager/def_function.py, line 580, in __call__(self, *args, **kwds) result = self._call(*args, **kwds)[SEP]File <*>python3.8/site-packages/tensorflow/python/eager/def_function.py, line 611, in _call(self, *args, **kwds) return self._stateless_fn(*args, **kwds) # pylint: disable=not-callable[SEP]TypeError: 'NoneType' object is not callable",0
"File [FILE], line 5, in <module>() out = vae.generate(model, mean, var)[SEP]File <*>/vae.py, line 92, in generate(model, mean, var) out = model.decode(z)[SEP]File <*>/vae.py, line 58, in decode(self, z) out = self.z_develop(z)[SEP]File <*>python3.6/dist-packages/torch/nn/modules/module.py, line 722, in _call_impl(self, *input, **kwargs) result = self.forward(*input, **kwargs)[SEP]File <*>python3.6/dist-packages/torch/nn/modules/linear.py, line 91, in forward(self, input) return F.linear(input, self.weight, self.bias)[SEP]File <*>python3.6/dist-packages/torch/nn/functional.py, line 1676, in linear(input, weight, bias) output = input.matmul(weight.t())[SEP]RuntimeError: mat1 dim 1 must match mat2 dim 0",0
"File [FILE], line 29, in <module>() model.add(Bidirectional(LSTM(150, return_sequences=True)))[SEP]File <*>python3.6/dist-packages/tensorflow/python/keras/engine/input_spec.py, line 180, in assert_input_compatibility(input_spec, inputs, layer_name) str(x.shape.as_list()))[SEP]ValueError: Input 0 of layer bidirectional is incompatible with the layer: expected ndim=3, found ndim=4. Full shape received: [None, 1, 1, 80]",0
"File [FILE], line 1, in <module>() model.fit([images, negatives], positives, epochs=10, batch_size=8, verbose=2)[SEP]File <*>python3.6/dist-packages/tensorflow/python/keras/engine/training.py, line 108, in _method_wrapper(self, *args, **kwargs) return method(self, *args, **kwargs)[SEP]File <*>python3.6/dist-packages/tensorflow/python/keras/engine/training.py, line 1098, in fit(self, x, y, batch_size, epochs, verbose, callbacks, validation_split, validation_data, shuffle, class_weight, sample_weight, initial_epoch, steps_per_epoch, validation_steps, validation_batch_size, validation_freq, max_queue_size, workers, use_multiprocessing) tmp_logs = train_function(iterator)[SEP]File <*>python3.6/dist-packages/tensorflow/python/eager/def_function.py, line 780, in __call__(self, *args, **kwds) result = self._call(*args, **kwds)[SEP]File <*>python3.6/dist-packages/tensorflow/python/eager/def_function.py, line 807, in _call(self, *args, **kwds) return self._stateless_fn(*args, **kwds) # pylint: disable=not-callable[SEP]TypeError: 'NoneType' object is not callable",0
"File [FILE], line 6, in <module>() validation_data=(x_test, y_test),[SEP]File <*>python3.6/dist-packages/tensorflow/python/framework/func_graph.py, line 973, in wrapper(*args, **kwargs) raise e.ag_error_metadata.to_exception(e)[SEP]ValueError: in user code: /usr/local/lib/python3.6/dist-packages/tensorflow/python/keras/engine/training.py:806 train_function * return step_function(self, iterator) /usr/local/lib/python3.6/dist-packages/tensorflow/python/keras/engine/training.py:796 step_function ** outputs = model.distribute_strategy.run(run_step, args=(data,)) /usr/local/lib/python3.6/dist-packages/tensorflow/python/distribute/distribute_lib.py:1211 run return self._extended.call_for_each_replica(fn, args=args, kwargs=kwargs) /usr/local/lib/python3.6/dist-packages/tensorflow/python/distribute/distribute_lib.py:2585 call_for_each_replica return self._call_for_each_replica(fn, args, kwargs) /usr/local/lib/python3.6/dist-packages/tensorflow/python/distribute/distribute_lib.py:2945 _call_for_each_replica return fn(*args, **kwargs) /usr/local/lib/python3.6/dist-packages/tensorflow/python/keras/engine/training.py:789 run_step ** outputs = model.train_step(data) /usr/local/lib/python3.6/dist-packages/tensorflow/python/keras/engine/training.py:747 train_step y_pred = self(x, training=True) /usr/local/lib/python3.6/dist-packages/tensorflow/python/keras/engine/base_layer.py:985 __call__ outputs = call_fn(inputs, *args, **kwargs) /usr/local/lib/python3.6/dist-packages/tensorflow/python/keras/engine/functional.py:386 call inputs, training=training, mask=mask) /usr/local/lib/python3.6/dist-packages/tensorflow/python/keras/engine/functional.py:508 _run_internal_graph outputs = node.layer(*args, **kwargs) /usr/local/lib/python3.6/dist-packages/tensorflow/python/keras/engine/base_layer.py:985 __call__ outputs = call_fn(inputs, *args, **kwargs) /usr/local/lib/python3.6/dist-packages/tensorflow/python/keras/layers/merge.py:183 call return self._merge_function(inputs) /usr/local/lib/python3.6/dist-packages/tensorflow/python/keras/layers/merge.py:522 _merge_function return K.concatenate(inputs, axis=self.axis) /usr/local/lib/python3.6/dist-packages/tensorflow/python/util/dispatch.py:201 wrapper return target(*args, **kwargs) /usr/local/lib/python3.6/dist-packages/tensorflow/python/keras/backend.py:2881 concatenate return array_ops.concat([to_dense(x) for x in tensors], axis) /usr/local/lib/python3.6/dist-packages/tensorflow/python/util/dispatch.py:201 wrapper return target(*args, **kwargs) /usr/local/lib/python3.6/dist-packages/tensorflow/python/ops/array_ops.py:1654 concat return gen_array_ops.concat_v2(values=values, axis=axis, name=name) /usr/local/lib/python3.6/dist-packages/tensorflow/python/ops/gen_array_ops.py:1222 concat_v2 ""ConcatV2"", values=values, axis=axis, name=name) /usr/local/lib/python3.6/dist-packages/tensorflow/python/framework/op_def_library.py:744 _apply_op_helper attrs=attr_protos, op_def=op_def) /usr/local/lib/python3.6/dist-packages/tensorflow/python/framework/func_graph.py:593 _create_op_internal compute_device) /usr/local/lib/python3.6/dist-packages/tensorflow/python/framework/ops.py:3485 _create_op_internal op_def=op_def) /usr/local/lib/python3.6/dist-packages/tensorflow/python/framework/ops.py:1975 __init__ control_input_ops, op_def) /usr/local/lib/python3.6/dist-packages/tensorflow/python/framework/ops.py:1815 _create_c_op raise ValueError(str(e)) ValueError: Dimension 2 in both shapes must be equal, but are 512 and 511. Shapes are [?,384,512] and [?,384,511]. for '{{node functional_3/decoder_stage3_concat/concat}} = ConcatV2[N=2, T=DT_FLOAT, Tidx=DT_INT32](functional_3/decoder_stage3_upsampling/resize/ResizeNearestNeighbor, functional_3/relu0/Relu, functional_3/decoder_stage3_concat/concat/axis)' with input shapes: [?,384,512,64], [?,384,511,64], [] and with computed input tensors: input[2] = <3>.",0
"File <*>python3.6/dist-packages/optkeras/optkeras.py, line 230, in synch_with_optuna(self) self.best_trial = self.study.best_trial[SEP]ValueError: No trials are completed yet.",0
"File [FILE], line 49, in <module>() for images, labels in myTrain_dataloader:[SEP]File <*>python3.6/dist-packages/torch/utils/data/dataloader.py, line 819, in __next__(self) return self._process_data(data)[SEP]File <*>python3.6/dist-packages/torch/utils/data/dataloader.py, line 846, in _process_data(self, data) data.reraise()[SEP]File <*>python3.6/dist-packages/torch/_utils.py, line 385, in reraise(self) raise self.exc_type(msg)[SEP]RuntimeError: Caught RuntimeError in DataLoader worker process 0.",0
