Templates,label
"File <*>python3.5/site-packages/theano/gof/opt.py, line 1772, in process_node replacements = lopt.transform(node) File <*>python3.5/site-packages/theano/sandbox/gpuarray/opt.py, line 140, in local_opt new_op = maker(node, context_name) File <*>python3.5/site-packages/theano/sandbox/gpuarray/opt.py, line 732, in local_gpua_hgemm if nvcc_compiler.nvcc_version < '7.5': TypeError: unorderable types: NoneType() < str()",1
"File <stdin>, line 1, in <module> [CODE] ImportError: No module named data_utils",1
"File <stdin>, line 1, in <module> [CODE] File <*>python2.7/site-packages/prettytensor-0.6.0-py2.7.egg/prettytensor/__init__.py, line 25, in <module> from prettytensor import funcs File <*>python2.7/site-packages/prettytensor-0.6.0-py2.7.egg/prettytensor/funcs.py, line 25, in <module> from prettytensor.pretty_tensor_image_methods import * File <*>python2.7/site-packages/prettytensor-0.6.0-py2.7.egg/prettytensor/pretty_tensor_image_methods.py, line 20, in <module> from prettytensor import layers ImportError: cannot import name layers",1
"File <pyshell#0>, line 1, in <module> from keras.layers import Dense ImportError: cannot import name 'Dense'",1
"File [FILE], line 4, in `<module>`() tf.global_variables_initializer().run() AttributeError: 'module' object has no attribute 'global_variables_initializer'",1
"File [FILE], line 1, in <module>() import keras File <*>python3.5/site-packages/keras/__init__.py, line 2, in <module>() from . import backend File <*>python3.5/site-packages/keras/backend/__init__.py, line 69, in <module>() from .tensorflow_backend import * File <*>python3.5/site-packages/keras/backend/tensorflow_backend.py, line 7, in <module>() import tensorflow.contrib.ctc as ctc ImportError: No module named 'tensorflow.contrib.ctc'",1
"File [FILE], line 1, in <module>() writer = tf.train.FileWriter('./my_graph', sess.graph) AttributeError: 'module' object has no attribute 'FileWriter'",1
"File <*>python3.6/site-packages/theano/gof/opt.py, line 1772, in process_node replacements = lopt.transform(node) File <*>python3.6/site-packages/theano/tensor/opt.py, line 5825, in constant_folding no_recycling=[]) File <*>python3.6/site-packages/theano/gof/op.py, line 970, in make_thunk no_recycling) File <*>python3.6/site-packages/theano/gof/op.py, line 879, in make_c_thunk output_storage=node_output_storage) File <*>python3.6/site-packages/theano/gof/cc.py, line 1200, in make_thunk keep_lock=keep_lock) File <*>python3.6/site-packages/theano/gof/cc.py, line 1143, in __compile__ keep_lock=keep_lock) File <*>python3.6/site-packages/theano/gof/cc.py, line 1595, in cthunk_factory key=key, lnk=self, keep_lock=keep_lock) File <*>python3.6/site-packages/theano/gof/cmodule.py, line 1142, in module_from_key module = lnk.compile_cmodule(location) File <*>python3.6/site-packages/theano/gof/cc.py, line 1506, in compile_cmodule preargs=preargs) File <*>python3.6/site-packages/theano/gof/cmodule.py, line 2213, in compile_str return dlimport(lib_filename) File <*>python3.6/site-packages/theano/gof/cmodule.py, line 299, in dlimport rval = __import__(module_name, {}, {}, [module_name]) ImportError: /home/puck/.theano/compiledir_Linux-4.4--MANJARO-x86_64-with-glibc2.2.5--3.6.0-64/tmpre6vph8g/mdb219947724f79219f7dbd36f0f52c77.so: undefined symbol: _ZdlPvm",1
"File <*>/running_template.py, line 65, in <module> cytoplasm_predictions = run_models_on_directory(data_location,cyto_channel_names, cyto_location, model_fn = cyto_fn,list_of_weights = list_of_cyto_weights, image_size_x = image_size_x, image_size_y = image_size_y,win_x = win_cyto, win_y = win_cyto, std = False, split = False) File <*>/cnn_functions.py, line 1491, in run_models_on_directory model = model_fn(batch_input_shape = batch_input_shape, n_features = n_features, weights_path = list_of_weights[0]) File <*>/model_zoo.py, line 528, in sparse_bn_feature_net_61x61 model.add(sparse_Convolution2D(64, 3, 3, d = d, init = init, batch_input_shape = batch_input_shape, border_mode='valid', W_regularizer = l2(reg))) File <*>python2.7/site-packages/keras/models.py, line 436, in add layer(x) File <*>python2.7/site-packages/keras/engine/topology.py, line 569, in __call__ self.build(input_shapes[0]) File <*>/cnn_functions.py, line 1012, in build self.W = self.init(self.W_shape, name='{}_W'.format(self.name)) TypeError: __call__() got an unexpected keyword argument 'name'",1
"File <stdin>, line 1, in <module> [CODE] File <*>python3.6/site-packages/keras/models.py, line 243, in load_model model = model_from_config(model_config, custom_objects=custom_objects) File <*>python3.6/site-packages/keras/models.py, line 317, in model_from_config return layer_module.deserialize(config, custom_objects=custom_objects) File <*>python3.6/site-packages/keras/layers/__init__.py, line 55, in deserialize printable_module_name='layer') File <*>python3.6/site-packages/keras/utils/generic_utils.py, line 143, in deserialize_keras_object list(custom_objects.items()))) File <*>python3.6/site-packages/keras/models.py, line 1352, in from_config layer = layer_module.deserialize(conf, custom_objects=custom_objects) File <*>python3.6/site-packages/keras/utils/generic_utils.py, line 145, in deserialize_keras_object return cls.from_config(config['config']) File <*>python3.6/site-packages/keras/engine/topology.py, line 1269, in from_config return cls(**config) File <*>python3.6/site-packages/keras/layers/core.py, line 483, in __init__ super(Flatten, self).__init__(**kwargs) File <*>python3.6/site-packages/keras/engine/topology.py, line 292, in __init__ raise TypeError('Keyword argument not understood:', kwarg) TypeError: ('Keyword argument not understood:', 'data_format')",1
"File [FILE], line 1, in <module>() from keras.layers import Merge ImportError: cannot import name 'Merge'",1
"File model_main.py, line 26, in <module> from object_detection import model_lib File <*>/site-packages/object_detection-0.1-py3.7.egg/object_detection/model_lib.py, line 28, in <module> from object_detection import eval_util File <*>/site-packages/object_detection-0.1-py3.7.egg/object_detection/eval_util.py, line 35, in <module> slim = tf.contrib.slim File <*>/site-packages/tensorflow/python/util/lazy_loader.py, line 62, in __getattr__ module = self._load() File <*>/site-packages/tensorflow/python/util/lazy_loader.py, line 45, in _load module = importlib.import_module(self.__name__) File <*>/__init__.py, line 127, in import_module return _bootstrap._gcd_import(name[level:], package, level) File <*>/site-packages/tensorflow/contrib/__init__.py, line 33, in <module> from tensorflow.contrib import compiler File <*>/site-packages/tensorflow/contrib/compiler/__init__.py, line 22, in <module> from tensorflow.contrib.compiler import xla File <*>/site-packages/tensorflow/contrib/compiler/xla.py, line 22, in <module> from tensorflow.python.estimator import model_fn as model_fn_lib File <*>/site-packages/tensorflow/python/estimator/__init__.py, line 26, in <module> from tensorflow_estimator.python import estimator File <*>/site-packages/tensorflow_estimator/python/estimator/__init__.py, line 25, in <module> import tensorflow_estimator.python.estimator.estimator_lib File <*>/site-packages/tensorflow_estimator/python/estimator/estimator_lib.py, line 69, in <module> from tensorflow_estimator.python.estimator.tpu.tpu_estimator import TPUEstimator File <*>/site-packages/tensorflow_estimator/python/estimator/tpu/tpu_estimator.py, line 83, in <module> from tensorflow_estimator.python.estimator import estimator as estimator_lib File <*>/site-packages/tensorflow_estimator/__init__.py, line 8, in <module> from tensorflow_estimator._api.v1 import estimator File <*>/site-packages/tensorflow_estimator/_api/v1/estimator/__init__.py, line 11, in <module> from tensorflow_estimator._api.v1.estimator import tpu File <*>/site-packages/tensorflow_estimator/_api/v1/estimator/tpu/__init__.py, line 8, in <module> from tensorflow_estimator._api.v1.estimator.tpu import experimental File <*>/site-packages/tensorflow_estimator/_api/v1/estimator/tpu/experimental/__init__.py, line 8, in <module> from tensorflow_estimator.python.estimator.tpu._tpu_estimator_embedding import EmbeddingConfigSpec File <*>/site-packages/tensorflow_estimator/python/estimator/tpu/_tpu_estimator_embedding.py, line 32, in <module> from tensorflow.python.tpu import feature_column_v2 as tpu_fc_v2 ImportError: cannot import name 'feature_column_v2' from 'tensorflow.python.tpu' (C:\Users\Rodolfo\AppData\Local\Programs\Python\Python37\lib\site-packages\tensorflow\python\tpu\__init__.py)",1
"File <*>/image.py, line 7, in <module> detector = ObjectDetection() File <*>python3.5/site-packages/imageai/Detection/__init__.py, line 88, in __init__ self.sess = K.get_session() File <*>python3.5/site-packages/keras/backend/tensorflow_backend.py, line 174, in get_session default_session = tf.get_default_session() AttributeError: module 'tensorflow' has no attribute 'get_default_session'",1
"File [FILE], line 1, in <module> from tensorflow.python.util.tf_export import keras_export ImportError: cannot import name 'keras_export' from 'tensorflow.python.util.tf_export' (C:\Users\DILAW\Anaconda3\lib\site-packages\tensorflow\python\util\tf_export.py)",1
"File [FILE], line 9, in <module> from tensorflow import set_random_seed ImportError: cannot import name 'set_random_seed' from 'tensorflow' (C:\Users\polon\Anaconda3\lib\site-packages\tensorflow\__init__.py)",1
"File [FILE], line 6, in <module> output = tensorflow.keras.layers.Dropout(dropout_rate, name=""dropout_out"")(vgg_output) File <*>/site-packages/tensorflow/python/keras/engine/base_layer.py, line 663, in __call__(self, inputs, *args, **kwargs) inputs, outputs, args, kwargs) File <*>/site-packages/tensorflow/python/keras/engine/base_layer.py, line 1708, in _set_connectivity_metadata_(self, inputs, outputs, args, kwargs) input_tensors=inputs, output_tensors=outputs, arguments=kwargs) File <*>/site-packages/tensorflow/python/keras/engine/base_layer.py, line 1795, in _add_inbound_node(self, input_tensors, output_tensors, arguments) input_tensors) File <*>/site-packages/tensorflow/python/util/nest.py, line 515, in map_structure(func, *structure, **kwargs) structure[0], [func(*x) for x in entries], File <*>/site-packages/tensorflow/python/util/nest.py, line 515, in <listcomp>(.0) structure[0], [func(*x) for x in entries], File <*>/site-packages/tensorflow/python/keras/engine/base_layer.py, line 1794, in <lambda>(t) inbound_layers = nest.map_structure(lambda t: t._keras_history.layer, AttributeError: 'tuple' object has no attribute 'layer'",1
"File [FILE], line 3, in <module> model.add(tensorflow.keras.layers.GlobalMaxPooling2D(name=""gap"")) File <*>/site-packages/keras/engine/sequential.py, line 133, in add(self, layer) 'Found: ' + str(layer)) TypeError: The added layer must be an instance of class Layer. Found: <tensorflow.python.keras.layers.core.Flatten object at 0x00000000B74364A8>",1
"File [FILE], line 1, in <module> var_init_1 = tf.get_variable(""var_init_1"", [1, 2], dtype=tf.int32, initializer=tf.zeros_initializer) AttributeError: module 'tensorflow' has no attribute 'get_variable'",1
"File <*>/tv-training-code.py, line 166, in <module> main() File <*>/tv-training-code.py, line 161, in main evaluate(model, data_loader_test, device=device) File <*>python3.6/dist-packages/torch/autograd/grad_mode.py, line 49, in decorate_no_grad return func(*args, **kwargs) File <*>/engine.py, line 80, in evaluate coco_evaluator = CocoEvaluator(coco, iou_types) File <*>/coco_eval.py, line 28, in __init__ self.coco_eval[iou_type] = COCOeval(coco_gt, iouType=iou_type) File <*>/cocoeval.py, line 75, in __init__ self.params = Params(iouType=iouType) # parameters File <*>/cocoeval.py, line 527, in __init__ self.setDetParams() File <*>/cocoeval.py, line 506, in setDetParams self.iouThrs = np.linspace(.5, 0.95, np.round((0.95 - .5) / .05) + 1, endpoint=True) File <__array_function__ internals>, line 6, in linspace [CODE] File <*>python3.6/dist-packages/numpy/core/function_base.py, line 121, in linspace .format(type(num))) TypeError: object of type <class 'numpy.float64'> cannot be safely interpreted as an integer.",1
"File [FILE], line 3, in <module> images_flat = tf.contrib.layers.flatten(x) AttributeError: module 'tensorflow_core.compat.v1' has no attribute 'contrib'",1
"File [FILE], line 8, in <module>() data= (src.transform(tfms,size=sz) #Data augmentation File <*>python3.6/dist-packages/fastai/data_block.py, line 505, in transform(self, tfms, **kwargs) self.train.transform(tfms[0], **kwargs) File <*>python3.6/dist-packages/fastai/data_block.py, line 724, in transform(self, tfms, tfm_y, **kwargs) _check_kwargs(self.x, tfms, **kwargs) File <*>python3.6/dist-packages/fastai/data_block.py, line 596, in _check_kwargs(ds, tfms, **kwargs) raise Exception(f""It's not possible to apply those transforms to your dataset:\n {e}"") Exception: It's not possible to apply those transforms to your dataset: Expected object of scalar type Float but got scalar type Double for argument #3 'mat2' in call to _th_addmm_out",1
"File [FILE], line 2, in <module> from object_detection.utils import label_map_util File <*>/site-packages/object_detection/utils/label_map_util.py, line 27, in <module> from object_detection.protos import string_int_label_map_pb2 File <*>/site-packages/object_detection/protos/string_int_label_map_pb2.py, line 21, in <module> create_key=_descriptor._internal_create_key, AttributeError: module 'google.protobuf.descriptor' has no attribute '_internal_create_key'",1
"File test.py, line 2, in <module> model = load_model(filepath = 'saved_model/model2.h5',custom_objects=None,compile=True, ) File <*>python3.8/site-packages/tensorflow/python/keras/saving/save.py, line 184, in load_model return hdf5_format.load_model_from_hdf5(filepath, custom_objects, compile) File <*>python3.8/site-packages/tensorflow/python/keras/saving/hdf5_format.py, line 177, in load_model_from_hdf5 model = model_config_lib.model_from_config(model_config, File <*>python3.8/site-packages/tensorflow/python/keras/saving/model_config.py, line 55, in model_from_config return deserialize(config, custom_objects=custom_objects) File <*>python3.8/site-packages/tensorflow/python/keras/layers/serialization.py, line 105, in deserialize return deserialize_keras_object( File <*>python3.8/site-packages/tensorflow/python/keras/utils/generic_utils.py, line 369, in deserialize_keras_object return cls.from_config( File <*>python3.8/site-packages/tensorflow/python/keras/engine/sequential.py, line 397, in from_config layer = layer_module.deserialize(layer_config, File <*>python3.8/site-packages/tensorflow/python/keras/utils/generic_utils.py, line 375, in deserialize_keras_object return cls.from_config(cls_config) File <*>python3.8/site-packages/tensorflow/python/keras/engine/base_layer.py, line 655, in from_config return cls(**config) File <*>python3.8/site-packages/tensorflow/python/keras/layers/convolutional.py, line 582, in __init__ super(Conv2D, self).__init__( File <*>python3.8/site-packages/tensorflow/python/keras/layers/convolutional.py, line 121, in __init__ super(Conv, self).__init__( File <*>python3.8/site-packages/tensorflow/python/training/tracking/base.py, line 456, in _method_wrapper result = method(self, *args, **kwargs) File <*>python3.8/site-packages/tensorflow/python/keras/engine/base_layer.py, line 294, in __init__ generic_utils.validate_kwargs(kwargs, allowed_kwargs) File <*>python3.8/site-packages/tensorflow/python/keras/utils/generic_utils.py, line 792, in validate_kwargs raise TypeError(error_message, kwarg) TypeError: ('Keyword argument not understood:', 'groups')",1
"File [FILE], line 1, in <module>() tokenizer = tfds.features.text.VocabTokenizer() AttributeError: module 'tensorflow_datasets.core.features' has no attribute 'text'",1
"File main.py, line 60, in <module> main() File main.py, line 50, in main train_iters, dev_iters, test_iters, vocab = load_dataset(config) File <*>/data.py, line 23, in load_dataset TEXT = data.Field(batch_first=True, eos_token='<eos>') AttributeError: module 'torchtext.data' has no attribute 'Field'",1
"File [FILE], line 1, in <module>() from keras.utils import to_categorical ImportError: cannot import name 'to_categorical' from 'keras.utils' (/usr/local/lib/python3.7/dist-packages/keras/utils/__init__.py)",1
"File [FILE], line 41, in <module>() from theano.tensor import shared_randomstreams File <*>python3.7/dist-packages/theano/gof/cmodule.py, line 37, in <module>() from theano.configdefaults import gcc_version_str, local_bitwidth ImportError: cannot import name 'local_bitwidth' from 'theano.configdefaults' (/usr/local/lib/python3.7/dist-packages/theano/configdefaults.py)",1
"File <*>/train_model.py, line 10, in <module> from cancernet.cancernet import CancerNet File <*>/cancernet.py, line 2, in <module> from keras.layers.normalization import BatchNormalization ImportError: cannot import name 'BatchNormalization' from 'keras.layers.normalization' (C:\Users\Catalin\AppData\Local\Programs\Python\Python39\lib\site-packages\keras\layers\normalization\__init__.py)",1
"File <*>/site-packages/IPython/core/interactiveshell.py, line 3032, in run_code =============================== C:\Users\aleja_000\AppData\Local\Theano\compiledir_Windows-8-6.2.9200-Intel64_Family_6_Model_60_Stepping_3_GenuineIntel-2.7.9-64\lazylinker_ext\mod.cpp:1:0: sorry, unimplemented: 64-bit mode not compiled in #include <Python.h> ^ exec(code_obj, self.user_global_ns, self.user_ns) File <ipython-input-2-1e86b04c8a9c>, line 6, in <module> from lasagne.layers import DenseLayer File <*>/pydev_import_hook.py, line 21, in do_import module = self._system_import(name, *args, **kwargs) File <*>/__init__.py, line 5, in <module> from . import nonlinearities File <*>/non, line 6, in <module> from theano.tensor.nnet import sigmoid File <*>/site-packages/theano/__init__.py, line 55, in <module> from theano.compile import ( File <*>/site-packages/theano/compile/__init__.py, line 9, in <module> from theano.compile.function_module import * File <*>/site-packages/theano/compile/function_module.py, line 17, in <module> import theano.compile.mode File <*>/site-packages/theano/compile/mode.py, line 11, in <module> import theano.gof.vm File <*>/site-packages/theano/gof/vm.py, line 654, in <module> import lazylinker_c File <*>/site-packages/theano/gof/lazylinker_c.py, line 125, in <module> preargs=args) File <*>/site-packages/theano/gof/cmodule.py, line 2042, in compile_str (status, compile_stderr.replace('\n', '. '))) Exception: Compilation failed (return status=1): C:\Users\aleja_000\AppData\Local\Theano\compiledir_Windows-8-6.2.9200-Intel64_Family_6_Model_60_Stepping_3_GenuineIntel-2.7.9-64\lazylinker_ext\mod.cpp:1:0: sorry, unimplemented: 64-bit mode not compiled in . #include <Python.h> . ^",0
"File <stdin>, line 1, in <module> [CODE] ImportError: No module named lmdb",0
"File word2vec_basic.py, line 171, in <module> _, loss_val = session.run([optimizer, loss], feed_dict=feed_dict) File <*>python2.7/site-packages/tensorflow/python/client/session.py, line 345, in run results = self._do_run(target_list, unique_fetch_targets, feed_dict_string) File <*>python2.7/site-packages/tensorflow/python/client/session.py, line 419, in _do_run e.code) tensorflow.python.framework.errors.InvalidArgumentError: Cannot assign a device to node 'GradientDescent/update_Variable_2/ScatterSub': Could not satisfy explicit device specification '' because the node was colocated with a group of nodes that required incompatible device '/job:localhost/replica:0/task:0/GPU:0' [[Node: GradientDescent/update_Variable_2/ScatterSub = ScatterSub[T=DT_FLOAT, Tindices=DT_INT64, use_locking=false](Variable_2, gradients/concat_1, GradientDescent/update_Variable_2/mul)]]",0
"File run_deep_trainer.py, line 404, in <module> main() File run_deep_trainer.py, line 400, in main layer_trainers[-1].main_loop() File <*>/train.py, line 141, in main_loop self.setup() File <*>/train.py, line 121, in setup self.algorithm.setup(model=self.model, dataset=self.dataset) File <*>/sgd.py, line 243, in setup inf_params = [param for param in model.get_params() File <*>/model.py, line 503, in get_params return list(self._params) AttributeError: 'Softmax' object has no attribute '_params'",0
"File <*>/lstmNetwork.py, line 54, in <module> model.fit(X_train, Y_train, batch_size=batch_size, nb_epoch=3, validation_data=(X_test, Y_test), show_accuracy=True) File <*>python2.7/dist-packages/keras/models.py, line 581, in fit shuffle=shuffle, metrics=metrics) File <*>python2.7/dist-packages/keras/models.py, line 239, in _fit outs = f(ins_batch) File <*>python2.7/dist-packages/keras/backend/theano_backend.py, line 365, in __call__ return self.function(*inputs) File <*>/function_module.py, line 786, in __call__ allow_downcast=s.allow_downcast) File <*>/type.py, line 177, in filter data.shape)) TypeError: ('Bad input argument to theano function with name ""/usr/local/lib/python2.7/dist-packages/keras/backend/theano_backend.py:362"" at index 1(0-based)', 'Wrong number of dimensions: expected 3, got 2 with shape (5, 10).')",0
"File <*>/teste2.py, line 1479, in Pred model.fit(X=predictor_train, y=target_train, nb_epoch=2, batch_size=90,show_accuracy=True) File <*>/site-packages/keras/models.py, line 581, in fit shuffle=shuffle, metrics=metrics) File <*>/site-packages/keras/models.py, line 239, in _fit outs = f(ins_batch) File <*>/site-packages/keras/backend/theano_backend.py, line 365, in __call__ return self.function(*inputs) File <*>/site-packages/theano/compile/function_module.py, line 595, in __call__ outputs = self.fn() File <*>/site-packages/theano/gof/vm.py, line 233, in __call__ link.raise_with_op(node, thunk) File <*>/site-packages/theano/gof/vm.py, line 229, in __call__ thunk() File <*>/site-packages/theano/gof/op.py, line 768, in rval r = p(n, [x[0] for x in i], o) File <*>/site-packages/theano/tensor/elemwise.py, line 808, in perform raise ValueError(base_exc_str) ValueError: Dimension mismatch; shapes are (98, 10), (98, 1)",0
"File <stdin>, line 1, in <module> [CODE] ImportError: No module named tensorflow",0
"File <ipython-input-29-4e06de0b7af3>, line 1, in <module> sess.run(edit_distances, feed_dict=feed_dict) File <*>python3.4/dist-packages/tensorflow/python/client/session.py, line 372, in run run_metadata_ptr) File <*>python3.4/dist-packages/tensorflow/python/client/session.py, line 597, in _run for subfeed, subfeed_val in _feed_fn(feed, feed_val): File <*>python3.4/dist-packages/tensorflow/python/client/session.py, line 558, in _feed_fn return feed_fn(feed, feed_val) File <*>python3.4/dist-packages/tensorflow/python/client/session.py, line 268, in <lambda> [feed.indices, feed.values, feed.shape], feed_val)), TypeError: zip argument #2 must support iteration",0
"File <stdin>, line 1, in <module> [CODE] File <*>python3.4/site-packages/tensorflow/__init__.py, line 23, in <module> from tensorflow.python import * File <*>python3.4/site-packages/tensorflow/python/__init__.py, line 48, in <module> from tensorflow.python import pywrap_tensorflow File <*>python3.4/site-packages/tensorflow/python/pywrap_tensorflow.py, line 28, in <module> _pywrap_tensorflow = swig_import_helper() File <*>python3.4/site-packages/tensorflow/python/pywrap_tensorflow.py, line 24, in swig_import_helper _mod = imp.load_module('_pywrap_tensorflow', fp, pathname, description) File <*>python3.4/imp.py, line 243, in load_module return load_dynamic(name, filename, file) ImportError: dlopen(/Library/Frameworks/Python.framework/Versions/3.4/lib/python3.4/site-packages/tensorflow/python/_pywrap_tensorflow.so, 10): Library not loaded: @rpath/libcudart.7.5.dylib",0
"File custom_op.py, line 19, in <module> grad = tf.gradients(my_op(a), [a])[0] File <*>python3.5/site-packages/tensorflow/python/framework/function.py, line 528, in __call__ return call_function(self._definition, *args, **kwargs) File <*>python3.5/site-packages/tensorflow/python/framework/function.py, line 267, in call_function compute_shapes=False) File <*>python3.5/site-packages/tensorflow/python/framework/ops.py, line 2285, in create_op raise TypeError(""Input #%d is not a tensor: %s"" % (idx, a)) TypeError: Input #0 is not a tensor: <tensorflow.python.ops.variables.Variable object at 0x1080d2710>",0
"File <*>/main, line 132, in <module> apply_weights_OP = tf.matmul(activation_OP, Weights, name=""apply_weights"") File <*>python3.5/dist-packages/tensorflow/python/ops/math_ops.py, line 1346, in matmul name=name) File <*>python3.5/dist-packages/tensorflow/python/ops/gen_math_ops.py, line 1271, in _mat_mul transpose_b=transpose_b, name=name) File <*>python3.5/dist-packages/tensorflow/python/framework/op_def_library.py, line 703, in apply_op op_def=op_def) File <*>python3.5/dist-packages/tensorflow/python/framework/ops.py, line 2312, in create_op set_shapes_for_outputs(ret) File <*>python3.5/dist-packages/tensorflow/python/framework/ops.py, line 1704, in set_shapes_for_outputs shapes = shape_func(op) File <*>python3.5/dist-packages/tensorflow/python/framework/common_shapes.py, line 94, in matmul_shape inner_a.assert_is_compatible_with(inner_b) File <*>python3.5/dist-packages/tensorflow/python/framework/tensor_shape.py, line 108, in assert_is_compatible_with % (self, other)) ValueError: Dimensions 3 and 4 are not compatible",0
"File <*>/gridsearch.py, line 43, in <module> model.fit(x,y) File <*>/site-packages/keras/wrappers/scikit_learn.py, line 135, in fit **self.filter_sk_params(self.build_fn.__call__)) TypeError: __call__() missing 1 required positional argument: 'x'",0
"File my_test.py, line 51, in [FUNC] [CODE] File <*>python3.5/dist-packages/tensorflow/python/ops/parsing_ops.py, line 640, in parse_single_sequence_example feature_list_dense_defaults, example_name, name) File <*>python3.5/dist-packages/tensorflow/python/ops/parsing_ops.py, line 837, in _parse_single_sequence_example_raw name=name) File <*>python3.5/dist-packages/tensorflow/python/ops/gen_parsing_ops.py, line 285, in _parse_single_sequence_example name=name) File <*>python3.5/dist-packages/tensorflow/python/framework/op_def_library.py, line 749, in apply_op op_def=op_def) File <*>python3.5/dist-packages/tensorflow/python/framework/ops.py, line 2382, in create_op set_shapes_for_outputs(ret) File <*>python3.5/dist-packages/tensorflow/python/framework/ops.py, line 1783, in set_shapes_for_outputs shapes = shape_func(op) File <*>python3.5/dist-packages/tensorflow/python/framework/common_shapes.py, line 596, in call_cpp_shape_fn raise ValueError(err.message) ValueError: Shape must be rank 0 but is rank 1",0
"File <*>python3.5/site-packages/tensorflow/python/client/session.py, line 972, in _do_call return fn(*args) File <*>python3.5/site-packages/tensorflow/python/client/session.py, line 954, in _run_fn status, run_metadata) File <*>python3/contextlib.py, line 66, in __exit__ next(self.gen) File <*>python3.5/site-packages/tensorflow/python/framework/errors.py, line 463, in raise_exception_on_not_ok_status pywrap_tensorflow.TF_GetCode(status)) tensorflow.python.framework.errors.InvalidArgumentError: Input to reshape is a tensor with 313600 values, but the requested shape requires a multiple of 4608 [[Node: Reshape_1 = Reshape[T=DT_FLOAT, Tshape=DT_INT32, _device=""/job:localhost/replica:0/task:0/cpu:0""](dropout/mul, Reshape_1/shape)]]",0
"File <stdin>, line 1, in <module> [CODE] File <*>python2.7/site-packages/tensorflow/__init__.py, line 23, in <module> from tensorflow.python import * File <*>python2.7/site-packages/tensorflow/python/__init__.py, line 49, in <module> from tensorflow.python import pywrap_tensorflow File <*>python2.7/site-packages/tensorflow/python/pywrap_tensorflow.py, line 21, in <module> _pywrap_tensorflow = swig_import_helper() File <*>python2.7/site-packages/tensorflow/python/pywrap_tensorflow.py, line 20, in swig_import_helper return importlib.import_module('_pywrap_tensorflow') File <*>python2.7/__init__.py, line 37, in import_module __import__(name) ImportError: No module named _pywrap_tensorflow",0
"File <*>/test_placeholder.py, line 5, in <module> input = tf.placeholder(tf.int32, tf.pack([batchSize, 5])) File <*>/site-packages/tensorflow/python/ops/array_ops.py, line 1579, in placeholder shape = tensor_shape.as_shape(shape) File <*>/site-packages/tensorflow/python/framework/tensor_shape.py, line 821, in as_shape return TensorShape(shape) File <*>/site-packages/tensorflow/python/framework/tensor_shape.py, line 454, in __init__ self._dims = [as_dimension(dims)] File <*>/site-packages/tensorflow/python/framework/tensor_shape.py, line 378, in as_dimension return Dimension(value) File <*>/site-packages/tensorflow/python/framework/tensor_shape.py, line 33, in __init__ self._value = int(value) TypeError: int() argument must be a string, a bytes-like object or a number, not 'Tensor'",0
"File <stdin>, line 1, in <module> [CODE] File <*>/site-packages/sklearn/model_selection/_validation.py, line 140, in cross_val_score for train, test in cv_iter) File <*>/site-packages/sklearn/externals/joblib/parallel.py, line 758, in __call__ while self.dispatch_one_batch(iterator): File <*>/site-packages/sklearn/externals/joblib/parallel.py, line 603, in dispatch_one_batch tasks = BatchedCalls(itertools.islice(iterator, batch_size)) File <*>/site-packages/sklearn/externals/joblib/parallel.py, line 127, in __init__ self.items = list(iterator_slice) File <*>/site-packages/sklearn/model_selection/_validation.py, line 140, in <genexpr> for train, test in cv_iter) File <*>/site-packages/sklearn/base.py, line 67, in clone new_object_params = estimator.get_params(deep=False) TypeError: get_params() got an unexpected keyword argument 'deep'",0
"File pymask.py, line 303, in <module> main(sys.argv) File pymask.py, line 285, in main keras.callbacks.ProgbarLogger() File <*>python3.6/site-packages/keras/engine/training.py, line 1557, in fit_generator class_weight=class_weight) File <*>python3.6/site-packages/keras/engine/training.py, line 1314, in train_on_batch check_batch_axis=True) File <*>python3.6/site-packages/keras/engine/training.py, line 1029, in _standardize_user_data exception_prefix='model input') File <*>python3.6/site-packages/keras/engine/training.py, line 52, in standardize_input_data str(names)) ValueError: No data provided for ""input_1"". Need data for each key in: ['input_1']",0
"File <*>/rock_detector.py, line 155, in <module> main() File <*>/rock_detector.py, line 117, in main est_vgg16.train(input_fn=dataset_input_fn, steps=10) File <*>python3.6/site-packages/tensorflow/python/estimator/estimator.py, line 302, in train loss = self._train_model(input_fn, hooks, saving_listeners) File <*>python3.6/site-packages/tensorflow/python/estimator/estimator.py, line 711, in _train_model features, labels, model_fn_lib.ModeKeys.TRAIN, self.config) File <*>python3.6/site-packages/tensorflow/python/estimator/estimator.py, line 694, in _call_model_fn model_fn_results = self._model_fn(features=features, **kwargs) File <*>python3.6/site-packages/tensorflow/python/keras/_impl/keras/estimator.py, line 145, in model_fn labels) File <*>python3.6/site-packages/tensorflow/python/keras/_impl/keras/estimator.py, line 92, in _clone_and_build_model keras_model, features) File <*>python3.6/site-packages/tensorflow/python/keras/_impl/keras/estimator.py, line 58, in _create_ordered_io for key in estimator_io_dict: File <*>python3.6/site-packages/tensorflow/python/framework/ops.py, line 505, in __iter__ raise TypeError(""'Tensor' object is not iterable."") TypeError: 'Tensor' object is not iterable.",0
"File <stdin>, line 1, in <module> [CODE] RuntimeError: matrices expected, got 1D, 2D tensors at /Users/soumith/code/builder/wheel/pytorch-src/torch/lib/TH/generic/THTensorMath.c:1288",0
"File <*>/site-packages/tensorflow/python/platform/self_check.py, line 75, in preload_check ctypes.WinDLL(build_info.cudart_dll_name) File <*>/__init__.py, line 351, in __init__ self._handle = _dlopen(self._name, mode) OSError: [WinError 126] This specified module could not be found",0
"File <ipython-input-7-e80e82960eb9>, line 1, in <module> cross = cross_val_score(estimator=classfier, X=Xtrain, y=Ytrain, cv=10 , n_jobs=-1) File <*>/site-packages/sklearn/model_selection/_validation.py, line 342, in cross_val_score pre_dispatch=pre_dispatch) File <*>/site-packages/sklearn/model_selection/_validation.py, line 206, in cross_validate for train, test in cv.split(X, y, groups)) File <*>/site-packages/sklearn/externals/joblib/parallel.py, line 779, in __call__ while self.dispatch_one_batch(iterator): File <*>/site-packages/sklearn/externals/joblib/parallel.py, line 620, in dispatch_one_batch tasks = BatchedCalls(itertools.islice(iterator, batch_size)) File <*>/site-packages/sklearn/externals/joblib/parallel.py, line 127, in __init__ self.items = list(iterator_slice) File <*>/site-packages/sklearn/model_selection/_validation.py, line 206, in <genexpr> for train, test in cv.split(X, y, groups)) File <*>/site-packages/sklearn/base.py, line 62, in clone new_object_params[name] = clone(param, safe=False) File <*>/site-packages/sklearn/base.py, line 53, in clone return copy.deepcopy(estimator) File <*>/copy.py, line 180, in deepcopy y = _reconstruct(x, memo, *rv) File <*>/copy.py, line 280, in _reconstruct state = deepcopy(state, memo) File <*>/copy.py, line 150, in deepcopy y = copier(x, memo) File <*>/copy.py, line 240, in _deepcopy_dict y[deepcopy(key, memo)] = deepcopy(value, memo) File <*>/copy.py, line 215, in _deepcopy_list append(deepcopy(a, memo)) File <*>/copy.py, line 169, in deepcopy rv = reductor(4) TypeError: can't pickle _thread.lock objects",0
"File <*>python3.5/dist-packages/tensorflow/python/pywrap_tensorflow.py, line 58, in <module> from tensorflow.python.pywrap_tensorflow_internal import * File <*>python3.5/dist-packages/tensorflow/python/pywrap_tensorflow_internal.py, line 28, in <module> _pywrap_tensorflow_internal = swig_import_helper() File <*>python3.5/dist-packages/tensorflow/python/pywrap_tensorflow_internal.py, line 24, in swig_import_helper _mod = imp.load_module('_pywrap_tensorflow_internal', fp, pathname, description) File <*>python3.5/imp.py, line 242, in load_module return load_dynamic(name, filename, file) File <*>python3.5/imp.py, line 342, in load_dynamic return _load(spec) ImportError: /usr/local/lib/python3.5/dist-packages/tensorflow/python/_pywrap_tensorflow_internal.so: undefined symbol: _ZN10tensorflow9ConcatCPUINS_8bfloat16EEEvPNS_10DeviceBaseERKSt6vectorISt10unique_ptrINS_6TTypesIT_Li2EiE11ConstMatrixESt14default_deleteIS9_EESaISC_EEPNS8_6MatrixE",0
"File <*>/cli.py, line 797, in Execute resources = calliope_command.Run(cli=self, args=args) File <*>/backend.py, line 757, in Run resources = command_instance.Run(args) File <*>/predict.py, line 65, in Run args.text_instances) File <*>/local_utils.py, line 89, in RunPredict raise LocalPredictRuntimeError(err) LocalPredictRuntimeError: RuntimeError: Bad magic number in .pyc file ERROR: (gcloud.ml-engine.local.predict) RuntimeError: Bad magic number in .pyc file",0
"File <*>/new_main.py, line 35, in <module> b = sess.run(correct_prediction, feed_dict={a: a1, b: b1, y: y1}) TypeError: unhashable type: 'numpy.ndarray'",0
"File <*>/try2.py, line 45, in <module> classifier.train(input_fn=lambda: my_input_fn(is_shuffle=True, repeat_count=100)) File <*>python3.6/site-packages/tensorflow/python/estimator/estimator.py, line 352, in train loss = self._train_model(input_fn, hooks, saving_listeners) File <*>python3.6/site-packages/tensorflow/python/estimator/estimator.py, line 812, in _train_model features, labels, model_fn_lib.ModeKeys.TRAIN, self.config) File <*>python3.6/site-packages/tensorflow/python/estimator/estimator.py, line 793, in _call_model_fn model_fn_results = self._model_fn(features=features, **kwargs) File <*>python3.6/site-packages/tensorflow/python/estimator/canned/dnn.py, line 354, in _model_fn config=config) File <*>python3.6/site-packages/tensorflow/python/estimator/canned/dnn.py, line 161, in _dnn_model_fn 'Given type: {}'.format(type(features))) ValueError: features should be a dictionary of `Tensor`s. Given type: <class 'tensorflow.python.framework.ops.Tensor'>",0
"File <*>/generate_tfrecord.py, line 99, in <module> tf.app.run() File <*>/site-packages/tensorflow/python/platform/app.py, line 126, in run _sys.exit(main(argv)) File <*>/generate_tfrecord.py, line 85, in main writer = tf.python_io.TFRecordWriter(FLAGS.output_path) File <*>/site-packages/tensorflow/python/lib/io/tf_record.py, line 111, in __init__ compat.as_bytes(path), compat.as_bytes(compression_type), status) File <*>/site-packages/tensorflow/python/framework/errors_impl.py, line 516, in __exit__ c_api.TF_GetCode(self.status.status)) tensorflow.python.framework.errors_impl.NotFoundError: Failed to create a NewWriteableFile: : The system cannot find the path specified.",0
"File <*>/lstm.py, line 131, in <module> main() File <*>/lstm.py, line 111, in main model.fit_generator(generator=training_sequence) File <*>/site-packages/keras/legacy/interfaces.py, line 91, in wrapper return func(*args, **kwargs) File <*>/site-packages/keras/models.py, line 1253, in fit_generator initial_epoch=initial_epoch) File <*>/site-packages/keras/engine/training.py, line 2244, in fit_generator class_weight=class_weight) File <*>/site-packages/keras/engine/training.py, line 1884, in train_on_batch class_weight=class_weight) File <*>/site-packages/keras/engine/training.py, line 1487, in _standardize_user_data exception_prefix='target') File <*>/site-packages/keras/engine/training.py, line 113, in _standardize_input_data 'with shape ' + str(data_shape)) ValueError: Error when checking target: expected dense_1 to have 2 dimensions, but got array with shape (1, 1034, 9)",0
"File <*>python3.5/dist-packages/tensorflow/python/framework/tensor_shape.py, line 579, in merge_with new_dims.append(dim.merge_with(other[i])) File <*>python3.5/dist-packages/tensorflow/python/framework/tensor_shape.py, line 138, in merge_with self.assert_is_compatible_with(other) File <*>python3.5/dist-packages/tensorflow/python/framework/tensor_shape.py, line 111, in assert_is_compatible_with other)) ValueError: Dimensions 5 and 4 are not compatible",0
"File <*>python3.5/dist-packages/tensorflow/python/ops/gradients_impl.py, line 602, in gradients in_grad.set_shape(t_in.get_shape()) File <*>python3.5/dist-packages/tensorflow/python/framework/ops.py, line 407, in set_shape self._shape = self._shape.merge_with(shape) File <*>python3.5/dist-packages/tensorflow/python/framework/tensor_shape.py, line 582, in merge_with raise ValueError(""Shapes %s and %s are not compatible"" % (self, other)) ValueError: Shapes (?, 5, 15, 1) and (?, 4, 15, 1) are not compatible",0
"File <*>/train.py, line 167, in <module> tf.app.run() File <*>/site-packages/tensorflow/python/platform/app.py, line 126, in run _sys.exit(main(argv)) File <*>/train.py, line 92, in main FLAGS.pipeline_config_path) File <*>/config_util.py, line 93, in get_configs_from_pipeline_file text_format.Merge(proto_str, pipeline_config) File <*>/site-packages/google/protobuf/text_format.py, line 533, in Merge descriptor_pool=descriptor_pool) File <*>/site-packages/google/protobuf/text_format.py, line 587, in MergeLines return parser.MergeLines(lines, message) File <*>/site-packages/google/protobuf/text_format.py, line 620, in MergeLines self._ParseOrMerge(lines, message) File <*>/site-packages/google/protobuf/text_format.py, line 635, in _ParseOrMerge self._MergeField(tokenizer, message) File <*>/site-packages/google/protobuf/text_format.py, line 735, in _MergeField merger(tokenizer, message, field) File <*>/site-packages/google/protobuf/text_format.py, line 823, in _MergeMessageField self._MergeField(tokenizer, sub_message) File <*>/site-packages/google/protobuf/text_format.py, line 703, in _MergeField (message_descriptor.full_name, name)) google.protobuf.text_format.ParseError: 108:7 : Message type ""object_detection.protos.SsdFeatureExtractor"" has no field named ""batch_norm_trainable"".",0
"File <*>/mnist_test.py, line 24, in <module> from official.mnist import mnist ModuleNotFoundError: No module named 'official'",0
"File <*>/site-packages/theano/gof/lazylinker_c.py, line 81, in <module> actual_version, force_compile, _need_reload)) ImportError: Version check of the existing lazylinker compiled file. Looking for version 0.211, but found None. Extra debug information: force_compile=False, _need_reload=True",0
"File train_v2.py, line 110, in <module> main() File train_v2.py, line 81, in main model.update(batch) File <*>/model.py, line 131, in update loss_adv = self.adversarial_loss(batch, loss, self.network.lexicon_encoder.embedding.weight, y) File <*>/model.py, line 94, in adversarial_loss adv_embedding = torch.LongTensor(adv_embedding) TypeError: expected torch.LongTensor (got torch.cuda.FloatTensor)",0
"File hello-world.py, line 1, in <module> from keras.models import Sequential File <*>python3.6/site-packages/keras/__init__.py, line 3, in <module> from . import utils File <*>python3.6/site-packages/keras/utils/__init__.py, line 2, in <module> from . import np_utils File <*>python3.6/site-packages/keras/utils/np_utils.py, line 6, in <module> import numpy as np File <*>python3.6/site-packages/numpy/__init__.py, line 142, in <module> from . import add_newdocs File <*>python3.6/site-packages/numpy/add_newdocs.py, line 13, in <module> from numpy.lib import add_newdoc File <*>python3.6/site-packages/numpy/lib/__init__.py, line 8, in <module> from .type_check import * File <*>python3.6/site-packages/numpy/lib/type_check.py, line 11, in <module> import numpy.core.numeric as _nx File <*>python3.6/site-packages/numpy/core/__init__.py, line 16, in <module> from . import multiarray SystemError: initialization of multiarray raised unreported exception",0
"File <*>/predict.py, line 74, in <module> print(get_grad(x_cloned, x)) File <*>/predict.py, line 68, in get_grad A.backward() File <*>python3.5/site-packages/torch/tensor.py, line 93, in backward torch.autograd.backward(self, gradient, retain_graph, create_graph) File <*>python3.5/site-packages/torch/autograd/__init__.py, line 90, in backward allow_unreachable=True) # allow_unreachable flag RuntimeError: element 0 of tensors does not require grad and does not have a grad_fn",0
"File <*>/all_good.py, line 15, in <module> import matplotlib.pyplot as plt File <*>/site-packages/matplotlib/pyplot.py, line 115, in <module> _backend_mod, new_figure_manager, draw_if_interactive, _show = pylab_setup() File <*>/site-packages/matplotlib/backends/__init__.py, line 62, in pylab_setup [backend_name], 0) File <*>/site-packages/matplotlib/backends/backend_qt5agg.py, line 15, in <module> from .backend_qt5 import ( File <*>/site-packages/matplotlib/backends/backend_qt5.py, line 19, in <module> import matplotlib.backends.qt_editor.figureoptions as figureoptions File <*>/site-packages/matplotlib/backends/qt_editor/figureoptions.py, line 20, in <module> import matplotlib.backends.qt_editor.formlayout as formlayout File <*>/site-packages/matplotlib/backends/qt_editor/formlayout.py, line 54, in <module> from matplotlib.backends.qt_compat import QtGui, QtWidgets, QtCore File <*>/site-packages/matplotlib/backends/qt_compat.py, line 158, in <module> raise ImportError(""Failed to import any qt binding"") ImportError: Failed to import any qt binding",0
"File binary_classification.py, line 59, in <module> history=model.fit(X, y,batch_size=10, epochs=25,validation_split=0.7) File <*>python3.6/site-packages/keras/engine/training.py, line 1039, in fit validation_steps=validation_steps) File <*>python3.6/site-packages/keras/engine/training_arrays.py, line 217, in fit_loop callbacks.on_epoch_end(epoch, epoch_logs) File <*>python3.6/site-packages/keras/callbacks.py, line 79, in on_epoch_end callback.on_epoch_end(epoch, logs) File <*>python3.6/site-packages/keras/callbacks.py, line 338, in on_epoch_end self.progbar.update(self.seen, self.log_values) AttributeError: 'ProgbarLogger' object has no attribute 'log_values'",0
"File test_loocv.py, line 245, in <module> output = model_ft(test_data) File <*>python3.6/site-packages/torch/nn/modules/module.py, line 477, in __call__ result = self.forward(*input, **kwargs) File <*>python3.6/site-packages/torchvision-0.2.1-py3.6.egg/torchvision/models/resnet.py, line 139, in forward [CODE] File <*>python3.6/site-packages/torch/nn/modules/conv.py, line 301, in forward self.padding, self.dilation, self.groups) RuntimeError: Given groups=1, weight of size [64, 3, 7, 7], expected input[3, 1, 224, 224] to have 3 channels, but got 1 channels instead",0
"File app.py, line 16, in <module> from modules.xvision import Xvision File <*>/xvision.py, line 84, in <module> tf.import_graph_def(net['graph_def'], name='vgg') TypeError: 'Model' object has no attribute '__getitem__'",0
"File <*>/site-packages/keras/engine/topology.py, line 442, in assert_input_compatibility K.is_keras_tensor(x) File <*>/site-packages/keras/backend/tensorflow_backend.py, line 468, in is_keras_tensor raise ValueError('Unexpectedly found an instance of type `' + str(type(x)) + '`. ' ValueError: Unexpectedly found an instance of type `<class 'keras.layers.core.Masking'>`. Expected a symbolic tensor instance.",0
"File <*>/main.py, line 94, in <module> data_menu() File <*>/main.py, line 42, in data_menu data_menu() File <*>/main.py, line 56, in data_menu nn_menu() File <*>/main.py, line 76, in nn_menu nn.nn_gen(pre_processed_data) File <*>/nn.py, line 33, in nn_gen x, y = train[0] File <*>python3.6/site-packages/keras_preprocessing/sequence.py, line 378, in __getitem__ samples[j] = self.data[indices] File <*>python3.6/site-packages/pandas/core/frame.py, line 2688, in __getitem__ return self._getitem_column(key) File <*>python3.6/site-packages/pandas/core/frame.py, line 2695, in _getitem_column return self._get_item_cache(key) File <*>python3.6/site-packages/pandas/core/generic.py, line 2489, in _get_item_cache values = self._data.get(item) File <*>python3.6/site-packages/pandas/core/internals.py, line 4115, in get loc = self.items.get_loc(item) File <*>python3.6/site-packages/pandas/core/indexes/base.py, line 3080, in get_loc return self._engine.get_loc(self._maybe_cast_indexer(key)) File <*>/index.pyx, line 140, in pandas._libs.index.IndexEngine.get_loc [CODE] File <*>/index.pyx, line 162, in pandas._libs.index.IndexEngine.get_loc [CODE] File <*>/hashtable_class_helper.pxi, line 1492, in pandas._libs.hashtable.PyObjectHashTable.get_item [CODE] File <*>/hashtable_class_helper.pxi, line 1500, in pandas._libs.hashtable.PyObjectHashTable.get_item [CODE] KeyError: range(418, 419)",0
"File <ipython-input-286-e49b6fac918b>, line 1, in <module> output=model(input_) File <*>/site-packages/torch/nn/modules/module.py, line 489, in __call__ result = self.forward(*input, **kwargs) TypeError: forward() missing 1 required positional argument: 'p'",0
"File test.py, line 7, in <module> print(model.summary()) AttributeError: 'NoneType' object has no attribute 'summary'",0
"File <*>/SVM_Stock.py, line 71, in <module> estimator.fit(x,y) File <*>/site-packages/keras/wrappers/scikit_learn.py, line 210, in fit return super(KerasClassifier, self).fit(x, y, **kwargs) File <*>/site-packages/keras/wrappers/scikit_learn.py, line 139, in fit **self.filter_sk_params(self.build_fn.__call__)) TypeError: __call__() missing 1 required positional argument: 'inputs'",0
"File <*>/vis.py, line 28, in <module> from deeplab import common ModuleNotFoundError: No module named 'deeplab'",0
"File <*>python3.7/site-packages/conda/exceptions.py, line 819, in __call__ return func(*args, **kwargs) File <*>python3.7/site-packages/conda/cli/main.py, line 78, in _main exit_code = do_call(args, p) File <*>python3.7/site-packages/conda/cli/conda_argparse.py, line 77, in do_call exit_code = getattr(module, func_name)(args, parser) File <*>python3.7/site-packages/conda/cli/main_update.py, line 14, in execute install(args, parser, 'update') File <*>python3.7/site-packages/conda/cli/install.py, line 253, in install handle_txn(unlink_link_transaction, prefix, args, newenv) File <*>python3.7/site-packages/conda/cli/install.py, line 282, in handle_txn unlink_link_transaction.execute() File <*>python3.7/site-packages/conda/core/link.py, line 223, in execute self.verify() File <*>python3.7/site-packages/conda/common/io.py, line 46, in decorated return f(*args, **kwds) File <*>python3.7/site-packages/conda/core/link.py, line 200, in verify self.prepare() File <*>python3.7/site-packages/conda/core/link.py, line 192, in prepare stp.remove_specs, stp.update_specs) File <*>python3.7/site-packages/conda/core/link.py, line 282, in _prepare mkdir_p(transaction_context['temp_dir']) File <*>python3.7/site-packages/conda/gateways/disk/__init__.py, line 60, in mkdir_p makedirs(path) File <*>python3.7/os.py, line 221, in makedirs mkdir(name, mode) PermissionError: [Errno 13] Permission denied: '/usr/share/anaconda3/.condatmp'",0
"File <*>/extra_classes.py, line 31, in <module> model_out = MyLayer(2)(model_in) File <*>/site-packages/tensorflow/python/keras/engine/base_layer.py, line 746, in __call__ self.build(input_shapes) File <*>/extra_classes.py, line 20, in build trainable=True) File <*>/site-packages/tensorflow/python/keras/engine/base_layer.py, line 609, in add_weight aggregation=aggregation) File <*>/site-packages/tensorflow/python/training/checkpointable/base.py, line 639, in _add_variable_with_custom_getter **kwargs_for_getter) File <*>/site-packages/tensorflow/python/keras/engine/base_layer.py, line 1977, in make_variable aggregation=aggregation) File <*>/site-packages/tensorflow/python/ops/variables.py, line 183, in __call__ return cls._variable_v1_call(*args, **kwargs) File <*>/site-packages/tensorflow/python/ops/variables.py, line 146, in _variable_v1_call aggregation=aggregation) File <*>/site-packages/tensorflow/python/ops/variables.py, line 125, in <lambda> previous_getter = lambda **kwargs: default_variable_creator(None, **kwargs) File <*>/site-packages/tensorflow/python/ops/variable_scope.py, line 2437, in default_variable_creator import_scope=import_scope) File <*>/site-packages/tensorflow/python/ops/variables.py, line 187, in __call__ return super(VariableMetaclass, cls).__call__(*args, **kwargs) File <*>/site-packages/tensorflow/python/ops/resource_variable_ops.py, line 297, in __init__ constraint=constraint) File <*>/site-packages/tensorflow/python/ops/resource_variable_ops.py, line 409, in _init_from_args initial_value() if init_from_fn else initial_value, File <*>/site-packages/tensorflow/python/keras/engine/base_layer.py, line 1959, in <lambda> shape, dtype=dtype, partition_info=partition_info) File <*>/site-packages/tensorflow/python/ops/init_ops.py, line 255, in __call__ shape, self.minval, self.maxval, dtype, seed=self.seed) File <*>/site-packages/tensorflow/python/ops/random_ops.py, line 235, in random_uniform shape = _ShapeTensor(shape) File <*>/site-packages/tensorflow/python/ops/random_ops.py, line 44, in _ShapeTensor return ops.convert_to_tensor(shape, dtype=dtype, name=""shape"") File <*>/site-packages/tensorflow/python/framework/ops.py, line 1050, in convert_to_tensor as_ref=False) File <*>/site-packages/tensorflow/python/framework/ops.py, line 1146, in internal_convert_to_tensor ret = conversion_func(value, dtype=dtype, name=name, as_ref=as_ref) File <*>/site-packages/tensorflow/python/framework/constant_op.py, line 229, in _constant_tensor_conversion_function return constant(v, dtype=dtype, name=name) File <*>/site-packages/tensorflow/python/framework/constant_op.py, line 208, in constant value, dtype=dtype, shape=shape, verify_shape=verify_shape)) File <*>/site-packages/tensorflow/python/framework/tensor_util.py, line 531, in make_tensor_proto ""supported type."" % (type(values), values)) TypeError: Failed to convert object of type <class 'tuple'> to Tensor. Contents: (Dimension(4), 2). Consider casting elements to a supported type.",0
"File classifier_model.py, line 115, in <module> model.fit_generator(generator.flow(train_images, train_labels, batch_size=BATCH_SIZE), epochs=num_epochs) File <*>python3.6/site-packages/tensorflow/python/keras/engine/training.py, line 1426, in fit_generator initial_epoch=initial_epoch) File <*>python3.6/site-packages/tensorflow/python/keras/engine/training_generator.py, line 191, in model_iteration batch_outs = batch_function(*batch_data) File <*>python3.6/site-packages/tensorflow/python/keras/engine/training.py, line 1191, in train_on_batch outputs = self._fit_function(ins) # pylint: disable=not-callable File <*>python3.6/site-packages/tensorflow/python/keras/backend.py, line 3076, in __call__ run_metadata=self.run_metadata) File <*>python3.6/site-packages/tensorflow/python/client/session.py, line 1439, in __call__ run_metadata_ptr) File <*>python3.6/site-packages/tensorflow/python/framework/errors_impl.py, line 528, in __exit__ c_api.TF_GetCode(self.status.status)) tensorflow.python.framework.errors_impl.InvalidArgumentError: logits and labels must have the same first dimension, got logits shape [1,7] and labels shape [7] [[{{node loss/dense_1_loss/SparseSoftmaxCrossEntropyWithLogits/SparseSoftmaxCrossEntropyWithLogits}}]]",0
"File <*>/site-packages/tensorflow/python/platform/self_check.py, line 62, in preload_check ctypes.WinDLL(build_info.nvcuda_dll_name) File <*>/__init__.py, line 356, in __init__ self._handle = _dlopen(self._name, mode) OSError: [WinError 126] Das angegebene Modul wurde nicht gefunden",0
"File <*>/bacteria_rcnn_train.py, line 53, in <module> import keras File <*>python3.5/dist-packages/keras/__init__.py, line 3, in <module> from . import utils File <*>python3.5/dist-packages/keras/utils/__init__.py, line 6, in <module> from . import conv_utils File <*>python3.5/dist-packages/keras/utils/conv_utils.py, line 9, in <module> from .. import backend as K File <*>python3.5/dist-packages/keras/backend/__init__.py, line 84, in <module> from .tensorflow_backend import * File <*>python3.5/dist-packages/keras/backend/tensorflow_backend.py, line 5, in <module> import tensorflow as tf File <*>python3.5/dist-packages/tensorflow/__init__.py, line 28, in <module> from tensorflow.python import pywrap_tensorflow # pylint: disable=unused-import File <*>python3.5/dist-packages/tensorflow/python/__init__.py, line 83, in <module> from tensorflow.python import keras File <*>python3.5/dist-packages/tensorflow/python/keras/__init__.py, line 26, in <module> from tensorflow.python.keras import activations File <*>python3.5/dist-packages/tensorflow/python/keras/activations/__init__.py, line 22, in <module> from tensorflow.python.keras._impl.keras.activations import elu File <*>python3.5/dist-packages/tensorflow/python/keras/_impl/keras/__init__.py, line 21, in <module> from tensorflow.python.keras._impl.keras import activations File <*>python3.5/dist-packages/tensorflow/python/keras/_impl/keras/activations.py, line 23, in <module> from tensorflow.python.keras._impl.keras import backend as K File <*>python3.5/dist-packages/tensorflow/python/keras/_impl/keras/backend.py, line 38, in <module> from tensorflow.python.layers import base as tf_base_layers File <*>python3.5/dist-packages/tensorflow/python/layers/base.py, line 25, in <module> from tensorflow.python.keras import backend File <*>python3.5/dist-packages/tensorflow/python/keras/backend/__init__.py, line 22, in <module> from tensorflow.python.keras._impl.keras.backend import abs ImportError: cannot import name 'abs'",0
"File <*>/script3.py, line 9, in <module> model = load_model(model_path, custom_objects={'MyMeanPooling': MyMeanPooling}) File <*>/site-packages/keras/engine/saving.py, line 419, in load_model model = _deserialize_model(f, custom_objects, compile) File <*>/site-packages/keras/engine/saving.py, line 225, in _deserialize_model model = model_from_config(model_config, custom_objects=custom_objects) File <*>/site-packages/keras/engine/saving.py, line 458, in model_from_config return deserialize(config, custom_objects=custom_objects) File <*>/site-packages/keras/layers/__init__.py, line 55, in deserialize printable_module_name='layer') File <*>/site-packages/keras/utils/generic_utils.py, line 145, in deserialize_keras_object list(custom_objects.items()))) File <*>/site-packages/keras/engine/network.py, line 1022, in from_config process_layer(layer_data) File <*>/site-packages/keras/engine/network.py, line 1008, in process_layer custom_objects=custom_objects) File <*>/site-packages/keras/utils/generic_utils.py, line 147, in deserialize_keras_object return cls.from_config(config['config']) File <*>/site-packages/keras/engine/base_layer.py, line 1109, in from_config return cls(**config) TypeError: __init__() missing 1 required positional argument: 'pool_size'",0
"File <stdin>, line 1, in <module> [CODE] File <*>python3.6/site-packages/keras/__init__.py, line 3, in <module> from . import utils File <*>python3.6/site-packages/keras/utils/__init__.py, line 6, in <module> from . import conv_utils File <*>python3.6/site-packages/keras/utils/conv_utils.py, line 9, in <module> from .. import backend as K File <*>python3.6/site-packages/keras/backend/__init__.py, line 1, in <module> from .load_backend import epsilon File <*>python3.6/site-packages/keras/backend/load_backend.py, line 90, in <module> from .tensorflow_backend import * File <*>python3.6/site-packages/keras/backend/tensorflow_backend.py, line 13, in <module> from tensorflow.python.keras.utils import tf_utils ImportError: cannot import name 'tf_utils'",0
"File classify_in_out_tf2.py, line 81, in [FUNC] [CODE] AttributeError: 'AutoTrackable' object has no attribute 'summary'",0
"File <*>/prova_bert.py, line 230, in <module> model = baseline_model(output_size, max_seq_len, visualize=True) File <*>/prova_bert.py, line 165, in baseline_model )(bert_embeddings) File <*>/site-packages/tensorflow/python/keras/layers/wrappers.py, line 473, in __call__ return super(Bidirectional, self).__call__(inputs, **kwargs) File <*>/site-packages/tensorflow/python/keras/engine/base_layer.py, line 746, in __call__ self.build(input_shapes) File <*>/site-packages/tensorflow/python/keras/layers/wrappers.py, line 612, in build self.forward_layer.build(input_shape) File <*>/site-packages/tensorflow/python/keras/utils/tf_utils.py, line 149, in wrapper output_shape = fn(instance, input_shape) File <*>/site-packages/tensorflow/python/keras/layers/recurrent.py, line 552, in build self.cell.build(step_input_shape) File <*>/site-packages/tensorflow/python/keras/layers/recurrent.py, line 1934, in build constraint=self.kernel_constraint) File <*>/site-packages/tensorflow/python/keras/engine/base_layer.py, line 609, in add_weight aggregation=aggregation) File <*>/site-packages/tensorflow/python/training/checkpointable/base.py, line 639, in _add_variable_with_custom_getter **kwargs_for_getter) File <*>/site-packages/tensorflow/python/keras/engine/base_layer.py, line 1977, in make_variable aggregation=aggregation) File <*>/site-packages/tensorflow/python/ops/variables.py, line 183, in __call__ return cls._variable_v1_call(*args, **kwargs) File <*>/site-packages/tensorflow/python/ops/variables.py, line 146, in _variable_v1_call aggregation=aggregation) File <*>/site-packages/tensorflow/python/ops/variables.py, line 125, in <lambda> previous_getter = lambda **kwargs: default_variable_creator(None, **kwargs) File <*>/site-packages/tensorflow/python/ops/variable_scope.py, line 2437, in default_variable_creator import_scope=import_scope) File <*>/site-packages/tensorflow/python/ops/variables.py, line 187, in __call__ return super(VariableMetaclass, cls).__call__(*args, **kwargs) File <*>/site-packages/tensorflow/python/ops/resource_variable_ops.py, line 297, in __init__ constraint=constraint) File <*>/site-packages/tensorflow/python/ops/resource_variable_ops.py, line 409, in _init_from_args initial_value() if init_from_fn else initial_value, File <*>/site-packages/tensorflow/python/keras/engine/base_layer.py, line 1959, in <lambda> shape, dtype=dtype, partition_info=partition_info) File <*>/site-packages/tensorflow/python/ops/init_ops.py, line 473, in __call__ scale /= max(1., (fan_in + fan_out) / 2.) TypeError: unsupported operand type(s) for +: 'NoneType' and 'int'",0
"File <*>/Program.py, line 88, in FitModel model.fit(x_train, y_train, epochs=3, validation_data=(x_test, y_test)) File <*>/site-packages/tensorflow_core/python/keras/engine/training.py, line 728, in fit use_multiprocessing=use_multiprocessing) File <*>/site-packages/tensorflow_core/python/keras/engine/training_v2.py, line 224, in fit distribution_strategy=strategy) File <*>/site-packages/tensorflow_core/python/keras/engine/training_v2.py, line 547, in _process_training_inputs use_multiprocessing=use_multiprocessing) File <*>/site-packages/tensorflow_core/python/keras/engine/training_v2.py, line 606, in _process_inputs use_multiprocessing=use_multiprocessing) File <*>/site-packages/tensorflow_core/python/keras/engine/data_adapter.py, line 479, in __init__ batch_size=batch_size, shuffle=shuffle, **kwargs) File <*>/site-packages/tensorflow_core/python/keras/engine/data_adapter.py, line 321, in __init__ dataset_ops.DatasetV2.from_tensors(inputs).repeat() File <*>/site-packages/tensorflow_core/python/data/ops/dataset_ops.py, line 414, in from_tensors return TensorDataset(tensors) File <*>/site-packages/tensorflow_core/python/data/ops/dataset_ops.py, line 2335, in __init__ element = structure.normalize_element(element) File <*>/site-packages/tensorflow_core/python/data/util/structure.py, line 111, in normalize_element ops.convert_to_tensor(t, name=""component_%d"" % i)) File <*>/site-packages/tensorflow_core/python/framework/ops.py, line 1184, in convert_to_tensor return convert_to_tensor_v2(value, dtype, preferred_dtype, name) File <*>/site-packages/tensorflow_core/python/framework/ops.py, line 1242, in convert_to_tensor_v2 as_ref=False) File <*>/site-packages/tensorflow_core/python/framework/ops.py, line 1296, in internal_convert_to_tensor ret = conversion_func(value, dtype=dtype, name=name, as_ref=as_ref) File <*>/site-packages/tensorflow_core/python/framework/tensor_conversion_registry.py, line 52, in _default_conversion_function return constant_op.constant(value, dtype, name=name) File <*>/site-packages/tensorflow_core/python/framework/constant_op.py, line 227, in constant allow_broadcast=True) File <*>/site-packages/tensorflow_core/python/framework/constant_op.py, line 235, in _constant_impl t = convert_to_eager_tensor(value, ctx, dtype) File <*>/site-packages/tensorflow_core/python/framework/constant_op.py, line 96, in convert_to_eager_tensor return ops.EagerTensor(value, ctx.device_name, dtype) ValueError: Failed to convert a NumPy array to a Tensor (Unsupported object type float).",0
"File <ipython-input-1-f9d072fc6a73>, line 19, in <module> onnx_model = keras2onnx.convert_keras(model) File <*>/site-packages/keras2onnx/main.py, line 67, in convert_keras "" Please set environment variable TF_KERAS = 1."") Exception: This is a tensorflow keras model, but keras standalone converter is used. Please set environment variable TF_KERAS = 1.",0
"File <*>python37/runpy.py, line 193, in _run_module_as_main ""__main__"", mod_spec) File <*>python37/runpy.py, line 85, in _run_code exec(code, run_globals) File <*>/__main__.py, line 9, in <module> [CODE] File <*>/site-packages/flask/cli.py, line 966, in main cli.main(prog_name=""python -m flask"" if as_module else None) File <*>/site-packages/flask/cli.py, line 586, in main return super(FlaskGroup, self).main(*args, **kwargs) File <*>/site-packages/click/core.py, line 717, in main rv = self.invoke(ctx) File <*>/site-packages/click/core.py, line 1137, in invoke return _process_result(sub_ctx.command.invoke(sub_ctx)) File <*>/site-packages/click/core.py, line 956, in invoke return ctx.invoke(self.callback, **ctx.params) File <*>/site-packages/click/core.py, line 555, in invoke return callback(*args, **kwargs) File <*>/site-packages/click/decorators.py, line 64, in new_func return ctx.invoke(f, obj, *args, **kwargs) File <*>/site-packages/flask/cli.py, line 860, in run_command extra_files=extra_files, File <*>/site-packages/werkzeug/serving.py, line 1008, in run_simple run_with_reloader(inner, extra_files, reloader_interval, reloader_type) File <*>/site-packages/werkzeug/_reloader.py, line 337, in run_with_reloader reloader.run() File <*>/site-packages/werkzeug/_reloader.py, line 202, in run for filename in chain(_iter_module_files(), self.extra_files): File <*>/site-packages/werkzeug/_reloader.py, line 24, in _iter_module_files filename = getattr(module, ""__file__"", None) File <*>/site-packages/tensorflow/__init__.py, line 50, in __getattr__ module = self._load() File <*>/site-packages/tensorflow/__init__.py, line 44, in _load module = _importlib.import_module(self.__name__) File <*>python37/__init__.py, line 127, in import_module return _bootstrap._gcd_import(name[level:], package, level) File <frozen importlib._bootstrap>, line 1006, in _gcd_import [CODE] File <frozen importlib._bootstrap>, line 983, in _find_and_load [CODE] File <frozen importlib._bootstrap>, line 965, in _find_and_load_unlocked [CODE] ModuleNotFoundError: No module named 'tensorflow_core.keras'",0
"File <*>python3.7/site-packages/tensorflow/python/client/session.py, line 1455, in __del__ self._session._session, self._handle, status) File <*>python3.7/site-packages/tensorflow/python/framework/errors_impl.py, line 528, in __exit__ c_api.TF_GetCode(self.status.status)) tensorflow.python.framework.errors_impl.InvalidArgumentError: No such callable handle: 94697914208640",0
"File <*>/main.py, line 81, in <module> train(epoch) File <*>/main.py, line 48, in train for iteration, batch in enumerate(training_data_loader, 1): File <*>/site-packages/torch/utils/data/dataloader.py, line 345, in __next__ data = self._next_data() File <*>/site-packages/torch/utils/data/dataloader.py, line 841, in _next_data idx, data = self._get_data() File <*>/site-packages/torch/utils/data/dataloader.py, line 808, in _get_data success, data = self._try_get_data() File <*>/site-packages/torch/utils/data/dataloader.py, line 774, in _try_get_data raise RuntimeError('DataLoader worker (pid(s) {}) exited unexpectedly'.format(pids_str)) RuntimeError: DataLoader worker (pid(s) 16596, 9376, 12756, 9844) exited unexpectedly",0
"File <*>/site-packages/IPython/core/interactiveshell.py, line 3296, in run_code exec(code_obj, self.user_global_ns, self.user_ns) File <ipython-input-2-78553e2886de>, line 1, in <module> runfile('F:/experiment_code/U-net/train.py', wdir='F:/experiment_code/U-net') File <*>/pydev_umd.py, line 197, in runfile pydev_imports.execfile(filename, global_vars, local_vars) # execute the script File <*>/_pydev_execfile.py, line 18, in execfile exec(compile(contents+""\n"", file, 'exec'), glob, loc) File <*>/train.py, line 99, in <module> loss.backward() File <*>/site-packages/torch/tensor.py, line 107, in backward torch.autograd.backward(self, gradient, retain_graph, create_graph) File <*>/site-packages/torch/autograd/__init__.py, line 93, in backward allow_unreachable=True) # allow_unreachable flag RuntimeError: one of the variables needed for gradient computation has been modified by an inplace operation: [torch.cuda.FloatTensor [4, 2, 224, 224]], which is output 0 of SigmoidBackward, is at version 2; expected version 0 instead. Hint: enable anomaly detection to find the operation that failed to compute its gradient, with torch.autograd.set_detect_anomaly(True).",0
"File <*>/train.py, line 66, in <module> train(epochs=20, prefix='test_new_loss_fn') File <*>/train.py, line 46, in train model = create_model((shape[0], shape[1], 3), backbone=backbone, loss_function=loss_fn, freeze_backbone=backbone_freeze, lr=learning_rate) File <*>/__init__.py, line 48, in create_model loss=loss_function, metrics=[mean_relative_percentage_error, metrics.mean_absolute_error]) File <*>/site-packages/keras/engine/training.py, line 342, in compile sample_weight, mask) File <*>/site-packages/keras/engine/training_utils.py, line 404, in weighted score_array = fn(y_true, y_pred) File <*>/losses.py, line 8, in mean_relative_percentage_error diff = K.update_sub(ones, e) File <*>/site-packages/keras/backend/tensorflow_backend.py, line 999, in update_sub return tf.assign_sub(x, decrement) File <*>/site-packages/tensorflow/python/ops/state_ops.py, line 160, in assign_sub return ref.assign_sub(value) AttributeError: 'Tensor' object has no attribute 'assign_sub'",0
"File test_dist_1.py, line 25, in <module> dist.broadcast(tensor=a, src=0) File <*>python3.7/site-packages/torch/distributed/distributed_c10d.py, line 806, in broadcast work = _default_pg.broadcast([tensor], opts) RuntimeError: NCCL error in: /tmp/pip-req-build-58y_cjjl/torch/lib/c10d/ProcessGroupNCCL.cpp:290, unhandled system error",0
"File <*>/rks.py, line 14, in <module> from tf.keras.preprocessing.image import ImageDataGenerator ModuleNotFoundError: No module named 'tf'",0
"File <*>/tempCodeRunnerFile.python, line 1234, in <module> df_enc = tensorflow.one_hot(df, 2, on_value=None, off_value=None, axis=None, dtype=None, name=None) File <*>python3.7/site-packages/tensorflow_core/python/util/dispatch.py, line 180, in wrapper return target(*args, **kwargs) File <*>python3.7/site-packages/tensorflow_core/python/ops/array_ops.py, line 3645, in one_hot name) File <*>python3.7/site-packages/tensorflow_core/python/ops/gen_array_ops.py, line 5549, in one_hot _ops.raise_from_not_ok_status(e, name) File <*>python3.7/site-packages/tensorflow_core/python/framework/ops.py, line 6606, in raise_from_not_ok_status six.raise_from(core._status_to_exception(e.code, message), None) File <string>, line 3, in raise_from [CODE] tensorflow.python.framework.errors_impl.NotFoundError: Could not find valid device for node.",0
"File <stdin>, line 1, in <module> [CODE] File <*>python3.6/site-packages/torch_xla/core/xla_model.py, line 231, in xla_device devkind=devkind if devkind is not None else None) File <*>python3.6/site-packages/torch_xla/core/xla_model.py, line 136, in get_xla_supported_devices xla_devices = _DEVICES.value File <*>python3.6/site-packages/torch_xla/utils/utils.py, line 32, in value self._value = self._gen_fn() File <*>python3.6/site-packages/torch_xla/core/xla_model.py, line 18, in <lambda> _DEVICES = xu.LazyProperty(lambda: torch_xla._XLAC._xla_get_devices()) RuntimeError: tensorflow/compiler/xla/xla_client/computation_client.cc:274 : Missing XLA configuration",0
"File <*>/emotion.py, line 4, in <module> emotion_detector = EmotionRecognition(device='gpu', gpu_id=1) File <*>python3.7/site-packages/facial_emotion_recognition/facial_emotion_recognition.py, line 25, in __init__ self.network = NetworkV2(in_c=1, nl=32, out_f=7).to(self.device) File <*>python3.7/site-packages/torch/nn/modules/module.py, line 607, in to return self._apply(convert) File <*>python3.7/site-packages/torch/nn/modules/module.py, line 354, in _apply module._apply(fn) File <*>python3.7/site-packages/torch/nn/modules/module.py, line 376, in _apply param_applied = fn(param) File <*>python3.7/site-packages/torch/nn/modules/module.py, line 605, in convert return t.to(device, dtype if t.is_floating_point() else None, non_blocking) RuntimeError: CUDA error: invalid device ordinal",0
"File model_main_tf2.py, line 113, in <module> tf.compat.v1.app.run() File <*>/site-packages/tensorflow/python/platform/app.py, line 40, in run _run(main=main, argv=argv, flags_parser=_parse_flags_tolerate_undef) File <*>/site-packages/absl/app.py, line 303, in run _run_main(main, args) File <*>/site-packages/absl/app.py, line 251, in _run_main sys.exit(main(argv)) File model_main_tf2.py, line 104, in main model_lib_v2.train_loop( File <*>/site-packages/object_detection/model_lib_v2.py, line 639, in train_loop loss = _dist_train_step(train_input_iter) File <*>/site-packages/tensorflow/python/eager/def_function.py, line 780, in __call__ result = self._call(*args, **kwds) File <*>/site-packages/tensorflow/python/eager/def_function.py, line 840, in _call return self._stateless_fn(*args, **kwds) File <*>/site-packages/tensorflow/python/eager/function.py, line 2829, in __call__ return graph_function._filtered_call(args, kwargs) # pylint: disable=protected-access File <*>/site-packages/tensorflow/python/eager/function.py, line 1843, in _filtered_call return self._call_flat( File <*>/site-packages/tensorflow/python/eager/function.py, line 1923, in _call_flat return self._build_call_outputs(self._inference_function.call( File <*>/site-packages/tensorflow/python/eager/function.py, line 545, in call outputs = execute.execute( File <*>/site-packages/tensorflow/python/eager/execute.py, line 59, in quick_execute tensors = pywrap_tfe.TFE_Py_Execute(ctx._handle, device_name, op_name, tensorflow.python.framework.errors_impl.ResourceExhaustedError: 2 root error(s) found. (0) Resource exhausted: OOM when allocating tensor with shape[64,256,17,17] and type float on /job:localhost/replica:0/task:0/device:GPU:0 by allocator GPU_0_bfc [[node functional_3/conv2d_160/Conv2D (defined at \site-packages\object_detection\meta_architectures\faster_rcnn_meta_arch.py:1149) ]] Hint: If you want to see a list of allocated tensors when OOM happens, add report_tensor_allocations_upon_oom to RunOptions for current allocation info. [[Identity_1/_432]] Hint: If you want to see a list of allocated tensors when OOM happens, add report_tensor_allocations_upon_oom to RunOptions for current allocation info. (1) Resource exhausted: OOM when allocating tensor with shape[64,256,17,17] and type float on /job:localhost/replica:0/task:0/device:GPU:0 by allocator GPU_0_bfc [[node functional_3/conv2d_160/Conv2D (defined at \site-packages\object_detection\meta_architectures\faster_rcnn_meta_arch.py:1149) ]] Hint: If you want to see a list of allocated tensors when OOM happens, add report_tensor_allocations_upon_oom to RunOptions for current allocation info. 0 successful operations. 0 derived errors ignored. [Op:__inference__dist_train_step_79248]",0
"File <ipython-input-39-17211d5a107c>, line 8, in <module> train_loss, _ = modhelper.train(proc.train_dataloader) File <*>/model.py, line 71, in train preds = self.model(sent_id, mask) File <*>/site-packages/torch/nn/modules/module.py, line 727, in _call_impl result = self.forward(*input, **kwargs) File <*>/model.py, line 181, in forward #pass the inputs to the model File <*>/site-packages/transformers/modeling_bert.py, line 837, in forward embedding_output = self.embeddings( File <*>/site-packages/transformers/modeling_bert.py, line 201, in forward embeddings = inputs_embeds + position_embeddings + token_type_embeddings RuntimeError: The size of tensor a (4000) must match the size of tensor b (512) at non-singleton dimension 1",0
"File <stdin>, line 1, in <module> [CODE] File <*>python3.6/site-packages/smdistributed/dataparallel/__init__.py, line 16, in <module> import smddpcommon as hc ImportError: libc10.so: cannot open shared object file: No such file or directory",0
"File [FILE], line 2, in <module>() y_pred = model.predict(X_nn) File <*>/site-packages/keras/models.pyc, line 493, in predict(self, X, batch_size, verbose) return self._predict_loop(self._predict, X, batch_size, verbose)[0] AttributeError: 'Sequential' object has no attribute '_predict'",0
"File [FILE], line 2, in <module>() sess.run(train_step, feed_dict={x: batch_xs, y_: batch_ys}) File <*>python2.7/dist-packages/tensorflow/python/client/session.pyc, line 340, in run(self, fetches, feed_dict, options, run_metadata) run_metadata_ptr) File <*>python2.7/dist-packages/tensorflow/python/client/session.pyc, line 564, in _run(self, handle, fetches, feed_dict, options, run_metadata) feed_dict_string, options, run_metadata) File <*>python2.7/dist-packages/tensorflow/python/client/session.pyc, line 637, in _do_run(self, handle, target_list, fetch_list, feed_dict, options, run_metadata) target_list, options, run_metadata) File <*>python2.7/dist-packages/tensorflow/python/client/session.pyc, line 659, in _do_call(self, fn, *args) e.code) InternalError: Blas SGEMM launch failed : a.shape=(100, 784), b.shape=(784, 10), m=100, n=10, k=784 [[Node: MatMul = MatMul[T=DT_FLOAT, transpose_a=false, transpose_b=false, _device=""/job:localhost/replica:0/task:0/gpu:0""](_recv_Placeholder_0/_4, Variable/read)]]",0
"File [FILE], line 1, in <module>() biases = tf.get_variable('biases', [64], tf.constant_initializer(0.0)) File <*>python2.7/site-packages/tensorflow/python/ops/variable_scope.pyc, line 732, in get_variable(name, shape, dtype, initializer, regularizer, trainable, collections, caching_device, partitioner, validate_shape) partitioner=partitioner, validate_shape=validate_shape) File <*>python2.7/site-packages/tensorflow/python/ops/variable_scope.pyc, line 596, in get_variable(self, var_store, name, shape, dtype, initializer, regularizer, trainable, collections, caching_device, partitioner, validate_shape) partitioner=partitioner, validate_shape=validate_shape) File <*>python2.7/site-packages/tensorflow/python/ops/variable_scope.pyc, line 161, in get_variable(self, name, shape, dtype, initializer, regularizer, reuse, trainable, collections, caching_device, partitioner, validate_shape) caching_device=caching_device, validate_shape=validate_shape) File <*>python2.7/site-packages/tensorflow/python/ops/variable_scope.pyc, line 425, in _get_single_variable(self, name, shape, dtype, initializer, regularizer, reuse, trainable, collections, caching_device, validate_shape) dtype = dtypes.as_dtype(dtype) File <*>python2.7/site-packages/tensorflow/python/framework/dtypes.pyc, line 536, in as_dtype(type_value) if key == type_value: TypeError: data type not understood",0
"File [FILE], line 18, in <module>() curr_loss = train(train_loader, model, criterion, epoch, num_epochs) File [FILE], line 18, in train(train_loader, model, criterion, epoch, num_epochs) loss = criterion(outputs, labels) File <*>python3.5/dist-packages/torch/nn/modules/module.py, line 325, in _ _call__(self, *input, **kwargs) result = self.forward(*input, **kwargs) File [FILE], line 11, in forward(self, logits, targets) return self.crossEntropy_loss(probs_flat, targets_flat) File <*>python3.5/dist-packages/torch/nn/modules/module.py, line 325, in __call__(self, *input, **kwargs) result = self.forward(*input, **kwargs) File <*>python3.5/dist-packages/torch/nn/modules/loss.py, line 601, in f orward(self, input, target) self.ignore_index, self.reduce) File <*>python3.5/dist-packages/torch/nn/functional.py, line 1140, in cross_entropy(input, target, weight, size_average, ignore_index, reduce) return nll_loss(log_softmax(input, 1), target, weight, size_average, ignore_index, reduce) File <*>python3.5/dist-packages/torch/nn/functional.py, line 786, in log_softmax(input, dim, _stacklevel) return torch._C._nn.log_softmax(input, dim) RuntimeError: dimension out of range (expected to be in range of [-1, 0], but got 1)",0
"File [FILE], line 1, in <module>() for batch_idx, (data, target) in enumerate(train_loader): File <*>python2.7/dist-packages/torch/utils/data/dataloader.pyc, line 259, in __next__(self) batch = self.collate_fn([self.dataset[i] for i in indices]) File <*>python2.7/dist-packages/torch/utils/data/dataloader.pyc, line 135, in default_collate(batch) return [default_collate(samples) for samples in transposed] File <*>python2.7/dist-packages/torch/utils/data/dataloader.pyc, line 112, in default_collate(batch) return torch.stack(batch, 0, out=out) File <*>python2.7/dist-packages/torch/functional.pyc, line 64, in stack(sequence, dim, out) return torch.cat(inputs, dim) RuntimeError: invalid argument 0: Sizes of tensors must match except in dimension 0. Got 400 and 487 in dimension 2 at /pytorch/torch/lib/TH/generic/THTensorMath.c:2897",0
"File <*>python3.6/site-packages/tensorflow/python/client/session.py, line 282, in __init__(self, fetches, contraction_fn) fetch, allow_tensor=True, allow_operation=True)) File <*>python3.6/site-packages/tensorflow/python/framework/ops.py, line 3590, in as_graph_element(self, obj, allow_tensor, allow_operation) return self._as_graph_element_locked(obj, allow_tensor, allow_operation) File <*>python3.6/site-packages/tensorflow/python/framework/ops.py, line 3679, in _as_graph_element_locked(self, obj, allow_tensor, allow_operation) types_str)) TypeError: Can not convert a Iterator into a Tensor or Operation.",0
"File [FILE], line 7, in <module>() X = AttentionLayer()(X) File <*>python3.6/site-packages/keras/engine/topology.py, line 619, in __call__(self, inputs, **kwargs) output = self.call(inputs, **kwargs) File <*>/attention.py, line 51, in call(self, x) flatten_g = hw_flatten(g) File <*>/attention.py, line 41, in hw_flatten(x) return K.reshape(x, shape=[x.shape[0], x.shape[1]*x.shape[2], x.shape[-1]]) File <*>python3.6/site-packages/keras/backend/tensorflow_backend.py, line 1898, in reshape(x, shape) return tf.reshape(x, shape) File <*>python3.6/site-packages/tensorflow/python/ops/gen_array_ops.py, line 6113, in reshape(tensor, shape, name) ""Reshape"", tensor=tensor, shape=shape, name=name) File <*>python3.6/site-packages/tensorflow/python/framework/op_def_library.py, line 513, in _apply_op_helper(self, op_type_name, name, **keywords) raise err File <*>python3.6/site-packages/tensorflow/python/framework/op_def_library.py, line 510, in _apply_op_helper(self, op_type_name, name, **keywords) preferred_dtype=default_dtype) File <*>python3.6/site-packages/tensorflow/python/framework/ops.py, line 1104, in internal_convert_to_tensor(value, dtype, name, as_ref, preferred_dtype, ctx) ret = conversion_func(value, dtype=dtype, name=name, as_ref=as_ref) File <*>python3.6/site-packages/tensorflow/python/framework/constant_op.py, line 235, in _constant_tensor_conversion_function(v, dtype, name, as_ref) return constant(v, dtype=dtype, name=name) File <*>python3.6/site-packages/tensorflow/python/framework/constant_op.py, line 214, in constant(value, dtype, shape, name, verify_shape) value, dtype=dtype, shape=shape, verify_shape=verify_shape)) File <*>python3.6/site-packages/tensorflow/python/framework/tensor_util.py, line 521, in make_tensor_proto(values, dtype, shape, verify_shape) ""supported type."" % (type(values), values)) TypeError: Failed to convert object of type <class 'list'> to Tensor. Contents: [Dimension(None), Dimension(64), Dimension(8)]. Consider casting elements to a supported type.",0
"File [FILE], line 48, in <module>() labels=train_labels, num_sampled=num_sampled, num_classes=vocabulary_size) File <*>python3.6/dist-packages/tensorflow/python/ops/nn_impl.py, line 1349, in sampled_softmax_loss(weights, biases, labels, inputs, num_sampled, num_classes, num_true, sampled_values, remove_accidental_hits, partition_strategy, name, seed) seed=seed) File <*>python3.6/dist-packages/tensorflow/python/ops/nn_impl.py, line 1128, in _compute_sampled_logits(weights, biases, labels, inputs, num_sampled, num_classes, num_true, sampled_values, subtract_log_q, remove_accidental_hits, partition_strategy, name, seed) true_logits -= math_ops.log(true_expected_count) File <*>python3.6/dist-packages/tensorflow/python/ops/math_ops.py, line 862, in binary_op_wrapper(x, y) return func(x, y, name=name) File <*>python3.6/dist-packages/tensorflow/python/ops/gen_math_ops.py, line 8318, in sub(x, y, name) ""Sub"", x=x, y=y, name=name) File <*>python3.6/dist-packages/tensorflow/python/framework/op_def_library.py, line 546, in _apply_op_helper(self, op_type_name, name, **keywords) inferred_from[input_arg.type_attr])) TypeError: Input 'y' of 'Sub' Op has type float32 that does not match type float16 of argument 'x'.",0
"File [FILE], line 8, in <module>() concat = tf.keras.layers.Concatenate()((features['a'], features['b'])) File <*>/base_layer.py, line 753, in __call__(self, inputs, *args, **kwargs) self.build(input_shapes) File <*>/tf_utils.py, line 150, in wrapper(instance, input_shape) input_shape = tuple(tensor_shape.TensorShape(input_shape).as_list()) File <*>/tensor_shape.py, line 690, in __init__(self, dims) self._dims = [as_dimension(d) for d in dims_iter] File <*>/tensor_shape.py, line 632, in as_dimension(value) return Dimension(value) File <*>/tensor_shape.py, line 185, in __init__(self, value) self._value = int(value) TypeError: int() argument must be a string or a number, not 'TensorShapeV1'",0
"File [FILE], line 16, in <module>() dataset = dataset.padded_batch(2, padded_shapes=([None],[None]), padding_values=-1) File <*>python3.6/dist-packages/tensorflow/python/data/ops/dataset_ops.py, line 945, in padded_batch(self, batch_size, padded_shapes, padding_values, drop_remainder) drop_remainder) File <*>python3.6/dist-packages/tensorflow/python/data/ops/dataset_ops.py, line 2528, in __init__(self, input_dataset, batch_size, padded_shapes, padding_values, drop_remainder) input_dataset.output_types) File <*>python3.6/dist-packages/tensorflow/python/data/util/nest.py, line 467, in map_structure_up_to(shallow_tree, func, *inputs) assert_shallow_structure(shallow_tree, input_tree) File <*>python3.6/dist-packages/tensorflow/python/data/util/nest.py, line 301, in assert_shallow_structure(shallow_tree, input_tree, check_types) ""Input has type: %s."" % type(input_tree)) TypeError: If shallow structure is a sequence, input must also be a sequence. Input has type: <class 'int'>.",0
"File <*>python3.7/site-packages/tensorflow/python/framework/op_def_library.py, line 525, in _apply_op_helper(self, op_type_name, name, **keywords) values, as_ref=input_arg.is_ref).dtype.name File <*>python3.7/site-packages/tensorflow/python/framework/ops.py, line 1175, in internal_convert_to_tensor(value, dtype, name, as_ref, preferred_dtype, ctx, accept_symbolic_tensors) ret = conversion_func(value, dtype=dtype, name=name, as_ref=as_ref) File <*>python3.7/site-packages/tensorflow/python/framework/constant_op.py, line 304, in _constant_tensor_conversion_function(v, dtype, name, as_ref) return constant(v, dtype=dtype, name=name) File <*>python3.7/site-packages/tensorflow/python/framework/constant_op.py, line 245, in constant(value, dtype, shape, name) allow_broadcast=True) File <*>python3.7/site-packages/tensorflow/python/framework/constant_op.py, line 283, in _constant_impl(value, dtype, shape, name, verify_shape, allow_broadcast) allow_broadcast=allow_broadcast)) File <*>python3.7/site-packages/tensorflow/python/framework/tensor_util.py, line 454, in make_tensor_proto(values, dtype, shape, verify_shape, allow_broadcast) raise ValueError(""None values not supported."") ValueError: None values not supported.",0
"File [FILE], line 14, in <module>() random_search.fit(X_train, y_train) File <*>python3.6/site-packages/sklearn/model_selection/_search.py, line 677, in fit(self, X, y, groups, **fit_params) base_estimator = clone(self.estimator) File <*>python3.6/site-packages/sklearn/base.py, line 58, in clone(estimator, safe) % (repr(estimator), type(estimator))) TypeError: Cannot clone object '<keras.engine.sequential.Sequential object at 0x7fc268d8abe0>' (type <class 'keras.engine.sequential.Sequential'>): it does not seem to be a scikit-learn estimator as it does not implement a 'get_params' methods.",0
"File [FILE], line 1, in <module> modl(x) File <*>python3.6/site-packages/torch/nn/modules/module.py, line 477, in __call__(self, *input, **kwargs) result = self.forward(*input, **kwargs) File [FILE], line 223, in forward(self, x) de2 = torch.cat([en6add,de2_],1) RuntimeError: invalid argument 0: Sizes of tensors must match except in dimension 1. Got 5 and 4 in dimension 2 at /opt/conda/conda-bld/pytorch_1535491974311/work/aten/src/TH/generic/THTensorMath.cpp:3616",0
"File [FILE], line 23, in <module>() print(model(torch.tensor(X)).size) File [FILE], line 14, in forward(self, x) x = self.layer1(x) File <*>python3.6/site-packages/torch/nn/modules/module.py, line 489, in __call__(self, *input, **kwargs) result = self.forward(*input, **kwargs) File <*>python3.6/site-packages/torch/nn/modules/conv.py, line 187, in forward(self, input) self.padding, self.dilation, self.groups) RuntimeError: Expected 3-dimensional input for 3-dimensional weight [20, 7, 5], but got 2-dimensional input of size [10, 7] instead",0
"File <*>python3.6/site-packages/tensorflow/python/keras/engine/base_layer.py, line 612, in __call__(self, inputs, *args, **kwargs) outputs = self.call(inputs, *args, **kwargs) File [FILE], line 8, in call(self, data_input) model = self.input_layer(data_input) File <*>python3.6/site-packages/tensorflow/python/keras/engine/input_layer.py, line 233, in Input(shape, batch_size, name, dtype, sparse, tensor, **kwargs) input_tensor=tensor) File <*>python3.6/site-packages/tensorflow/python/keras/engine/input_layer.py, line 94, in __init__(self, input_shape, batch_size, dtype, input_tensor, sparse, name, **kwargs) batch_input_shape = (batch_size,) + tuple(input_shape) File <*>python3.6/site-packages/tensorflow/python/framework/ops.py, line 449, in __iter__(self) ""Tensor objects are only iterable when eager execution is "" TypeError: Tensor objects are only iterable when eager execution is enabled. To iterate over this tensor use tf.map_fn.",0
"File [FILE], line 5, in <module>() train_step(x_sample=x_point, y_sample=y_point) File <*>python3.6/site-packages/tensorflow/python/eager/def_function.py, line 418, in __call__(self, *args, **kwds) results = self._stateful_fn(*args, **kwds) File <*>python3.6/site-packages/tensorflow/python/eager/function.py, line 1287, in __call__(self, *args, **kwargs) graph_function, args, kwargs = self._maybe_define_function(args, kwargs) File <*>python3.6/site-packages/tensorflow/python/eager/function.py, line 1611, in _maybe_define_function(self, args, kwargs) args, kwargs, override_flat_arg_shapes=relaxed_arg_shapes) File <*>python3.6/site-packages/tensorflow/python/eager/function.py, line 1512, in _create_graph_function(self, args, kwargs, override_flat_arg_shapes) capture_by_value=self._capture_by_value), File <*>python3.6/site-packages/tensorflow/python/framework/func_graph.py, line 694, in func_graph_from_py_func(name, python_func, args, kwargs, signature, func_graph, autograph, autograph_options, add_control_dependencies, arg_names, op_return_value, collections, capture_by_value, override_flat_arg_shapes) func_outputs = python_func(*func_args, **func_kwargs) File <*>python3.6/site-packages/tensorflow/python/eager/def_function.py, line 317, in wrapped_fn(*args, **kwds) return weak_wrapped_fn().__wrapped__(*args, **kwds) File <*>python3.6/site-packages/tensorflow/python/framework/func_graph.py, line 686, in wrapper(*args, **kwargs) ), args, kwargs) File <*>python3.6/site-packages/tensorflow/python/autograph/impl/api.py, line 392, in converted_call(f, owner, options, args, kwargs) result = converted_f(*effective_args, **kwargs) File <*>/tmpluzodr7d.py, line 4, in tf__train_step(x_sample, y_sample) predictions = ag__.converted_call(nn_regressor, None, ag__.ConversionOptions(recursive=True, verbose=0, strip_decorators=(tf.function, defun, ag__.convert, ag__.do_not_convert, ag__.converted_call), force_conversion=False, optional_features=(), internal_convert_user_code=True), (x_sample,), {}) File <*>python3.6/site-packages/tensorflow/python/autograph/impl/api.py, line 267, in converted_call(f, owner, options, args, kwargs) return _call_unconverted(f, args, kwargs) File <*>python3.6/site-packages/tensorflow/python/autograph/impl/api.py, line 188, in _call_unconverted(f, args, kwargs) return f(*args, **kwargs) File <*>python3.6/site-packages/tensorflow/python/keras/engine/base_layer.py, line 625, in __call__(self, inputs, *args, **kwargs) exception_str + '\n""""""') TypeError: You are attempting to use Python control flow in a layer that was not declared to be dynamic. Pass `dynamic=True` to the class constructor.",0
"File [FILE], line 3, in <module> act([a,b]) File <*>python36/site-packages/keras/engine/base_layer.py, line 431, in __call__(self, inputs, **kwargs) self.build(unpack_singleton(input_shapes)) TypeError: build() takes 1 positional argument but 2 were given",0
"File [FILE], line 9, in <module>() for i in train_iter: File <*>python3.6/site-packages/torchtext/data/iterator.py, line 157, in __iter__(self) yield Batch(minibatch, self.dataset, self.device) File <*>python3.6/site-packages/torchtext/data/batch.py, line 34, in __init__(self, data, dataset, device) setattr(self, name, field.process(batch, device=device)) File <*>python3.6/site-packages/torchtext/data/field.py, line 201, in process(self, batch, device) tensor = self.numericalize(padded, device=device) File <*>python3.6/site-packages/torchtext/data/field.py, line 302, in numericalize(self, arr, device) arr = [self.vocab.stoi[x] for x in arr] File <*>python3.6/site-packages/torchtext/data/field.py, line 302, in <listcomp>(.0) arr = [self.vocab.stoi[x] for x in arr] AttributeError: 'Field' object has no attribute 'vocab'",0
"File <*>python3.6/site-packages/tensorflow/python/framework/ops.py, line 1659, in _create_c_op(graph, node_def, inputs, control_inputs) c_op = c_api.TF_FinishOperation(op_desc) InvalidArgumentError: Dimensions must be equal, but are 1 and 64 for 'loss_1/zero_padding2d_5_loss/MatMul' (op: 'BatchMatMul') with input shapes: [?,64,64,1], [1,64,64,?].",0
"File <*>python3.6/dist-packages/tensorflow/python/keras/engine/base_layer.py, line 1969, in __setattr__(self, name, value) super(tracking.AutoTrackable, self).__setattr__(name, value) AttributeError: can't set attribute",0
"File <*>python3.6/dist-packages/tensorflow/python/keras/engine/base_layer.py, line 1974, in __setattr__(self, name, value) 'different name.').format(name)) AttributeError: Can't set the attribute ""name"", likely because it conflicts with an existing read-only @property of the object. Please choose a different name.",0
"File [FILE], line 1, in <module> import tensorflow_probability as tfp ModuleNotFoundError: No module named 'tensorflow_probability'.",0
"File [FILE], line 1, in <module>() process_image('IMG_PATH') File [FILE], line 5, in process_image(img_path) pImg = MobileNetV2.preprocess_input(img_array) AttributeError: 'function' object has no attribute 'preprocess_input'",0
"File [FILE], line 2, in <module> x.forward(torch.tensor([0,2,5,8]), higgs_bosson=2) TypeError: forward() got an unexpected keyword argument 'higgs_bosson'",0
"File <*>python3.6/site-packages/keras/engine/topology.py, line 425, in assert_input_compatibility(self, inputs) K.is_keras_tensor(x) File <*>python3.6/site-packages/keras/backend/tensorflow_backend.py, line 400, in is_keras_tensor(x) raise ValueError('Unexpectedly found an instance of type `' + str(type(x)) + '`. ' ValueError: Unexpectedly found an instance of type `<class 'keras.layers.normalization.BatchNormalization'>`. Expected a symbolic tensor instance.",0
"File [FILE], line 4, in <module>() feature_extractor = hub.KerasLayer(_URL, input_shape=(_TARGET_SIZE, _TARGET_SIZE,3)) File <*>python3.6/dist-packages/tensorflow_core/python/ops/resource_variable_ops.py, line 167, in _variable_handle_from_shape_and_dtype(shape, dtype, shared_name, name, graph_mode, initial_value) handle_data.shape_and_type.append( AttributeError: 'google.protobuf.pyext._message.RepeatedCompositeCo' object has no attribute 'append'",0
"File [FILE], line 1, in <module> loaded_model.summary() AttributeError: 'NoneType' object has no attribute 'summary'",0
"File [FILE], line 4, in <module>() pred = model(x) File <*>python3.6/sequential.py, line 256, in call(self, inputs, training, mask) return super(Sequential, self).call(inputs, training=training, mask=mask) File <*>python3.6/network.py, line 708, in call(self, inputs, training, mask) convert_kwargs_to_constants=base_layer_utils.call_context().saving) File <*>python3.6/network.py, line 860, in _run_internal_graph(self, inputs, training, mask, convert_kwargs_to_constants) output_tensors = layer(computed_tensors, **kwargs) File <*>python3.6/wrappers.py, line 528, in __call__(self, inputs, initial_state, constants, **kwargs) return super(Bidirectional, self).__call__(inputs, **kwargs) File <*>python3.6/base_layer.py, line 891, in __call__(self, inputs, *args, **kwargs) outputs = self.call(cast_inputs, *args, **kwargs) File <*>python3.6/wrappers.py, line 642, in call(self, inputs, training, mask, initial_state, constants) initial_state=forward_state, **kwargs) File <*>python3.6/recurrent.py, line 623, in __call__(self, inputs, initial_state, constants, **kwargs) return super(RNN, self).__call__(inputs, **kwargs) File <*>python3.6/recurrent_v2.py, line 961, in call(self, inputs, mask, training, initial_state) **cudnn_lstm_kwargs) File <*>python3.6/recurrent_v2.py, line 1174, in cudnn_lstm(inputs, init_h, init_c, kernel, recurrent_kernel, bias, mask, time_major, go_backwards) rnn_mode='lstm') File <*>python3.6/gen_cudnn_rnn_ops.py, line 109, in cudnn_rnn(input, input_h, input_c, params, rnn_mode, input_mode, direction, dropout, seed, seed2, is_training, name) ctx=_ctx) File <*>python3.6/gen_cudnn_rnn_ops.py, line 198, in cudnn_rnn_eager_fallback(input, input_h, input_c, params, rnn_mode, input_mode, direction, dropout, seed, seed2, is_training, name, ctx) attrs=_attrs, ctx=_ctx, name=name) File <*>python3.6/execute.py, line 67, in quick_execute(op_name, num_outputs, inputs, attrs, ctx, name) six.raise_from(core._status_to_exception(e.code, message), None) File <*>python3.6/dist-packages/six.py, line [NUM], in raise_from(value, from_value) [CODE] InvalidArgumentError: Invalid input_h shape: [1,64,1024] [1,54,1024] [Op:CudnnRNN]",0
"File [FILE], line 48, in <module> prediction = model(X) File <*>python3.6/site-packages/torch/nn/modules/module.py, line 493, in __call__(self, *input, **kwargs) result = self.forward(*input, **kwargs) File <*>python3.6/site-packages/torch/nn/parallel/data_parallel.py, line 146, in forward(self, *inputs, **kwargs) ""them on device: {}"".format(self.src_device_obj, t.device)) RuntimeError: module must have its parameters and buffers on device cuda:0 (device_ids[0]) but found one of them on device: cuda:2",0
"File [FILE], line 4, in <module> model.fit(train_encoded, train_labels, epochs=epochs, batch_size=batch_size, validation_data=(test_encoded,test_labels)) File <*>/site-packages/tensorflow_core/python/keras/engine/training.py, line 728, in fit(self, x, y, batch_size, epochs, verbose, callbacks, validation_split, validation_data, shuffle, class_weight, sample_weight, initial_epoch, steps_per_epoch, validation_steps, validation_freq, max_queue_size, workers, use_multiprocessing, **kwargs) use_multiprocessing=use_multiprocessing) File <*>/site-packages/tensorflow_core/python/keras/engine/training_v2.py, line 324, in fit(self, model, x, y, batch_size, epochs, verbose, callbacks, validation_split, validation_data, shuffle, class_weight, sample_weight, initial_epoch, steps_per_epoch, validation_steps, validation_freq, **kwargs) total_epochs=epochs) File <*>/site-packages/tensorflow_core/python/keras/engine/training_v2.py, line 123, in run_one_epoch(model, iterator, execution_function, dataset_size, batch_size, strategy, steps_per_epoch, num_samples, mode, training_context, total_epochs) batch_outs = execution_function(iterator) File <*>/site-packages/tensorflow_core/python/keras/engine/training_v2_utils.py, line 86, in execution_function(input_fn) distributed_function(input_fn)) File <*>/site-packages/tensorflow_core/python/eager/def_function.py, line 457, in __call__(self, *args, **kwds) result = self._call(*args, **kwds) File <*>/site-packages/tensorflow_core/python/eager/def_function.py, line 503, in _call(self, *args, **kwds) self._initialize(args, kwds, add_initializers_to=initializer_map) File <*>/site-packages/tensorflow_core/python/eager/def_function.py, line 408, in _initialize(self, args, kwds, add_initializers_to) *args, **kwds)) File <*>/site-packages/tensorflow_core/python/eager/function.py, line 1848, in _get_concrete_function_internal_garbage_collected(self, *args, **kwargs) graph_function, _, _ = self._maybe_define_function(args, kwargs) File <*>/site-packages/tensorflow_core/python/eager/function.py, line 2150, in _maybe_define_function(self, args, kwargs) graph_function = self._create_graph_function(args, kwargs) File <*>/site-packages/tensorflow_core/python/eager/function.py, line 2041, in _create_graph_function(self, args, kwargs, override_flat_arg_shapes) capture_by_value=self._capture_by_value), File <*>/site-packages/tensorflow_core/python/framework/func_graph.py, line 915, in func_graph_from_py_func(name, python_func, args, kwargs, signature, func_graph, autograph, autograph_options, add_control_dependencies, arg_names, op_return_value, collections, capture_by_value, override_flat_arg_shapes) func_outputs = python_func(*func_args, **func_kwargs) File <*>/site-packages/tensorflow_core/python/eager/def_function.py, line 358, in wrapped_fn(*args, **kwds) return weak_wrapped_fn().__wrapped__(*args, **kwds) File <*>/site-packages/tensorflow_core/python/keras/engine/training_v2_utils.py, line 73, in distributed_function(input_iterator) per_replica_function, args=(model, x, y, sample_weights)) File <*>/site-packages/tensorflow_core/python/distribute/distribute_lib.py, line 760, in experimental_run_v2(self, fn, args, kwargs) return self._extended.call_for_each_replica(fn, args=args, kwargs=kwargs) File <*>/site-packages/tensorflow_core/python/distribute/distribute_lib.py, line 1787, in call_for_each_replica(self, fn, args, kwargs) return self._call_for_each_replica(fn, args, kwargs) File <*>/site-packages/tensorflow_core/python/distribute/distribute_lib.py, line 2132, in _call_for_each_replica(self, fn, args, kwargs) return fn(*args, **kwargs) File <*>/site-packages/tensorflow_core/python/autograph/impl/api.py, line 292, in wrapper(*args, **kwargs) return func(*args, **kwargs) File <*>/site-packages/tensorflow_core/python/keras/engine/training_v2_utils.py, line 264, in train_on_batch(model, x, y, sample_weight, class_weight, reset_metrics) output_loss_metrics=model._output_loss_metrics) File <*>/site-packages/tensorflow_core/python/keras/engine/training_eager.py, line 311, in train_on_batch(model, inputs, targets, sample_weights, output_loss_metrics) output_loss_metrics=output_loss_metrics)) File <*>/site-packages/tensorflow_core/python/keras/engine/training_eager.py, line 252, in _process_single_batch(model, inputs, targets, output_loss_metrics, sample_weights, training) training=training)) File <*>/site-packages/tensorflow_core/python/keras/engine/training_eager.py, line 127, in _model_loss(model, inputs, targets, output_loss_metrics, sample_weights, training) outs = model(inputs, **kwargs) File <*>/site-packages/tensorflow_core/python/keras/engine/base_layer.py, line 847, in __call__(self, inputs, *args, **kwargs) outputs = call_fn(cast_inputs, *args, **kwargs) File <*>/site-packages/tensorflow_core/python/keras/engine/sequential.py, line 270, in call(self, inputs, training, mask) outputs = layer(inputs, **kwargs) File <*>/site-packages/tensorflow_core/python/keras/engine/base_layer.py, line 812, in __call__(self, inputs, *args, **kwargs) self.name) File <*>/site-packages/tensorflow_core/python/keras/engine/input_spec.py, line 213, in assert_input_compatibility(input_spec, inputs, layer_name) ' but received input with shape ' + str(shape)) ValueError: Input 0 of layer dense_3 is incompatible with the layer: expected axis -1 of input shape to have value 6022 but received input with shape [None, 512]",0
"File [FILE], line 9, in <module> train_loss, train_acc = train(model, train_iterator, optimizer, criterion) File [FILE], line 8, in train(model, iterator, optimizer, criterion) for batch in iterator: File <*>python3.7/site-packages/torchtext/data/iterator.py, line 142, in __iter__(self) for idx, minibatch in enumerate(self.batches): File <*>python3.7/site-packages/torchtext/data/iterator.py, line 286, in pool(data, batch_size, key, batch_size_fn, random_shuffler, shuffle, sort_within_batch) if sort_within_batch \ TypeError: '<' not supported between instances of 'Example' and 'Example'",0
"File [FILE], line 70, in <module>() loss = torch.nn.MSELoss(out, target) File <*>python3.6/dist-packages/torch/nn/_reduction.py, line 36, in legacy_get_string(size_average, reduce, emit_warning) if size_average and reduce: RuntimeError: bool value of Tensor with more than one value is ambiguous",0
"File [FILE], line 16, in <module> model.fit(X_train, y_train, epochs=3) File <*>/site-packages/tensorflow_core/python/keras/engine/training.py, line 819, in fit(self, x, y, batch_size, epochs, verbose, callbacks, validation_split, validation_data, shuffle, class_weight, sample_weight, initial_epoch, steps_per_epoch, validation_steps, validation_freq, max_queue_size, workers, use_multiprocessing, **kwargs) use_multiprocessing=use_multiprocessing) File <*>/site-packages/tensorflow_core/python/keras/engine/training_v2.py, line 342, in fit(self, model, x, y, batch_size, epochs, verbose, callbacks, validation_split, validation_data, shuffle, class_weight, sample_weight, initial_epoch, steps_per_epoch, validation_steps, validation_freq, max_queue_size, workers, use_multiprocessing, **kwargs) total_epochs=epochs) File <*>/site-packages/tensorflow_core/python/keras/engine/training_v2.py, line 128, in run_one_epoch(model, iterator, execution_function, dataset_size, batch_size, strategy, steps_per_epoch, num_samples, mode, training_context, total_epochs) batch_outs = execution_function(iterator) File <*>/site-packages/tensorflow_core/python/keras/engine/training_v2_utils.py, line 98, in execution_function(input_fn) distributed_function(input_fn)) File <*>/site-packages/tensorflow_core/python/eager/def_function.py, line 568, in __call__(self, *args, **kwds) result = self._call(*args, **kwds) File <*>/site-packages/tensorflow_core/python/eager/def_function.py, line 632, in _call(self, *args, **kwds) return self._stateless_fn(*args, **kwds) File <*>/site-packages/tensorflow_core/python/eager/function.py, line 2363, in __call__(self, *args, **kwargs) return graph_function._filtered_call(args, kwargs) # pylint: disable=protected-access File <*>/site-packages/tensorflow_core/python/eager/function.py, line 1611, in _filtered_call(self, args, kwargs) self.captured_inputs) File <*>/site-packages/tensorflow_core/python/eager/function.py, line 1692, in _call_flat(self, args, captured_inputs, cancellation_manager) ctx, args, cancellation_manager=cancellation_manager)) File <*>/site-packages/tensorflow_core/python/eager/function.py, line 545, in call(self, ctx, args, cancellation_manager) ctx=ctx) File <*>/site-packages/tensorflow_core/python/eager/execute.py, line 67, in quick_execute(op_name, num_outputs, inputs, attrs, ctx, name) six.raise_from(core._status_to_exception(e.code, message), None) File <*>/site-packages/six.py, line [NUM], in raise_from(value, from_value) [CODE] UnimplementedError: Cast string to int64 is not supported [[node loss/output_1_loss/Cast (defined at <ipython-input-111-1a89f1d94518>:16) ]] [Op:__inference_distributed_function_544280]",0
"File [FILE], line 5, in <module> verbose = 1) File <*>/site-packages/tensorflow/python/keras/engine/training.py, line 872, in fit(self, x, y, batch_size, epochs, verbose, callbacks, validation_split, validation_data, shuffle, class_weight, sample_weight, initial_epoch, steps_per_epoch, validation_steps, validation_batch_size, validation_freq, max_queue_size, workers, use_multiprocessing) return_dict=True) File <*>/site-packages/tensorflow/python/keras/engine/training.py, line 66, in _method_wrapper(self, *args, **kwargs) return method(self, *args, **kwargs) File <*>/site-packages/tensorflow/python/keras/engine/training.py, line 1081, in evaluate(self, x, y, batch_size, verbose, sample_weight, steps, callbacks, max_queue_size, workers, use_multiprocessing, return_dict) tmp_logs = test_function(iterator) File <*>/site-packages/tensorflow/python/eager/def_function.py, line 580, in __call__(self, *args, **kwds) result = self._call(*args, **kwds) File <*>/site-packages/tensorflow/python/eager/def_function.py, line 618, in _call(self, *args, **kwds) results = self._stateful_fn(*args, **kwds) File <*>/site-packages/tensorflow/python/eager/function.py, line 2419, in __call__(self, *args, **kwargs) graph_function, args, kwargs = self._maybe_define_function(args, kwargs) File <*>/site-packages/tensorflow/python/eager/function.py, line 2774, in _maybe_define_function(self, args, kwargs) return self._define_function_with_shape_relaxation(args, kwargs) File <*>/site-packages/tensorflow/python/eager/function.py, line 2706, in _define_function_with_shape_relaxation(self, args, kwargs) args, kwargs, override_flat_arg_shapes=relaxed_arg_shapes) File <*>/site-packages/tensorflow/python/eager/function.py, line 2667, in _create_graph_function(self, args, kwargs, override_flat_arg_shapes) capture_by_value=self._capture_by_value), File <*>/site-packages/tensorflow/python/framework/func_graph.py, line 981, in func_graph_from_py_func(name, python_func, args, kwargs, signature, func_graph, autograph, autograph_options, add_control_dependencies, arg_names, op_return_value, collections, capture_by_value, override_flat_arg_shapes) func_outputs = python_func(*func_args, **func_kwargs) File <*>/site-packages/tensorflow/python/eager/def_function.py, line 441, in wrapped_fn(*args, **kwds) return weak_wrapped_fn().__wrapped__(*args, **kwds) File <*>/site-packages/tensorflow/python/framework/func_graph.py, line 968, in wrapper(*args, **kwargs) raise e.ag_error_metadata.to_exception(e) AssertionError: in user code: c:\users\aniket\documents\aniket\learning-ml\ml_env\lib\site-packages\tensorflow\python\keras\engine\training.py:941 test_function * outputs = self.distribute_strategy.run( c:\users\aniket\documents\aniket\learning-ml\ml_env\lib\site-packages\tensorflow\python\distribute\distribute_lib.py:951 run ** return self._extended.call_for_each_replica(fn, args=args, kwargs=kwargs) c:\users\aniket\documents\aniket\learning-ml\ml_env\lib\site-packages\tensorflow\python\distribute\distribute_lib.py:2290 call_for_each_replica return self._call_for_each_replica(fn, args, kwargs) c:\users\aniket\documents\aniket\learning-ml\ml_env\lib\site-packages\tensorflow\python\distribute\distribute_lib.py:2649 _call_for_each_replica return fn(*args, **kwargs) c:\users\aniket\documents\aniket\learning-ml\ml_env\lib\site-packages\tensorflow\python\keras\engine\training.py:909 test_step ** y_pred = self(x, training=False) c:\users\aniket\documents\aniket\learning-ml\ml_env\lib\site-packages\tensorflow\python\keras\engine\base_layer.py:927 __call__ outputs = call_fn(cast_inputs, *args, **kwargs) c:\users\aniket\documents\aniket\learning-ml\ml_env\lib\site-packages\tensorflow\python\keras\engine\ etwork.py:719 call convert_kwargs_to_constants=base_layer_utils.call_context().saving) c:\users\aniket\documents\aniket\learning-ml\ml_env\lib\site-packages\tensorflow\python\keras\engine\ etwork.py:899 _run_internal_graph assert str(id(x)) in tensor_dict, 'Could not compute output ' + str(x) AssertionError: Could not compute output Tensor(""O1_6/Identity:0"", shape=(None, 2), dtype=float32)",0
"File [FILE], line 9, in <module>() model.save(outdir+'model.h5') File <*>python3.6/dist-packages/h5py/_hl/group.py, line 373, in __setitem__(self, name, obj) h5o.link(obj.id, self.id, name, lcpl=lcpl, lapl=self._lapl) File <*>/_objects.pyx, line [NUM], in h5py._objects.with_phil.wrapper() [CODE] File <*>/h5o.pyx, line [NUM], in h5py.h5o.link() [CODE] RuntimeError: Unable to create link (name already exists)",0
"File [FILE], line 1, in <module> history = model.fit([train.id, train.user_id], train.user_like, nb_epoch=3) File <*>/site-packages/keras/engine/training.py, line 1657, in fit(self, x, y, batch_size, epochs, verbose, callbacks, validation_split, validation_data, shuffle, class_weight, sample_weight, initial_epoch, steps_per_epoch, validation_steps, **kwargs) validation_steps=validation_steps) File <*>/site-packages/keras/engine/training.py, line 1213, in _fit_loop(self, f, ins, out_labels, batch_size, epochs, verbose, callbacks, val_f, val_ins, shuffle, callback_metrics, initial_epoch, steps_per_epoch, validation_steps) outs = f(ins_batch) File <*>/site-packages/keras/backend/tensorflow_backend.py, line 2357, in __call__(self, inputs) **self.session_kwargs) File <*>/site-packages/tensorflow_core/python/client/session.py, line 956, in run(self, fetches, feed_dict, options, run_metadata) run_metadata_ptr) File <*>/site-packages/tensorflow_core/python/client/session.py, line 1180, in _run(self, handle, fetches, feed_dict, options, run_metadata) feed_dict_tensor, options, run_metadata) File <*>/site-packages/tensorflow_core/python/client/session.py, line 1359, in _do_run(self, handle, target_list, fetch_list, feed_dict, options, run_metadata) run_metadata) File <*>/site-packages/tensorflow_core/python/client/session.py, line 1384, in _do_call(self, fn, *args) session_config.graph_options.rewrite_options.' raise type(e)(node_def, op, message) InvalidArgumentError: indices[24,0] = 335 is not in [0, 304) [[node user-embedding-mlp_1/GatherV2 (defined at E:\My\Ananconda\envs\tensor\lib\site-packages\tensorflow_core\python\framework\ops.py:1748) ]]",0
"File [FILE], line 3, in <module> validation_data=validation_batches) File <*>/site-packages/tensorflow/python/keras/engine/training.py, line 66, in _method_wrapper(self, *args, **kwargs) return method(self, *args, **kwargs) File <*>/site-packages/tensorflow/python/keras/engine/training.py, line 848, in fit(self, x, y, batch_size, epochs, verbose, callbacks, validation_split, validation_data, shuffle, class_weight, sample_weight, initial_epoch, steps_per_epoch, validation_steps, validation_batch_size, validation_freq, max_queue_size, workers, use_multiprocessing) tmp_logs = train_function(iterator) File <*>/site-packages/tensorflow/python/eager/def_function.py, line 580, in __call__(self, *args, **kwds) result = self._call(*args, **kwds) File <*>/site-packages/tensorflow/python/eager/def_function.py, line 611, in _call(self, *args, **kwds) return self._stateless_fn(*args, **kwds) # pylint: disable=not-callable File <*>/site-packages/tensorflow/python/eager/function.py, line 2420, in __call__(self, *args, **kwargs) return graph_function._filtered_call(args, kwargs) # pylint: disable=protected-access File <*>/site-packages/tensorflow/python/eager/function.py, line 1665, in _filtered_call(self, args, kwargs) self.captured_inputs) File <*>/site-packages/tensorflow/python/eager/function.py, line 1746, in _call_flat(self, args, captured_inputs, cancellation_manager) ctx, args, cancellation_manager=cancellation_manager)) File <*>/site-packages/tensorflow/python/eager/function.py, line 598, in call(self, ctx, args, cancellation_manager) ctx=ctx) File <*>/site-packages/tensorflow/python/eager/execute.py, line 60, in quick_execute(op_name, num_outputs, inputs, attrs, ctx, name) inputs, attrs, num_outputs) InvalidArgumentError: 2 root error(s) found. (0) Invalid argument: Invalid JPEG data or crop window, data size 34228 [[{{node DecodeJpeg}}]] [[IteratorGetNext]] (1) Invalid argument: Invalid JPEG data or crop window, data size 34228 [[{{node DecodeJpeg}}]] [[IteratorGetNext]] [[IteratorGetNext/_4]]",0
"File [FILE], line 30, in <module>() attn_out, attn_states = tf.keras.layers.Attention()([encoder_output, decoder_output]) File <*>python3.6/site-packages/tensorflow_core/python/framework/ops.py, line 548, in __iter__(self) ""Cannot iterate over a tensor with unknown first dimension."") TypeError: Cannot iterate over a tensor with unknown first dimension.",0
"File [FILE], line 16, in <module>() abc = model.predict(img) File <*>python3.6/dist-packages/tensorflow/python/keras/engine/data_adapter.py, line 971, in select_data_adapter(x, y) _type_name(x), _type_name(y))) ValueError: Failed to find data adapter that can handle input: <class 'NoneType'>, <class 'NoneType'>",0
"File [FILE], line 8, in <module> from keras.models import Sequential File <*>/site-packages/keras/__init__.py, line 6, in <module> 'Keras requires TensorFlow 2.2 or higher. ' ImportError: Keras requires TensorFlow 2.2 or higher. Install TensorFlow via `pip install tensorflow",0
"File [FILE], line 3, in <module>() loss = keras.losses.categorical_crossentropy() File <*>python3.6/dist-packages/tensorflow/python/util/dispatch.py, line 201, in wrapper(*args, **kwargs) return target(*args, **kwargs) TypeError: categorical_crossentropy() missing 2 required positional arguments: 'y_true' and 'y_pred'",0
"File [FILE], line 1, in <module> import deeplabcut as dlc File <*>python3.7/site-packages/deeplabcut/__init__.py, line 38, in <module> from deeplabcut import generate_training_dataset File <*>python3.7/site-packages/deeplabcut/generate_training_dataset/__init__.py, line 18, in <module> from deeplabcut.generate_training_dataset.labeling_toolbox import * File <*>python3.7/site-packages/deeplabcut/generate_training_dataset/labeling_toolbox.py, line 33, in <module> from deeplabcut.utils import auxiliaryfunctions File <*>python3.7/site-packages/deeplabcut/utils/__init__.py, line 6, in <module> from deeplabcut.utils.make_labeled_video import * File <*>python3.7/site-packages/deeplabcut/utils/make_labeled_video.py, line 28, in <module> from matplotlib.animation import FFMpegWriter File <*>python3.7/site-packages/matplotlib/animation.py, line 737, in <module> class ImageMagickWriter(ImageMagickBase, MovieWriter): File <*>python3.7/site-packages/matplotlib/animation.py, line 120, in wrapper(writerClass) if writerClass.isAvailable(): File <*>python3.7/site-packages/matplotlib/animation.py, line 730, in isAvailable(cls) return super().isAvailable() File <*>python3.7/site-packages/matplotlib/animation.py, line 427, in isAvailable(cls) return shutil.which(cls.bin_path()) is not None File <*>python3.7/site-packages/matplotlib/animation.py, line 724, in bin_path(cls) binpath = mpl._get_executable_info('magick').executable File <*>python3.7/site-packages/matplotlib/__init__.py, line 385, in _get_executable_info(name) return impl([path, ""--version""], r""^Version: ImageMagick (\S*)"") File <*>python3.7/site-packages/matplotlib/__init__.py, line 330, in impl(args, regex, min_ver, ignore_exit_code) raise _cpe File <*>python3.7/site-packages/matplotlib/__init__.py, line 325, in impl(args, regex, min_ver, ignore_exit_code) universal_newlines=True, errors=""replace"") File <*>python3.7/subprocess.py, line 411, in check_output(timeout, *popenargs, **kwargs) **kwargs).stdout File <*>python3.7/subprocess.py, line 512, in run(input, capture_output, timeout, check, *popenargs, **kwargs) output=stdout, stderr=stderr) CalledProcessError: Command '['convert', '--version']' returned non-zero exit status 1.",0
"File [FILE], line 3, in <module> torch.load(cachefile) File <*>python3.8/site-packages/torch/serialization.py, line 584, in load(f, map_location, pickle_module, **pickle_load_args) return _load(opened_zipfile, map_location, pickle_module, **pickle_load_args) File <*>python3.8/site-packages/torch/serialization.py, line 839, in _load(zip_file, map_location, pickle_module, **pickle_load_args) data_file = io.BytesIO(zip_file.get_record('data.pkl')) RuntimeError: [enforce fail at inline_container.cc:209] . file not found: archive/data.pkl",0
"File [FILE], line 1, in <module>() x = build_img_encod() File <*>python3.6/dist-packages/tensorflow/python/keras/engine/input_spec.py, line 166, in assert_input_compatibility(input_spec, inputs, layer_name) if x.shape.ndims is None: AttributeError: 'Functional' object has no attribute 'shape'",0
"File <*>python3.6/dist-packages/tensorflow/python/util/nest.py, line 402, in assert_same_structure(nest1, nest2, check_types, expand_composites) % (str(e), str1, str2)) ValueError: The two structures don't have the same nested structure.",0
"File [FILE], line 7, in <module>() gen.load_state_dict(torch.load(os.path.join(workspace_dir, 'dcgan_g.pth'))) File <*>python3.6/dist-packages/torch/nn/modules/module.py, line 1052, in load_state_dict(self, state_dict, strict) self.__class__.__name__, ""\n\t"".join(error_msgs))) ***RuntimeError: Error(s) in loading state_dict for Generator: Missing key(s) in state_dict***: ""gen.0.0.weight"", ""gen.0.1.weight"", ""gen.0.1.bias"", ""gen.0.1.running_mean"", ""gen.0.1.running_var"", ""gen.1.0.weight"", ""gen.1.1.weight"", ""gen.1.1.bias"", ""gen.1.1.running_mean"", ""gen.1.1.running_var"", ""gen.2.0.weight"", ""gen.2.1.weight"", ""gen.2.1.bias"", ""gen.2.1.running_mean"", ""gen.2.1.running_var"", ""gen.3.0.weight"", ""gen.3.1.weight"", ""gen.3.1.bias"", ""gen.3.1.running_mean"", ""gen.3.1.running_var"", ""gen.4.weight"", ""gen.4.bias"". Unexpected key(s) in state_dict: ""disc.0.weight"", ""disc.0.bias"", ""disc.2.0.weight"", ""disc.2.1.weight"", ""disc.2.1.bias"", ""disc.2.1.running_mean"", ""disc.2.1.running_var"", ""disc.2.1.num_batches_tracked"", ""disc.3.0.weight"", ""disc.3.1.weight"", ""disc.3.1.bias"", ""disc.3.1.running_mean"", ""disc.3.1.running_var"", ""disc.3.1.num_batches_tracked"", ""disc.4.0.weight"", ""disc.4.1.weight"", ""disc.4.1.bias"", ""disc.4.1.running_mean"", ""disc.4.1.running_var"", ""disc.4.1.num_batches_tracked"", ""disc.5.weight"", ""disc.5.bias"".",0
"File [FILE], line 8, in <module> model.save(""temp_model"") File <*>/site-packages/tensorflow/python/keras/engine/training.py, line 1979, in save(self, filepath, overwrite, include_optimizer, save_format, signatures, options) signatures, options) File <*>/site-packages/tensorflow/python/keras/saving/save.py, line 134, in save_model(model, filepath, overwrite, include_optimizer, save_format, signatures, options) signatures, options) File <*>/site-packages/tensorflow/python/keras/saving/saved_model/save.py, line 80, in save(model, filepath, overwrite, include_optimizer, signatures, options) save_lib.save(model, filepath, signatures, options) File <*>/site-packages/tensorflow/python/saved_model/save.py, line 976, in save(obj, export_dir, signatures, options) obj, export_dir, signatures, options, meta_graph_def) File <*>/site-packages/tensorflow/python/saved_model/save.py, line 1061, in _build_meta_graph(obj, export_dir, signatures, options, meta_graph_def) _ = _SaveableView(checkpoint_graph_view) File <*>/site-packages/tensorflow/python/saved_model/save.py, line 178, in __init__(self, checkpoint_view, wrapped_functions) self.checkpoint_view.objects_ids_and_slot_variables()) File <*>/site-packages/tensorflow/python/training/tracking/graph_view.py, line 426, in objects_ids_and_slot_variables(self) object_names[obj] = _object_prefix_from_path(path) File <*>/site-packages/tensorflow/python/training/tracking/graph_view.py, line 64, in _object_prefix_from_path(path_to_root) for trackable in path_to_root)) File <*>/site-packages/tensorflow/python/training/tracking/graph_view.py, line 64, in <genexpr>(.0) for trackable in path_to_root)) File <*>/site-packages/tensorflow/python/training/tracking/graph_view.py, line 57, in _escape_local_name(name) return (name.replace(_ESCAPE_CHAR, _ESCAPE_CHAR + _ESCAPE_CHAR) AttributeError: 'NoneType' object has no attribute 'replace'",0
"File [FILE], line 7, in <module>() validation_steps = valid_step , callbacks = [metrics], verbose=2) File <*>python3.6/dist-packages/tensorflow/python/keras/engine/training.py, line 673, in fit(self, x, y, batch_size, epochs, verbose, callbacks, validation_split, validation_data, shuffle, class_weight, sample_weight, initial_epoch, steps_per_epoch, validation_steps, validation_freq, max_queue_size, workers, use_multiprocessing, **kwargs) initial_epoch=initial_epoch) File <*>python3.6/dist-packages/tensorflow/python/keras/engine/training.py, line 1433, in fit_generator(self, generator, steps_per_epoch, epochs, verbose, callbacks, validation_data, validation_steps, validation_freq, class_weight, max_queue_size, workers, use_multiprocessing, shuffle, initial_epoch) steps_name='steps_per_epoch') File <*>python3.6/dist-packages/tensorflow/python/keras/engine/training_generator.py, line 260, in model_iteration(model, data, steps_per_epoch, epochs, verbose, callbacks, validation_data, validation_steps, validation_freq, class_weight, max_queue_size, workers, use_multiprocessing, shuffle, initial_epoch, mode, batch_size, steps_name, **kwargs) callbacks._call_batch_hook(mode, 'begin', step, batch_logs) File <*>python3.6/dist-packages/tensorflow/python/keras/callbacks.py, line 247, in _call_batch_hook(self, mode, hook, batch, logs) batch_hook = getattr(callback, hook_name) AttributeError: 'Metrics' object has no attribute 'on_train_batch_begin'",0
